<robot name="onshape">
<link name="chassis">
<visual>
<origin xyz="-0.036999999999999928779 0.099000000000000004663 2.740320990957112457e-17" rpy="1.570796326794896558 -0 0" />
<geometry>
<mesh filename="package:///bearing_10x15x4_v1.stl"/>
</geometry>
<material name="bearing_10x15x4_v1_material">
<color rgba="0.62745098039215685404 0.62745098039215685404 0.62745098039215685404 1.0"/>
</material>
</visual>
<collision>
<origin xyz="-0.036999999999999928779 0.099000000000000004663 2.740320990957112457e-17" rpy="1.570796326794896558 -0 0" />
<geometry>
<mesh filename="package:///bearing_10x15x4_v1.stl"/>
</geometry>
</collision>
<visual>
<origin xyz="0.031900000000000656997 0.0782500000000000695 0.0056045238724370116667" rpy="-3.141592653589793116 1.2143064331837168949e-16 -1.6653345369377597091e-16" />
<geometry>
<mesh filename="package:///18g_servo_v1.stl"/>
</geometry>
<material name="18g_servo_v1_material">
<color rgba="0.62745098039215685404 0.62745098039215685404 0.62745098039215685404 1.0"/>
</material>
</visual>
<collision>
<origin xyz="0.031900000000000656997 0.0782500000000000695 0.0056045238724370116667" rpy="-3.141592653589793116 1.2143064331837168949e-16 -1.6653345369377597091e-16" />
<geometry>
<mesh filename="package:///18g_servo_v1.stl"/>
</geometry>
</collision>
<visual>
<origin xyz="0.037000000000001073697 0.049000000000011256773 1.3525422101756667814e-17" rpy="-1.570796326794896558 2.1297348549913199277e-16 0" />
<geometry>
<mesh filename="package:///bearing_10x15x4_v1.stl"/>
</geometry>
<material name="bearing_10x15x4_v1_material">
<color rgba="0.62745098039215685404 0.62745098039215685404 0.62745098039215685404 1.0"/>
</material>
</visual>
<collision>
<origin xyz="0.037000000000001073697 0.049000000000011256773 1.3525422101756667814e-17" rpy="-1.570796326794896558 2.1297348549913199277e-16 0" />
<geometry>
<mesh filename="package:///bearing_10x15x4_v1.stl"/>
</geometry>
</collision>
<visual>
<origin xyz="-0.011349999999999457745 0.069400000000000044986 -0.0061454761275629848916" rpy="-1.7733605042685643151e-32 -1.0648674274956600871e-16 3.141592653589793116" />
<geometry>
<mesh filename="package:///bottom_hip_servo_v12.stl"/>
</geometry>
<material name="bottom_hip_servo_v12_material">
<color rgba="1 1 1 1.0"/>
</material>
</visual>
<collision>
<origin xyz="-0.011349999999999457745 0.069400000000000044986 -0.0061454761275629848916" rpy="-1.7733605042685643151e-32 -1.0648674274956600871e-16 3.141592653589793116" />
<geometry>
<mesh filename="package:///bottom_hip_servo_v12.stl"/>
</geometry>
</collision>
<visual>
<origin xyz="5.273559366969493567e-16 0.2129900000000000404 0.0055000238724370320575" rpy="3.141592653589793116 -1.570796326794896558 0" />
<geometry>
<mesh filename="package:///servo_controller_v1.stl"/>
</geometry>
<material name="servo_controller_v1_material">
<color rgba="0.63921568627450975342 0.66666666666666662966 0.67843137254901964006 1.0"/>
</material>
</visual>
<collision>
<origin xyz="5.273559366969493567e-16 0.2129900000000000404 0.0055000238724370320575" rpy="3.141592653589793116 -1.570796326794896558 0" />
<geometry>
<mesh filename="package:///servo_controller_v1.stl"/>
</geometry>
</collision>
<visual>
<origin xyz="-0.036999999999998992029 0.14800000000001128919 2.740320990957112457e-17" rpy="1.570796326794896558 2.1297348549913199277e-16 0" />
<geometry>
<mesh filename="package:///bearing_10x15x4_v1.stl"/>
</geometry>
<material name="bearing_10x15x4_v1_material">
<color rgba="0.62745098039215685404 0.62745098039215685404 0.62745098039215685404 1.0"/>
</material>
</visual>
<collision>
<origin xyz="-0.036999999999998992029 0.14800000000001128919 2.740320990957112457e-17" rpy="1.570796326794896558 2.1297348549913199277e-16 0" />
<geometry>
<mesh filename="package:///bearing_10x15x4_v1.stl"/>
</geometry>
</collision>
<visual>
<origin xyz="5.273559366969493567e-16 0.21650000000000008127 0.0055000238724370320575" rpy="1.7733605042685613045e-32 1.0648674274956599639e-16 -1.665334536937733085e-16" />
<geometry>
<mesh filename="package:///servo_driver_mount_v9.stl"/>
</geometry>
<material name="servo_driver_mount_v9_material">
<color rgba="1 1 1 1.0"/>
</material>
</visual>
<collision>
<origin xyz="5.273559366969493567e-16 0.21650000000000008127 0.0055000238724370320575" rpy="1.7733605042685613045e-32 1.0648674274956599639e-16 -1.665334536937733085e-16" />
<geometry>
<mesh filename="package:///servo_driver_mount_v9.stl"/>
</geometry>
</collision>
<visual>
<origin xyz="0.037000000000000067557 0 2.0464316005663896192e-17" rpy="-1.570796326794896558 -0 0" />
<geometry>
<mesh filename="package:///bearing_10x15x4_v1.stl"/>
</geometry>
<material name="bearing_10x15x4_v1_material">
<color rgba="0.62745098039215685404 0.62745098039215685404 0.62745098039215685404 1.0"/>
</material>
</visual>
<collision>
<origin xyz="0.037000000000000067557 0 2.0464316005663896192e-17" rpy="-1.570796326794896558 -0 0" />
<geometry>
<mesh filename="package:///bearing_10x15x4_v1.stl"/>
</geometry>
</collision>
<visual>
<origin xyz="-0.01134999999999942305 0.16440399999999999459 0.0056754761275630283279" rpy="0 -1.0648674274956599639e-16 3.141592653589793116" />
<geometry>
<mesh filename="package:///top_hip_servo_v14.stl"/>
</geometry>
<material name="top_hip_servo_v14_material">
<color rgba="1 1 1 1.0"/>
</material>
</visual>
<collision>
<origin xyz="-0.01134999999999942305 0.16440399999999999459 0.0056754761275630283279" rpy="0 -1.0648674274956599639e-16 3.141592653589793116" />
<geometry>
<mesh filename="package:///top_hip_servo_v14.stl"/>
</geometry>
</collision>
<visual>
<origin xyz="0.037000000000001073697 0.053000000000011260326 1.3525422101756667814e-17" rpy="0 -2.1297348549913199277e-16 3.141592653589793116" />
<geometry>
<mesh filename="package:///hip_cage_v4.stl"/>
</geometry>
<material name="hip_cage_v4_material">
<color rgba="1 1 1 1.0"/>
</material>
</visual>
<collision>
<origin xyz="0.037000000000001073697 0.053000000000011260326 1.3525422101756667814e-17" rpy="0 -2.1297348549913199277e-16 3.141592653589793116" />
<geometry>
<mesh filename="package:///hip_cage_v4.stl"/>
</geometry>
</collision>
<visual>
<origin xyz="-0.036999999999999928779 0.0040000000000000035527 2.0464316005663896192e-17" rpy="1.570796326794896558 -0 0" />
<geometry>
<mesh filename="package:///bearing_10x15x4_v1.stl"/>
</geometry>
<material name="bearing_10x15x4_v1_material">
<color rgba="0.62745098039215685404 0.62745098039215685404 0.62745098039215685404 1.0"/>
</material>
</visual>
<collision>
<origin xyz="-0.036999999999999928779 0.0040000000000000035527 2.0464316005663896192e-17" rpy="1.570796326794896558 -0 0" />
<geometry>
<mesh filename="package:///bearing_10x15x4_v1.stl"/>
</geometry>
</collision>
<visual>
<origin xyz="-0.036999999999998839373 0.053000000000011260326 2.740320990957112457e-17" rpy="1.570796326794896558 2.1297348549913199277e-16 0" />
<geometry>
<mesh filename="package:///bearing_10x15x4_v1.stl"/>
</geometry>
<material name="bearing_10x15x4_v1_material">
<color rgba="0.62745098039215685404 0.62745098039215685404 0.62745098039215685404 1.0"/>
</material>
</visual>
<collision>
<origin xyz="-0.036999999999998839373 0.053000000000011260326 2.740320990957112457e-17" rpy="1.570796326794896558 2.1297348549913199277e-16 0" />
<geometry>
<mesh filename="package:///bearing_10x15x4_v1.stl"/>
</geometry>
</collision>
<visual>
<origin xyz="0.037000000000000067557 0.09500000000000000111 2.0464316005663896192e-17" rpy="-1.570796326794896558 -0 0" />
<geometry>
<mesh filename="package:///bearing_10x15x4_v1.stl"/>
</geometry>
<material name="bearing_10x15x4_v1_material">
<color rgba="0.62745098039215685404 0.62745098039215685404 0.62745098039215685404 1.0"/>
</material>
</visual>
<collision>
<origin xyz="0.037000000000000067557 0.09500000000000000111 2.0464316005663896192e-17" rpy="-1.570796326794896558 -0 0" />
<geometry>
<mesh filename="package:///bearing_10x15x4_v1.stl"/>
</geometry>
</collision>
<visual>
<origin xyz="-0.011349999999999429989 0.069403999999999993475 0.0056754761275630005724" rpy="-6.1629758220391547298e-33 -5.097559151830850833e-17 -3.141592653589793116" />
<geometry>
<mesh filename="package:///top_hip_servo_v14.stl"/>
</geometry>
<material name="top_hip_servo_v14_material">
<color rgba="1 1 1 1.0"/>
</material>
</visual>
<collision>
<origin xyz="-0.011349999999999429989 0.069403999999999993475 0.0056754761275630005724" rpy="-6.1629758220391547298e-33 -5.097559151830850833e-17 -3.141592653589793116" />
<geometry>
<mesh filename="package:///top_hip_servo_v14.stl"/>
</geometry>
</collision>
<visual>
<origin xyz="-0.031899999999999491263 0.17325000000000009837 -0.0061454761275629684117" rpy="-1.7733605042685645888e-32 -1.0648674274956603337e-16 3.141592653589793116" />
<geometry>
<mesh filename="package:///18g_servo_v1.stl"/>
</geometry>
<material name="18g_servo_v1_material">
<color rgba="0.62745098039215685404 0.62745098039215685404 0.62745098039215685404 1.0"/>
</material>
</visual>
<collision>
<origin xyz="-0.031899999999999491263 0.17325000000000009837 -0.0061454761275629684117" rpy="-1.7733605042685645888e-32 -1.0648674274956603337e-16 3.141592653589793116" />
<geometry>
<mesh filename="package:///18g_servo_v1.stl"/>
</geometry>
</collision>
<visual>
<origin xyz="-0.036999999999999928779 0.09500000000000000111 2.0464316005663896192e-17" rpy="0 -0 0" />
<geometry>
<mesh filename="package:///hip_cage_v4.stl"/>
</geometry>
<material name="hip_cage_v4_material">
<color rgba="1 1 1 1.0"/>
</material>
</visual>
<collision>
<origin xyz="-0.036999999999999928779 0.09500000000000000111 2.0464316005663896192e-17" rpy="0 -0 0" />
<geometry>
<mesh filename="package:///hip_cage_v4.stl"/>
</geometry>
</collision>
<visual>
<origin xyz="-0.031899999999999519018 0.0782500000000000695 -0.0061454761275629814221" rpy="-1.1102230246251582661e-16 1.7106901340672157332e-16 3.141592653589793116" />
<geometry>
<mesh filename="package:///18g_servo_v1.stl"/>
</geometry>
<material name="18g_servo_v1_material">
<color rgba="0.62745098039215685404 0.62745098039215685404 0.62745098039215685404 1.0"/>
</material>
</visual>
<collision>
<origin xyz="-0.031899999999999519018 0.0782500000000000695 -0.0061454761275629814221" rpy="-1.1102230246251582661e-16 1.7106901340672157332e-16 3.141592653589793116" />
<geometry>
<mesh filename="package:///18g_servo_v1.stl"/>
</geometry>
</collision>
<visual>
<origin xyz="-0.011349999999999478562 0.16440000000000007385 -0.0061454761275629710138" rpy="-1.7733605042685607571e-32 -1.0648674274956602104e-16 3.141592653589793116" />
<geometry>
<mesh filename="package:///bottom_hip_servo_v12.stl"/>
</geometry>
<material name="bottom_hip_servo_v12_material">
<color rgba="1 1 1 1.0"/>
</material>
</visual>
<collision>
<origin xyz="-0.011349999999999478562 0.16440000000000007385 -0.0061454761275629710138" rpy="-1.7733605042685607571e-32 -1.0648674274956602104e-16 3.141592653589793116" />
<geometry>
<mesh filename="package:///bottom_hip_servo_v12.stl"/>
</geometry>
</collision>
<visual>
<origin xyz="0.0050000000000005734302 0.0040000000000000035527 -0.016470476127562978796" rpy="-3.141592653589793116 -1.7733605042685613045e-32 1.57079632679489678" />
<geometry>
<mesh filename="package:///bottom_body_v3.stl"/>
</geometry>
<material name="bottom_body_v3_material">
<color rgba="1 1 1 1.0"/>
</material>
</visual>
<collision>
<origin xyz="0.0050000000000005734302 0.0040000000000000035527 -0.016470476127562978796" rpy="-3.141592653589793116 -1.7733605042685613045e-32 1.57079632679489678" />
<geometry>
<mesh filename="package:///bottom_body_v3.stl"/>
</geometry>
</collision>
<visual>
<origin xyz="-0.0049999999999994285127 0.0040000000000000035527 0.01647047612756302043" rpy="1.0648674274956599639e-16 -0 1.570796326794896558" />
<geometry>
<mesh filename="package:///top_body_v21.stl"/>
</geometry>
<material name="top_body_v21_material">
<color rgba="1 1 1 1.0"/>
</material>
</visual>
<collision>
<origin xyz="-0.0049999999999994285127 0.0040000000000000035527 0.01647047612756302043" rpy="1.0648674274956599639e-16 -0 1.570796326794896558" />
<geometry>
<mesh filename="package:///top_body_v21.stl"/>
</geometry>
</collision>
<visual>
<origin xyz="0.037000000000001073697 0.14800000000001128919 1.3525422101756667814e-17" rpy="1.570796326794896558 2.1297348549913199277e-16 0" />
<geometry>
<mesh filename="package:///bearing_10x15x4_v1.stl"/>
</geometry>
<material name="bearing_10x15x4_v1_material">
<color rgba="0.62745098039215685404 0.62745098039215685404 0.62745098039215685404 1.0"/>
</material>
</visual>
<collision>
<origin xyz="0.037000000000001073697 0.14800000000001128919 1.3525422101756667814e-17" rpy="1.570796326794896558 2.1297348549913199277e-16 0" />
<geometry>
<mesh filename="package:///bearing_10x15x4_v1.stl"/>
</geometry>
</collision>
<visual>
<origin xyz="0.037000000000001073697 0.14800000000001128919 1.3525422101756667814e-17" rpy="0 -2.1297348549913199277e-16 3.141592653589793116" />
<geometry>
<mesh filename="package:///hip_cage_v4.stl"/>
</geometry>
<material name="hip_cage_v4_material">
<color rgba="1 1 1 1.0"/>
</material>
</visual>
<collision>
<origin xyz="0.037000000000001073697 0.14800000000001128919 1.3525422101756667814e-17" rpy="0 -2.1297348549913199277e-16 3.141592653589793116" />
<geometry>
<mesh filename="package:///hip_cage_v4.stl"/>
</geometry>
</collision>
<visual>
<origin xyz="0.031900000000000566791 0.17325000000000007061 0.0056045238724370324834" rpy="3.141592653589793116 1.0648674274956604569e-16 -1.665334536937733578e-16" />
<geometry>
<mesh filename="package:///18g_servo_v1.stl"/>
</geometry>
<material name="18g_servo_v1_material">
<color rgba="0.62745098039215685404 0.62745098039215685404 0.62745098039215685404 1.0"/>
</material>
</visual>
<collision>
<origin xyz="0.031900000000000566791 0.17325000000000007061 0.0056045238724370324834" rpy="3.141592653589793116 1.0648674274956604569e-16 -1.665334536937733578e-16" />
<geometry>
<mesh filename="package:///18g_servo_v1.stl"/>
</geometry>
</collision>
<visual>
<origin xyz="-0.036999999999999928779 0 2.0464316005663896192e-17" rpy="0 -0 0" />
<geometry>
<mesh filename="package:///hip_cage_v4.stl"/>
</geometry>
<material name="hip_cage_v4_material">
<color rgba="1 1 1 1.0"/>
</material>
</visual>
<collision>
<origin xyz="-0.036999999999999928779 0 2.0464316005663896192e-17" rpy="0 -0 0" />
<geometry>
<mesh filename="package:///hip_cage_v4.stl"/>
</geometry>
</collision>
<inertial>
<origin xyz="-4.5556326039548192589e-05 0.11744527528301254571 0.00048649524046891684309" rpy="0 0 0"/>
<mass value="0.14444259148618379673" />
<inertia ixx="0.00050691211853786158868" ixy="6.0508940719534670227e-07"  ixz="4.0228692064900980824e-07" iyy="0.00012093550510184169328" iyz="-1.4515988224596834736e-06" izz="0.00059699138903157339831" />
</inertial>
</link>

<link name="lefthip">
<visual>
<origin xyz="-0.015649999999996784539 0.0071750000000001803654 -0.024150000000003606082" rpy="-3.0184188481995486949e-16 -1.5707963267945610486 0" />
<geometry>
<mesh filename="package:///9g_thigh_servo_attachment_v1.stl"/>
</geometry>
<material name="9g_thigh_servo_attachment_v1_material">
<color rgba="1 1 1 1.0"/>
</material>
</visual>
<collision>
<origin xyz="-0.015649999999996784539 0.0071750000000001803654 -0.024150000000003606082" rpy="-3.0184188481995486949e-16 -1.5707963267945610486 0" />
<geometry>
<mesh filename="package:///9g_thigh_servo_attachment_v1.stl"/>
</geometry>
</collision>
<visual>
<origin xyz="0.015650000000006127759 -0.0052250000000002138484 -0.029249999999993100963" rpy="1.570796326794896558 -1.5707963267945610486 0" />
<geometry>
<mesh filename="package:///microservosg90.stl"/>
</geometry>
<material name="microservosg90_material">
<color rgba="0.35294117647058825815 0.35294117647058825815 0.35294117647058825815 1.0"/>
</material>
</visual>
<collision>
<origin xyz="0.015650000000006127759 -0.0052250000000002138484 -0.029249999999993100963" rpy="1.570796326794896558 -1.5707963267945610486 0" />
<geometry>
<mesh filename="package:///microservosg90.stl"/>
</geometry>
</collision>
<visual>
<origin xyz="0.003887500000013539847 -7.1557343384043292644e-18 -0.050899999999988114474" rpy="3.141592653589793116 3.3716262352439410057e-13 3.141592653589793116" />
<geometry>
<mesh filename="package:///hip_joint_to_bearing_v3.stl"/>
</geometry>
<material name="hip_joint_to_bearing_v3_material">
<color rgba="1 1 1 1.0"/>
</material>
</visual>
<collision>
<origin xyz="0.003887500000013539847 -7.1557343384043292644e-18 -0.050899999999988114474" rpy="3.141592653589793116 3.3716262352439410057e-13 3.141592653589793116" />
<geometry>
<mesh filename="package:///hip_joint_to_bearing_v3.stl"/>
</geometry>
</collision>
<visual>
<origin xyz="-0.022149999999992009414 0.018292109297700007847 -0.037665155617948899158" rpy="1.570796326795329767 0.68835957731061858667 -1.5707963267946585262" />
<geometry>
<mesh filename="package:///left_forearm_linkage_v1.stl"/>
</geometry>
<material name="left_forearm_linkage_v1_material">
<color rgba="1 1 1 1.0"/>
</material>
</visual>
<collision>
<origin xyz="-0.022149999999992009414 0.018292109297700007847 -0.037665155617948899158" rpy="1.570796326795329767 0.68835957731061858667 -1.5707963267946585262" />
<geometry>
<mesh filename="package:///left_forearm_linkage_v1.stl"/>
</geometry>
</collision>
<visual>
<origin xyz="-0.019149999999993470856 -0.0052250000000002069095 -0.03435000000000476561" rpy="-1.570796326794896558 -1.5707963267945621588 0" />
<geometry>
<mesh filename="package:///left_forearm_servo_attachment_v1.stl"/>
</geometry>
<material name="left_forearm_servo_attachment_v1_material">
<color rgba="1 1 1 1.0"/>
</material>
</visual>
<collision>
<origin xyz="-0.019149999999993470856 -0.0052250000000002069095 -0.03435000000000476561" rpy="-1.570796326794896558 -1.5707963267945621588 0" />
<geometry>
<mesh filename="package:///left_forearm_servo_attachment_v1.stl"/>
</geometry>
</collision>
<visual>
<origin xyz="-0.028649999999997177724 0.0071955475779957337942 -0.024133107805413590852" rpy="-1.5707963270129230438 -1.5692676824827016535 1.570796327012620619" />
<geometry>
<mesh filename="package:///left_cover_v2.stl"/>
</geometry>
<material name="left_cover_v2_material">
<color rgba="1 1 1 1.0"/>
</material>
</visual>
<collision>
<origin xyz="-0.028649999999997177724 0.0071955475779957337942 -0.024133107805413590852" rpy="-1.5707963270129230438 -1.5692676824827016535 1.570796327012620619" />
<geometry>
<mesh filename="package:///left_cover_v2.stl"/>
</geometry>
</collision>
<visual>
<origin xyz="0 0 -0.0015000000000000013323" rpy="1.570796326794896558 -1.5646701318588417617e-48 0" />
<geometry>
<mesh filename="package:///9g_servo_arm_v1.stl"/>
</geometry>
<material name="9g_servo_arm_v1_material">
<color rgba="0.62745098039215685404 0.62745098039215685404 0.62745098039215685404 1.0"/>
</material>
</visual>
<collision>
<origin xyz="0 0 -0.0015000000000000013323" rpy="1.570796326794896558 -1.5646701318588417617e-48 0" />
<geometry>
<mesh filename="package:///9g_servo_arm_v1.stl"/>
</geometry>
</collision>
<visual>
<origin xyz="-6.9388939039072283776e-18 0 -0.0015000000000000152101" rpy="-3.141592653589793116 -1.6662850516505818006e-16 -3.4694469519517206145e-18" />
<geometry>
<mesh filename="package:///18g_thigh_servo_attachment_v3.stl"/>
</geometry>
<material name="18g_thigh_servo_attachment_v3_material">
<color rgba="1 1 1 1.0"/>
</material>
</visual>
<collision>
<origin xyz="-6.9388939039072283776e-18 0 -0.0015000000000000152101" rpy="-3.141592653589793116 -1.6662850516505818006e-16 -3.4694469519517206145e-18" />
<geometry>
<mesh filename="package:///18g_thigh_servo_attachment_v3.stl"/>
</geometry>
</collision>
<visual>
<origin xyz="0.015650000000006120821 0.0071750000000001690897 -0.029249999999993100963" rpy="-1.570796326794896336 1.5707963267945610486 0" />
<geometry>
<mesh filename="package:///microservosg90.stl"/>
</geometry>
<material name="microservosg90_material">
<color rgba="0.35294117647058825815 0.35294117647058825815 0.35294117647058825815 1.0"/>
</material>
</visual>
<collision>
<origin xyz="0.015650000000006120821 0.0071750000000001690897 -0.029249999999993100963" rpy="-1.570796326794896336 1.5707963267945610486 0" />
<geometry>
<mesh filename="package:///microservosg90.stl"/>
</geometry>
</collision>
<visual>
<origin xyz="-0.019149999999988939758 0.0058922344346109770813 -0.04786506931266857473" rpy="-3.665734114006959092e-14 -1.5707963267945408425 0" />
<geometry>
<mesh filename="package:///bearing_5x8x2.5_v1.stl"/>
</geometry>
<material name="bearing_5x8x2.5_v1_material">
<color rgba="0.62745098039215685404 0.62745098039215685404 0.62745098039215685404 1.0"/>
</material>
</visual>
<collision>
<origin xyz="-0.019149999999988939758 0.0058922344346109770813 -0.04786506931266857473" rpy="-3.665734114006959092e-14 -1.5707963267945408425 0" />
<geometry>
<mesh filename="package:///bearing_5x8x2.5_v1.stl"/>
</geometry>
</collision>
<visual>
<origin xyz="0.0038875000000001408429 -4.1199682554449168492e-18 -0.0091000000000000039191" rpy="-4.5880209886826304443e-18 1.6662850516505820472e-16 3.141592653589793116" />
<geometry>
<mesh filename="package:///hip_joint_to_servo_v2.stl"/>
</geometry>
<material name="hip_joint_to_servo_v2_material">
<color rgba="1 1 1 1.0"/>
</material>
</visual>
<collision>
<origin xyz="0.0038875000000001408429 -4.1199682554449168492e-18 -0.0091000000000000039191" rpy="-4.5880209886826304443e-18 1.6662850516505820472e-16 3.141592653589793116" />
<geometry>
<mesh filename="package:///hip_joint_to_servo_v2.stl"/>
</geometry>
</collision>
<visual>
<origin xyz="0.0044749999999999998113 0.012125000000000458328 -0.02999999999999171385" rpy="-1.570796326794896558 1.5022351513306217979e-15 3.141592653589793116" />
<geometry>
<mesh filename="package:///hip_v2.stl"/>
</geometry>
<material name="hip_v2_material">
<color rgba="1 1 1 1.0"/>
</material>
</visual>
<collision>
<origin xyz="0.0044749999999999998113 0.012125000000000458328 -0.02999999999999171385" rpy="-1.570796326794896558 1.5022351513306217979e-15 3.141592653589793116" />
<geometry>
<mesh filename="package:///hip_v2.stl"/>
</geometry>
</collision>
<visual>
<origin xyz="-0.017649999999996862643 0.0071750000000001812328 -0.024150000000004279155" rpy="-3.0251981258801865177e-16 -1.5707963267945610486 0" />
<geometry>
<mesh filename="package:///bearing_10x15x4_v1.stl"/>
</geometry>
<material name="bearing_10x15x4_v1_material">
<color rgba="0.62745098039215685404 0.62745098039215685404 0.62745098039215685404 1.0"/>
</material>
</visual>
<collision>
<origin xyz="-0.017649999999996862643 0.0071750000000001812328 -0.024150000000004279155" rpy="-3.0251981258801865177e-16 -1.5707963267945610486 0" />
<geometry>
<mesh filename="package:///bearing_10x15x4_v1.stl"/>
</geometry>
</collision>
<visual>
<origin xyz="-0.015649999999996784539 0.0071750000000001803654 -0.024150000000003606082" rpy="-1.5707963267948970021 -1.5707963267945610486 0" />
<geometry>
<mesh filename="package:///9g_servo_arm_v1.stl"/>
</geometry>
<material name="9g_servo_arm_v1_material">
<color rgba="0.62745098039215685404 0.62745098039215685404 0.62745098039215685404 1.0"/>
</material>
</visual>
<collision>
<origin xyz="-0.015649999999996784539 0.0071750000000001803654 -0.024150000000003606082" rpy="-1.5707963267948970021 -1.5707963267945610486 0" />
<geometry>
<mesh filename="package:///9g_servo_arm_v1.stl"/>
</geometry>
</collision>
<visual>
<origin xyz="0.0044750000000063488992 -0.012125000000000468736 -0.029999999999996182498" rpy="1.570796326794896558 3.3582701687822854731e-13 3.141592653589793116" />
<geometry>
<mesh filename="package:///hip_v2.stl"/>
</geometry>
<material name="hip_v2_material">
<color rgba="1 1 1 1.0"/>
</material>
</visual>
<collision>
<origin xyz="0.0044750000000063488992 -0.012125000000000468736 -0.029999999999996182498" rpy="1.570796326794896558 3.3582701687822854731e-13 3.141592653589793116" />
<geometry>
<mesh filename="package:///hip_v2.stl"/>
</geometry>
</collision>
<visual>
<origin xyz="-0.015649999999993335908 -0.0052250000000002095116 -0.034350000000003592937" rpy="1.570796326794896558 1.5707963267945610486 0" />
<geometry>
<mesh filename="package:///9g_servo_arm_v1.stl"/>
</geometry>
<material name="9g_servo_arm_v1_material">
<color rgba="0.62745098039215685404 0.62745098039215685404 0.62745098039215685404 1.0"/>
</material>
</visual>
<collision>
<origin xyz="-0.015649999999993335908 -0.0052250000000002095116 -0.034350000000003592937" rpy="1.570796326794896558 1.5707963267945610486 0" />
<geometry>
<mesh filename="package:///9g_servo_arm_v1.stl"/>
</geometry>
</collision>
<visual>
<origin xyz="-0.021649999999997018851 0.0071750000000000025563 -0.0241500000000056253" rpy="7.4562739736932740406e-15 -1.5707963267945410646 0" />
<geometry>
<mesh filename="package:///left_forearm_pivot_v1.stl"/>
</geometry>
<material name="left_forearm_pivot_v1_material">
<color rgba="1 1 1 1.0"/>
</material>
</visual>
<collision>
<origin xyz="-0.021649999999997018851 0.0071750000000000025563 -0.0241500000000056253" rpy="7.4562739736932740406e-15 -1.5707963267945410646 0" />
<geometry>
<mesh filename="package:///left_forearm_pivot_v1.stl"/>
</geometry>
</collision>
<visual>
<origin xyz="-0.019149999999988939758 0.0058922344346109770813 -0.04786506931266857473" rpy="3.1415926535897558125 -1.5707963267945408425 0" />
<geometry>
<mesh filename="package:///servo_arm_retainer_v1.stl"/>
</geometry>
<material name="servo_arm_retainer_v1_material">
<color rgba="1 1 1 1.0"/>
</material>
</visual>
<collision>
<origin xyz="-0.019149999999988939758 0.0058922344346109770813 -0.04786506931266857473" rpy="3.1415926535897558125 -1.5707963267945408425 0" />
<geometry>
<mesh filename="package:///servo_arm_retainer_v1.stl"/>
</geometry>
</collision>
<visual>
<origin xyz="-0.022149999999992009414 0.018292109297700007847 -0.037665155617948899158" rpy="1.570796326795329545 0.68835957731061858667 -1.5707963267946589703" />
<geometry>
<mesh filename="package:///bearing_5x8x2.5_v1.stl"/>
</geometry>
<material name="bearing_5x8x2.5_v1_material">
<color rgba="0.62745098039215685404 0.62745098039215685404 0.62745098039215685404 1.0"/>
</material>
</visual>
<collision>
<origin xyz="-0.022149999999992009414 0.018292109297700007847 -0.037665155617948899158" rpy="1.570796326795329545 0.68835957731061858667 -1.5707963267946589703" />
<geometry>
<mesh filename="package:///bearing_5x8x2.5_v1.stl"/>
</geometry>
</collision>
<inertial>
<origin xyz="-0.0014149870812316511087 0.0026262653552970856123 -0.028173125869927921616" rpy="0 0 0"/>
<mass value="0.035898853366757597916" />
<inertia ixx="8.8254316677968369485e-06" ixy="1.5321144265341071473e-06"  ixz="-7.0751529199990089052e-07" iyy="1.1416196796456223682e-05" iyz="-1.8704472750179606306e-07" izz="8.4326370763718319835e-06" />
</inertial>
</link>

<link name="leftfemur">
<visual>
<origin xyz="1.7347234759768070944e-18 -6.9388939039072283776e-18 -0.0025000000000000022204" rpy="2.9383883133220779003e-29 -1.7783893110503516537e-29 7.863641712915428063e-17" />
<geometry>
<mesh filename="package:///bearing_5x8x2.5_v1.stl"/>
</geometry>
<material name="bearing_5x8x2.5_v1_material">
<color rgba="0.62745098039215685404 0.62745098039215685404 0.62745098039215685404 1.0"/>
</material>
</visual>
<collision>
<origin xyz="1.7347234759768070944e-18 -6.9388939039072283776e-18 -0.0025000000000000022204" rpy="2.9383883133220779003e-29 -1.7783893110503516537e-29 7.863641712915428063e-17" />
<geometry>
<mesh filename="package:///bearing_5x8x2.5_v1.stl"/>
</geometry>
</collision>
<visual>
<origin xyz="0.03499999999999994782 -5.5511151231257827021e-17 -0.0025000000000000438538" rpy="2.9383883133220779003e-29 -1.7783893110503516537e-29 7.863641712915428063e-17" />
<geometry>
<mesh filename="package:///bearing_5x8x2.5_v1.stl"/>
</geometry>
<material name="bearing_5x8x2.5_v1_material">
<color rgba="0.62745098039215685404 0.62745098039215685404 0.62745098039215685404 1.0"/>
</material>
</visual>
<collision>
<origin xyz="0.03499999999999994782 -5.5511151231257827021e-17 -0.0025000000000000438538" rpy="2.9383883133220779003e-29 -1.7783893110503516537e-29 7.863641712915428063e-17" />
<geometry>
<mesh filename="package:///bearing_5x8x2.5_v1.stl"/>
</geometry>
</collision>
<visual>
<origin xyz="3.1225022567582527699e-17 2.7755575615628913511e-17 0" rpy="-3.141592653589793116 -1.7783893110503516537e-29 7.863641712915428063e-17" />
<geometry>
<mesh filename="package:///lever_v1.stl"/>
</geometry>
<material name="lever_v1_material">
<color rgba="1 1 1 1.0"/>
</material>
</visual>
<collision>
<origin xyz="3.1225022567582527699e-17 2.7755575615628913511e-17 0" rpy="-3.141592653589793116 -1.7783893110503516537e-29 7.863641712915428063e-17" />
<geometry>
<mesh filename="package:///lever_v1.stl"/>
</geometry>
</collision>
<inertial>
<origin xyz="0.016745239433454649214 0.0019623707901208387212 -0.0012499999999999941713" rpy="0 0 0"/>
<mass value="0.0012188090534078449383" />
<inertia ixx="2.3153914212892998703e-08" ixy="7.3509510903220034529e-09"  ixz="6.4650519301803626498e-23" iyy="2.7100368005614662432e-07" iyz="-1.09430815773193468e-23" izz="2.9302349553645665563e-07" />
</inertial>
</link>

<joint name="femur_leftfront" type="revolute">
<origin xyz="-0.024650000000001406897 0.019549368670763487416 -0.011775631329240969503" rpy="1.570796326795334874 -0.66646697390099118863 -1.5707963267951601249" />
<parent link="lefthip" />
<child link="leftfemur" />
<axis xyz="0 0 1"/>
<limit effort="1" velocity="20" />
<joint_properties friction="0.0"/>
</joint>

<link name="leftthigh">
<visual>
<origin xyz="0 -3.4694469519536141888e-18 -0.0069999999999999992784" rpy="-6.6055504878560520827e-30 6.2425541518460372563e-30 -2.5408264050719269255e-17" />
<geometry>
<mesh filename="package:///right_thigh_v1.stl"/>
</geometry>
<material name="right_thigh_v1_material">
<color rgba="1 1 1 1.0"/>
</material>
</visual>
<collision>
<origin xyz="0 -3.4694469519536141888e-18 -0.0069999999999999992784" rpy="-6.6055504878560520827e-30 6.2425541518460372563e-30 -2.5408264050719269255e-17" />
<geometry>
<mesh filename="package:///right_thigh_v1.stl"/>
</geometry>
</collision>
<visual>
<origin xyz="0.034999999999982038534 -7.9866668833972198627e-15 -0.0044999999999999068523" rpy="-3.1415926535897917837 -3.4416913763379497766e-15 -9.3086176128034095306e-16" />
<geometry>
<mesh filename="package:///bearing_5x8x2.5_v1.stl"/>
</geometry>
<material name="bearing_5x8x2.5_v1_material">
<color rgba="0.62745098039215685404 0.62745098039215685404 0.62745098039215685404 1.0"/>
</material>
</visual>
<collision>
<origin xyz="0.034999999999982038534 -7.9866668833972198627e-15 -0.0044999999999999068523" rpy="-3.1415926535897917837 -3.4416913763379497766e-15 -9.3086176128034095306e-16" />
<geometry>
<mesh filename="package:///bearing_5x8x2.5_v1.stl"/>
</geometry>
</collision>
<inertial>
<origin xyz="0.013280795299928632031 -0.00036090962217552114213 -0.004495288279320248416" rpy="0 0 0"/>
<mass value="0.0018464875329195404828" />
<inertia ixx="2.9147242782952559493e-08" ixy="3.1720502075642859595e-09"  ixz="1.4292641337521414662e-08" iyy="3.5092221986757939663e-07" iyz="-8.5226644673134710941e-10" izz="3.6712034510499328269e-07" />
</inertial>
</link>

<link name="leftfoot">
<visual>
<origin xyz="2.2898349882893853646e-16 0 0.0004999999999999935052" rpy="-1.570796326794896336 7.2590061491182525888e-28 -1.8930827081845103288e-16" />
<geometry>
<mesh filename="package:///left_forearm_outside_v1.stl"/>
</geometry>
<material name="left_forearm_outside_v1_material">
<color rgba="1 1 1 1.0"/>
</material>
</visual>
<collision>
<origin xyz="2.2898349882893853646e-16 0 0.0004999999999999935052" rpy="-1.570796326794896336 7.2590061491182525888e-28 -1.8930827081845103288e-16" />
<geometry>
<mesh filename="package:///left_forearm_outside_v1.stl"/>
</geometry>
</collision>
<visual>
<origin xyz="0 0 -0.0030000000000000026645" rpy="-1.570796326794896558 2.5665972923433450406e-29 -6.3841240699234761017e-17" />
<geometry>
<mesh filename="package:///left_forearm_inside_v1.stl"/>
</geometry>
<material name="left_forearm_inside_v1_material">
<color rgba="1 1 1 1.0"/>
</material>
</visual>
<collision>
<origin xyz="0 0 -0.0030000000000000026645" rpy="-1.570796326794896558 2.5665972923433450406e-29 -6.3841240699234761017e-17" />
<geometry>
<mesh filename="package:///left_forearm_inside_v1.stl"/>
</geometry>
</collision>
<inertial>
<origin xyz="-0.011359259428207639508 0.00069384123630962936218 -0.0010747482996256516995" rpy="0 0 0"/>
<mass value="0.0052313671076180037062" />
<inertia ixx="1.3990969757495894961e-07" ixy="3.9342837035930331588e-08"  ixz="-1.01740454566335793e-08" iyy="2.2588013896284998625e-06" iyz="-6.5844125899863008252e-09" izz="2.2886673861905136574e-06" />
</inertial>
</link>

<joint name="foot_leftfront" type="revolute">
<origin xyz="0.034999999999982094046 -8.0005446712050343194e-15 -0.0069999999999999090727" rpy="-3.1415926535897900074 1.4027236575191825091e-15 -1.6352595016448581156" />
<parent link="leftthigh" />
<child link="leftfoot" />
<axis xyz="0 0 1"/>
<limit effort="300" velocity="300" lower="0" upper="1.0472"/>
<joint_properties friction="0.0"/>
</joint>

<joint name="thigh_leftfront" type="revolute">
<origin xyz="-0.017649999999996862643 0.0071750000000001751613 -0.024150000000004313849" rpy="-1.5707963267944642372 -0.68299626649609701534 -1.570796326795170117" />
<parent link="lefthip" />
<child link="leftthigh" />
<axis xyz="0 0 1"/>
<limit effort="300" velocity="300" lower="0" upper="1.0472"/>
<joint_properties friction="0.0"/>
</joint>

<joint name="frontlefthip" type="revolute">
<origin xyz="0.036800000000000845923 0.056500000000000223654 -0.00047047612756321785521" rpy="1.570796326794896558 -1.07552855510556222e-16 3.141592653589793116" />
<parent link="chassis" />
<child link="lefthip" />
<axis xyz="0 0 1"/>
<limit effort="300" velocity="300" lower="-1.0472" upper="1.0472"/>
<joint_properties friction="0.0"/>
</joint>

<link name="lefthip_2">
<visual>
<origin xyz="-0.019149999999988245869 0.0058922344346107732513 -0.047865069312668706569" rpy="1.2580762642903519765e-15 -1.5707963267945455055 0" />
<geometry>
<mesh filename="package:///bearing_5x8x2.5_v1.stl"/>
</geometry>
<material name="bearing_5x8x2.5_v1_material">
<color rgba="0.62745098039215685404 0.62745098039215685404 0.62745098039215685404 1.0"/>
</material>
</visual>
<collision>
<origin xyz="-0.019149999999988245869 0.0058922344346107732513 -0.047865069312668706569" rpy="1.2580762642903519765e-15 -1.5707963267945455055 0" />
<geometry>
<mesh filename="package:///bearing_5x8x2.5_v1.stl"/>
</geometry>
</collision>
<visual>
<origin xyz="-0.028649999999996282607 0.0071911362092343536837 -0.024136731956856616321" rpy="-1.5707963270749540907 -1.569593921142050208 1.570796327074955423" />
<geometry>
<mesh filename="package:///left_cover_v2.stl"/>
</geometry>
<material name="left_cover_v2_material">
<color rgba="1 1 1 1.0"/>
</material>
</visual>
<collision>
<origin xyz="-0.028649999999996282607 0.0071911362092343536837 -0.024136731956856616321" rpy="-1.5707963270749540907 -1.569593921142050208 1.570796327074955423" />
<geometry>
<mesh filename="package:///left_cover_v2.stl"/>
</geometry>
</collision>
<visual>
<origin xyz="0 0 -0.0015000000000000013323" rpy="3.141592653589793116 -2.4651903288156594287e-32 5.5511151231257716088e-17" />
<geometry>
<mesh filename="package:///18g_thigh_servo_attachment_v3.stl"/>
</geometry>
<material name="18g_thigh_servo_attachment_v3_material">
<color rgba="1 1 1 1.0"/>
</material>
</visual>
<collision>
<origin xyz="0 0 -0.0015000000000000013323" rpy="3.141592653589793116 -2.4651903288156594287e-32 5.5511151231257716088e-17" />
<geometry>
<mesh filename="package:///18g_thigh_servo_attachment_v3.stl"/>
</geometry>
</collision>
<visual>
<origin xyz="0.0044750000000062031824 -0.012125000000000005565 -0.029999999999996238009" rpy="1.570796326794896558 3.3566038837307654211e-13 -3.141592653589793116" />
<geometry>
<mesh filename="package:///hip_v2.stl"/>
</geometry>
<material name="hip_v2_material">
<color rgba="1 1 1 1.0"/>
</material>
</visual>
<collision>
<origin xyz="0.0044750000000062031824 -0.012125000000000005565 -0.029999999999996238009" rpy="1.570796326794896558 3.3566038837307654211e-13 -3.141592653589793116" />
<geometry>
<mesh filename="package:///hip_v2.stl"/>
</geometry>
</collision>
<visual>
<origin xyz="0.015650000000005537953 0.0071749999999999643924 -0.029249999999993198108" rpy="-1.570796326794896558 1.5707963267945610486 0" />
<geometry>
<mesh filename="package:///microservosg90.stl"/>
</geometry>
<material name="microservosg90_material">
<color rgba="0.35294117647058825815 0.35294117647058825815 0.35294117647058825815 1.0"/>
</material>
</visual>
<collision>
<origin xyz="0.015650000000005537953 0.0071749999999999643924 -0.029249999999993198108" rpy="-1.570796326794896558 1.5707963267945610486 0" />
<geometry>
<mesh filename="package:///microservosg90.stl"/>
</geometry>
</collision>
<visual>
<origin xyz="0.0038875000000134218858 -7.3183646642771549296e-18 -0.05089999999998820468" rpy="-3.141592653589793116 3.3699599501924214586e-13 -3.141592653589793116" />
<geometry>
<mesh filename="package:///hip_joint_to_bearing_v3.stl"/>
</geometry>
<material name="hip_joint_to_bearing_v3_material">
<color rgba="1 1 1 1.0"/>
</material>
</visual>
<collision>
<origin xyz="0.0038875000000134218858 -7.3183646642771549296e-18 -0.05089999999998820468" rpy="-3.141592653589793116 3.3699599501924214586e-13 -3.141592653589793116" />
<geometry>
<mesh filename="package:///hip_joint_to_bearing_v3.stl"/>
</geometry>
</collision>
<visual>
<origin xyz="-0.019149999999992790845 -0.0052250000000000065489 -0.034350000000004807243" rpy="-1.570796326794896558 -1.5707963267945614927 0" />
<geometry>
<mesh filename="package:///left_forearm_servo_attachment_v1.stl"/>
</geometry>
<material name="left_forearm_servo_attachment_v1_material">
<color rgba="1 1 1 1.0"/>
</material>
</visual>
<collision>
<origin xyz="-0.019149999999992790845 -0.0052250000000000065489 -0.034350000000004807243" rpy="-1.570796326794896558 -1.5707963267945614927 0" />
<geometry>
<mesh filename="package:///left_forearm_servo_attachment_v1.stl"/>
</geometry>
</collision>
<visual>
<origin xyz="-0.021649999999996207001 0.0071749999999998715847 -0.024150000000005639178" rpy="7.5175441797125890929e-15 -1.5707963267945397323 0" />
<geometry>
<mesh filename="package:///left_forearm_pivot_v1.stl"/>
</geometry>
<material name="left_forearm_pivot_v1_material">
<color rgba="1 1 1 1.0"/>
</material>
</visual>
<collision>
<origin xyz="-0.021649999999996207001 0.0071749999999998715847 -0.024150000000005639178" rpy="7.5175441797125890929e-15 -1.5707963267945397323 0" />
<geometry>
<mesh filename="package:///left_forearm_pivot_v1.stl"/>
</geometry>
</collision>
<visual>
<origin xyz="0 0 -0.0015000000000000013323" rpy="1.570796326794896558 1.888393838202867699e-48 -2.0141931291516121755e-33" />
<geometry>
<mesh filename="package:///9g_servo_arm_v1.stl"/>
</geometry>
<material name="9g_servo_arm_v1_material">
<color rgba="0.62745098039215685404 0.62745098039215685404 0.62745098039215685404 1.0"/>
</material>
</visual>
<collision>
<origin xyz="0 0 -0.0015000000000000013323" rpy="1.570796326794896558 1.888393838202867699e-48 -2.0141931291516121755e-33" />
<geometry>
<mesh filename="package:///9g_servo_arm_v1.stl"/>
</geometry>
</collision>
<visual>
<origin xyz="-0.022149999999991711042 0.018292112015483981413 -0.037665158921918170942" rpy="1.5707963267953330977 0.68835931085885382341 -1.5707963267946181141" />
<geometry>
<mesh filename="package:///left_forearm_linkage_v1.stl"/>
</geometry>
<material name="left_forearm_linkage_v1_material">
<color rgba="1 1 1 1.0"/>
</material>
</visual>
<collision>
<origin xyz="-0.022149999999991711042 0.018292112015483981413 -0.037665158921918170942" rpy="1.5707963267953330977 0.68835931085885382341 -1.5707963267946181141" />
<geometry>
<mesh filename="package:///left_forearm_linkage_v1.stl"/>
</geometry>
</collision>
<visual>
<origin xyz="0.015650000000005537953 -0.0052250000000000004774 -0.02924999999999318423" rpy="1.570796326794896558 -1.5707963267945610486 0" />
<geometry>
<mesh filename="package:///microservosg90.stl"/>
</geometry>
<material name="microservosg90_material">
<color rgba="0.35294117647058825815 0.35294117647058825815 0.35294117647058825815 1.0"/>
</material>
</visual>
<collision>
<origin xyz="0.015650000000005537953 -0.0052250000000000004774 -0.02924999999999318423" rpy="1.570796326794896558 -1.5707963267945610486 0" />
<geometry>
<mesh filename="package:///microservosg90.stl"/>
</geometry>
</collision>
<visual>
<origin xyz="0.0038875000000000159428 -7.3183646642771549296e-18 -0.0090999999999999969802" rpy="3.3543053820388777836e-49 2.4651903288156594287e-32 -3.141592653589793116" />
<geometry>
<mesh filename="package:///hip_joint_to_servo_v2.stl"/>
</geometry>
<material name="hip_joint_to_servo_v2_material">
<color rgba="1 1 1 1.0"/>
</material>
</visual>
<collision>
<origin xyz="0.0038875000000000159428 -7.3183646642771549296e-18 -0.0090999999999999969802" rpy="3.3543053820388777836e-49 2.4651903288156594287e-32 -3.141592653589793116" />
<geometry>
<mesh filename="package:///hip_joint_to_servo_v2.stl"/>
</geometry>
</collision>
<visual>
<origin xyz="-0.015649999999996208611 0.0071749999999999713313 -0.024150000000003668532" rpy="-1.6653345369385732219e-16 -1.5707963267945610486 0" />
<geometry>
<mesh filename="package:///9g_thigh_servo_attachment_v1.stl"/>
</geometry>
<material name="9g_thigh_servo_attachment_v1_material">
<color rgba="1 1 1 1.0"/>
</material>
</visual>
<collision>
<origin xyz="-0.015649999999996208611 0.0071749999999999713313 -0.024150000000003668532" rpy="-1.6653345369385732219e-16 -1.5707963267945610486 0" />
<geometry>
<mesh filename="package:///9g_thigh_servo_attachment_v1.stl"/>
</geometry>
</collision>
<visual>
<origin xyz="-0.015649999999996208611 0.0071749999999999713313 -0.024150000000003668532" rpy="-1.57079632679489678 -1.5707963267945610486 0" />
<geometry>
<mesh filename="package:///9g_servo_arm_v1.stl"/>
</geometry>
<material name="9g_servo_arm_v1_material">
<color rgba="0.62745098039215685404 0.62745098039215685404 0.62745098039215685404 1.0"/>
</material>
</visual>
<collision>
<origin xyz="-0.015649999999996208611 0.0071749999999999713313 -0.024150000000003668532" rpy="-1.57079632679489678 -1.5707963267945610486 0" />
<geometry>
<mesh filename="package:///9g_servo_arm_v1.stl"/>
</geometry>
</collision>
<visual>
<origin xyz="-0.022149999999991711042 0.018292112015483981413 -0.037665158921918170942" rpy="1.5707963267953328756 0.68835931085885382341 -1.5707963267946185582" />
<geometry>
<mesh filename="package:///bearing_5x8x2.5_v1.stl"/>
</geometry>
<material name="bearing_5x8x2.5_v1_material">
<color rgba="0.62745098039215685404 0.62745098039215685404 0.62745098039215685404 1.0"/>
</material>
</visual>
<collision>
<origin xyz="-0.022149999999991711042 0.018292112015483981413 -0.037665158921918170942" rpy="1.5707963267953328756 0.68835931085885382341 -1.5707963267946185582" />
<geometry>
<mesh filename="package:///bearing_5x8x2.5_v1.stl"/>
</geometry>
</collision>
<visual>
<origin xyz="0.0044749999999998471556 0.012124999999999988218 -0.029999999999991783239" rpy="-1.570796326794896558 1.3356066461656157813e-15 3.141592653589793116" />
<geometry>
<mesh filename="package:///hip_v2.stl"/>
</geometry>
<material name="hip_v2_material">
<color rgba="1 1 1 1.0"/>
</material>
</visual>
<collision>
<origin xyz="0.0044749999999998471556 0.012124999999999988218 -0.029999999999991783239" rpy="-1.570796326794896558 1.3356066461656157813e-15 3.141592653589793116" />
<geometry>
<mesh filename="package:///hip_v2.stl"/>
</geometry>
</collision>
<visual>
<origin xyz="-0.015649999999992787736 -0.0052250000000000117531 -0.034350000000003613754" rpy="1.57079632679489678 1.5707963267945610486 0" />
<geometry>
<mesh filename="package:///9g_servo_arm_v1.stl"/>
</geometry>
<material name="9g_servo_arm_v1_material">
<color rgba="0.62745098039215685404 0.62745098039215685404 0.62745098039215685404 1.0"/>
</material>
</visual>
<collision>
<origin xyz="-0.015649999999992787736 -0.0052250000000000117531 -0.034350000000003613754" rpy="1.57079632679489678 1.5707963267945610486 0" />
<geometry>
<mesh filename="package:///9g_servo_arm_v1.stl"/>
</geometry>
</collision>
<visual>
<origin xyz="-0.019149999999988245869 0.0058922344346107732513 -0.047865069312668706569" rpy="3.141592653589793116 -1.5707963267945455055 0" />
<geometry>
<mesh filename="package:///servo_arm_retainer_v1.stl"/>
</geometry>
<material name="servo_arm_retainer_v1_material">
<color rgba="1 1 1 1.0"/>
</material>
</visual>
<collision>
<origin xyz="-0.019149999999988245869 0.0058922344346107732513 -0.047865069312668706569" rpy="3.141592653589793116 -1.5707963267945455055 0" />
<geometry>
<mesh filename="package:///servo_arm_retainer_v1.stl"/>
</geometry>
</collision>
<visual>
<origin xyz="-0.017649999999996203448 0.007174999999999901075 -0.024150000000004251399" rpy="-1.6431479197523074546e-16 -1.5707963267945610486 0" />
<geometry>
<mesh filename="package:///bearing_10x15x4_v1.stl"/>
</geometry>
<material name="bearing_10x15x4_v1_material">
<color rgba="0.62745098039215685404 0.62745098039215685404 0.62745098039215685404 1.0"/>
</material>
</visual>
<collision>
<origin xyz="-0.017649999999996203448 0.007174999999999901075 -0.024150000000004251399" rpy="-1.6431479197523074546e-16 -1.5707963267945610486 0" />
<geometry>
<mesh filename="package:///bearing_10x15x4_v1.stl"/>
</geometry>
</collision>
<inertial>
<origin xyz="-0.0014149870812316209679 0.0026260940434307293231 -0.028173120215437556096" rpy="0 0 0"/>
<mass value="0.035898853366757604855" />
<inertia ixx="8.8252350075534964836e-06" ixy="1.5319581048346723732e-06"  ixz="-7.0751013417706971989e-07" iyy="1.1416196374334967479e-05" iyz="-1.8697377752515868257e-07" izz="8.4324408382492225611e-06" />
</inertial>
</link>

<link name="leftthigh_2">
<visual>
<origin xyz="1.3877787807814456755e-17 0 -0.0069999999999999992784" rpy="4.2170285906946465727e-29 -2.9438927917129553116e-29 -8.2698090563950440512e-17" />
<geometry>
<mesh filename="package:///right_thigh_v1.stl"/>
</geometry>
<material name="right_thigh_v1_material">
<color rgba="1 1 1 1.0"/>
</material>
</visual>
<collision>
<origin xyz="1.3877787807814456755e-17 0 -0.0069999999999999992784" rpy="4.2170285906946465727e-29 -2.9438927917129553116e-29 -8.2698090563950440512e-17" />
<geometry>
<mesh filename="package:///right_thigh_v1.stl"/>
</geometry>
</collision>
<visual>
<origin xyz="0.035000000000000100475 -2.4147350785597154754e-15 -0.0044999999999998652189" rpy="-3.1415926535897868987 -1.3878168082508266872e-15 -1.0612352477184145494e-13" />
<geometry>
<mesh filename="package:///bearing_5x8x2.5_v1.stl"/>
</geometry>
<material name="bearing_5x8x2.5_v1_material">
<color rgba="0.62745098039215685404 0.62745098039215685404 0.62745098039215685404 1.0"/>
</material>
</visual>
<collision>
<origin xyz="0.035000000000000100475 -2.4147350785597154754e-15 -0.0044999999999998652189" rpy="-3.1415926535897868987 -1.3878168082508266872e-15 -1.0612352477184145494e-13" />
<geometry>
<mesh filename="package:///bearing_5x8x2.5_v1.stl"/>
</geometry>
</collision>
<inertial>
<origin xyz="0.013280795299929456024 -0.00036090962217526787251 -0.0044952882793202466813" rpy="0 0 0"/>
<mass value="0.0018464875329195404828" />
<inertia ixx="2.9147242782952880439e-08" ixy="3.17205020755368564e-09"  ixz="1.429264133752321957e-08" iyy="3.5092221986764440641e-07" iyz="-8.5226644673077097811e-10" izz="3.6712034510505861011e-07" />
</inertial>
</link>

<link name="leftfoot_2">
<visual>
<origin xyz="-6.2450045135165055399e-16 -2.7755575615628913511e-17 0.0004999999999999935052" rpy="-1.57079632679489678 -2.0875323207119765524e-28 -9.6648317970636003512e-17" />
<geometry>
<mesh filename="package:///left_forearm_outside_v1.stl"/>
</geometry>
<material name="left_forearm_outside_v1_material">
<color rgba="1 1 1 1.0"/>
</material>
</visual>
<collision>
<origin xyz="-6.2450045135165055399e-16 -2.7755575615628913511e-17 0.0004999999999999935052" rpy="-1.57079632679489678 -2.0875323207119765524e-28 -9.6648317970636003512e-17" />
<geometry>
<mesh filename="package:///left_forearm_outside_v1.stl"/>
</geometry>
</collision>
<visual>
<origin xyz="-1.3877787807814456755e-17 -2.7755575615628913511e-17 -0.0030000000000000026645" rpy="-1.570796326794896558 -7.7250000057067444988e-30 3.2883220873265247532e-17" />
<geometry>
<mesh filename="package:///left_forearm_inside_v1.stl"/>
</geometry>
<material name="left_forearm_inside_v1_material">
<color rgba="1 1 1 1.0"/>
</material>
</visual>
<collision>
<origin xyz="-1.3877787807814456755e-17 -2.7755575615628913511e-17 -0.0030000000000000026645" rpy="-1.570796326794896558 -7.7250000057067444988e-30 3.2883220873265247532e-17" />
<geometry>
<mesh filename="package:///left_forearm_inside_v1.stl"/>
</geometry>
</collision>
<inertial>
<origin xyz="-0.011359259428207946555 0.00069384123630958653619 -0.0010747482996256516995" rpy="0 0 0"/>
<mass value="0.0052313671076180037062" />
<inertia ixx="1.3990969757495654086e-07" ixy="3.9342837035929597052e-08"  ixz="-1.0174045456628884222e-08" iyy="2.2588013896284464995e-06" iyz="-6.5844125899863669997e-09" izz="2.2886673861905081516e-06" />
</inertial>
</link>

<joint name="foot_leftback" type="revolute">
<origin xyz="0.035000000000000058842 -2.2759572004815709079e-15 -0.0069999999999998674394" rpy="-3.1415926535897926719 6.6159403471175274119e-15 -1.6625457993150511982" />
<parent link="leftthigh_2" />
<child link="leftfoot_2" />
<axis xyz="0 0 1"/>
<limit effort="300" velocity="300" lower="0" upper="1.0472"/>
<joint_properties friction="0.0"/>
</joint>

<joint name="thigh_leftback" type="revolute">
<origin xyz="-0.017649999999996203448 0.0071749999999998993402 -0.024150000000004223644" rpy="-1.5707963267944760055 -0.64616105155389358394 -1.570796326795150577" />
<parent link="lefthip_2" />
<child link="leftthigh_2" />
<axis xyz="0 0 1"/>
<limit effort="300" velocity="300" lower="0" upper="1.0472"/>
<joint_properties friction="0.0"/>
</joint>

<link name="leftfemur_2">
<visual>
<origin xyz="-4.1633363423443370266e-17 -2.7755575615628913511e-17 0" rpy="3.141592653589793116 3.0913692823123433779e-29 -1.8089770761682631591e-17" />
<geometry>
<mesh filename="package:///lever_v1.stl"/>
</geometry>
<material name="lever_v1_material">
<color rgba="1 1 1 1.0"/>
</material>
</visual>
<collision>
<origin xyz="-4.1633363423443370266e-17 -2.7755575615628913511e-17 0" rpy="3.141592653589793116 3.0913692823123433779e-29 -1.8089770761682631591e-17" />
<geometry>
<mesh filename="package:///lever_v1.stl"/>
</geometry>
</collision>
<visual>
<origin xyz="-1.3877787807814456755e-17 0 -0.0024999999999999952816" rpy="-1.7428680753365667806e-29 3.0913692823123433779e-29 -1.8089770761682631591e-17" />
<geometry>
<mesh filename="package:///bearing_5x8x2.5_v1.stl"/>
</geometry>
<material name="bearing_5x8x2.5_v1_material">
<color rgba="0.62745098039215685404 0.62745098039215685404 0.62745098039215685404 1.0"/>
</material>
</visual>
<collision>
<origin xyz="-1.3877787807814456755e-17 0 -0.0024999999999999952816" rpy="-1.7428680753365667806e-29 3.0913692823123433779e-29 -1.8089770761682631591e-17" />
<geometry>
<mesh filename="package:///bearing_5x8x2.5_v1.stl"/>
</geometry>
</collision>
<visual>
<origin xyz="0.034999999999999989453 -8.3266726846886740532e-17 -0.0025000000000000716094" rpy="-1.7428680753365667806e-29 3.0913692823123433779e-29 -1.8089770761682631591e-17" />
<geometry>
<mesh filename="package:///bearing_5x8x2.5_v1.stl"/>
</geometry>
<material name="bearing_5x8x2.5_v1_material">
<color rgba="0.62745098039215685404 0.62745098039215685404 0.62745098039215685404 1.0"/>
</material>
</visual>
<collision>
<origin xyz="0.034999999999999989453 -8.3266726846886740532e-17 -0.0025000000000000716094" rpy="-1.7428680753365667806e-29 3.0913692823123433779e-29 -1.8089770761682631591e-17" />
<geometry>
<mesh filename="package:///bearing_5x8x2.5_v1.stl"/>
</geometry>
</collision>
<inertial>
<origin xyz="0.016745239433454586764 0.0019623707901207879806 -0.0012499999999999956892" rpy="0 0 0"/>
<mass value="0.0012188090534078449383" />
<inertia ixx="2.3153914212892968924e-08" ixy="7.3509510903220985787e-09"  ixz="1.1632194093785200273e-22" iyy="2.7100368005614683607e-07" iyz="-1.4331906839986991087e-23" izz="2.9302349553645681445e-07" />
</inertial>
</link>

<joint name="femur_leftback" type="revolute">
<origin xyz="-0.024650000000000477085 0.019549368670763501293 -0.011775631329240782152" rpy="1.5707963267953368725 -0.67051192598255138222 -1.5707963267951625674" />
<parent link="lefthip_2" />
<child link="leftfemur_2" />
<axis xyz="0 0 1"/>
<limit effort="300" velocity="300" />
<joint_properties friction="0.0"/>
</joint>

<joint name="backlefthip" type="revolute">
<origin xyz="0.036800000000000568368 0.15150000000000005129 -0.00047047612756297499392" rpy="1.570796326794896558 -1.0648674274956604569e-16 3.141592653589793116" />
<parent link="chassis" />
<child link="lefthip_2" />
<axis xyz="0 0 1"/>
<limit effort="300" velocity="300" lower="-1.0472" upper="1.0472"/>
<joint_properties friction="0.0"/>
</joint>

<link name="righthip">
<visual>
<origin xyz="-0.024642932224072586211 -0.018555812535801033403 -0.039164960532352188771" rpy="1.5707963267948943376 0.6883753102790965972 1.5707963267948921171" />
<geometry>
<mesh filename="package:///right_forearm_linkage_v1.stl"/>
</geometry>
<material name="right_forearm_linkage_v1_material">
<color rgba="1 1 1 1.0"/>
</material>
</visual>
<collision>
<origin xyz="-0.024642932224072586211 -0.018555812535801033403 -0.039164960532352188771" rpy="1.5707963267948943376 0.6883753102790965972 1.5707963267948921171" />
<geometry>
<mesh filename="package:///right_forearm_linkage_v1.stl"/>
</geometry>
</collision>
<visual>
<origin xyz="-0.024642932224072586211 -0.018555812535801033403 -0.039164960532352188771" rpy="1.5707963267948934494 0.68837531027909681924 1.5707963267948921171" />
<geometry>
<mesh filename="package:///bearing_5x8x2.5_v1.stl"/>
</geometry>
<material name="bearing_5x8x2.5_v1_material">
<color rgba="0.62745098039215685404 0.62745098039215685404 0.62745098039215685404 1.0"/>
</material>
</visual>
<collision>
<origin xyz="-0.024642932224072586211 -0.018555812535801033403 -0.039164960532352188771" rpy="1.5707963267948934494 0.68837531027909681924 1.5707963267948921171" />
<geometry>
<mesh filename="package:///bearing_5x8x2.5_v1.stl"/>
</geometry>
</collision>
<visual>
<origin xyz="0.0044749999999997153166 0.012124999999999802602 -0.029999999999991536909" rpy="-1.5707963267948970021 1.8353404112987402494e-15 3.141592653589793116" />
<geometry>
<mesh filename="package:///hip_v2.stl"/>
</geometry>
<material name="hip_v2_material">
<color rgba="1 1 1 1.0"/>
</material>
</visual>
<collision>
<origin xyz="0.0044749999999997153166 0.012124999999999802602 -0.029999999999991536909" rpy="-1.5707963267948970021 1.8353404112987402494e-15 3.141592653589793116" />
<geometry>
<mesh filename="package:///hip_v2.stl"/>
</geometry>
</collision>
<visual>
<origin xyz="-0.01564293222407300149 -0.007438863714561101681 -0.025649999999990881483" rpy="7.9146758591381857928e-17 -1.5707963267948956698 0" />
<geometry>
<mesh filename="package:///9g_thigh_servo_attachment_v1.stl"/>
</geometry>
<material name="9g_thigh_servo_attachment_v1_material">
<color rgba="1 1 1 1.0"/>
</material>
</visual>
<collision>
<origin xyz="-0.01564293222407300149 -0.007438863714561101681 -0.025649999999990881483" rpy="7.9146758591381857928e-17 -1.5707963267948956698 0" />
<geometry>
<mesh filename="package:///9g_thigh_servo_attachment_v1.stl"/>
</geometry>
</collision>
<visual>
<origin xyz="-0.01564293222407300149 -0.007438863714561101681 -0.025649999999990881483" rpy="-1.570796326794896558 -1.5707963267948956698 0" />
<geometry>
<mesh filename="package:///9g_servo_arm_v1.stl"/>
</geometry>
<material name="9g_servo_arm_v1_material">
<color rgba="0.62745098039215685404 0.62745098039215685404 0.62745098039215685404 1.0"/>
</material>
</visual>
<collision>
<origin xyz="-0.01564293222407300149 -0.007438863714561101681 -0.025649999999990881483" rpy="-1.570796326794896558 -1.5707963267948956698 0" />
<geometry>
<mesh filename="package:///9g_servo_arm_v1.stl"/>
</geometry>
</collision>
<visual>
<origin xyz="-0.021642932224072881919 0.0049611362854388310964 -0.03584999999999079201" rpy="1.570796326794896558 -1.5707963267948958919 0" />
<geometry>
<mesh filename="package:///right_forearm_servo_attachment_v1.stl"/>
</geometry>
<material name="right_forearm_servo_attachment_v1_material">
<color rgba="1 1 1 1.0"/>
</material>
</visual>
<collision>
<origin xyz="-0.021642932224072881919 0.0049611362854388310964 -0.03584999999999079201" rpy="1.570796326794896558 -1.5707963267948958919 0" />
<geometry>
<mesh filename="package:///right_forearm_servo_attachment_v1.stl"/>
</geometry>
</collision>
<visual>
<origin xyz="0 3.3881317890172013563e-19 -0.0015000000000000152101" rpy="-3.1415926535897926719 -1.1350879944306512947e-31 -4.3738591260764381265e-29" />
<geometry>
<mesh filename="package:///18g_thigh_servo_attachment_v3.stl"/>
</geometry>
<material name="18g_thigh_servo_attachment_v3_material">
<color rgba="1 1 1 1.0"/>
</material>
</visual>
<collision>
<origin xyz="0 3.3881317890172013563e-19 -0.0015000000000000152101" rpy="-3.1415926535897926719 -1.1350879944306512947e-31 -4.3738591260764381265e-29" />
<geometry>
<mesh filename="package:///18g_thigh_servo_attachment_v3.stl"/>
</geometry>
</collision>
<visual>
<origin xyz="-0.021642932224072743141 -0.007438863714561101681 -0.025649999999990891891" rpy="-3.141592653589793116 -1.5707963267948945596 0" />
<geometry>
<mesh filename="package:///right_forearm_pivot_v1.stl"/>
</geometry>
<material name="right_forearm_pivot_v1_material">
<color rgba="1 1 1 1.0"/>
</material>
</visual>
<collision>
<origin xyz="-0.021642932224072743141 -0.007438863714561101681 -0.025649999999990891891" rpy="-3.141592653589793116 -1.5707963267948945596 0" />
<geometry>
<mesh filename="package:///right_forearm_pivot_v1.stl"/>
</geometry>
</collision>
<visual>
<origin xyz="-0.015642932224072925163 0.0049611362854387313498 -0.035849999999990798949" rpy="1.570796326794896558 1.5707963267948961139 0" />
<geometry>
<mesh filename="package:///9g_servo_arm_v1.stl"/>
</geometry>
<material name="9g_servo_arm_v1_material">
<color rgba="0.62745098039215685404 0.62745098039215685404 0.62745098039215685404 1.0"/>
</material>
</visual>
<collision>
<origin xyz="-0.015642932224072925163 0.0049611362854387313498 -0.035849999999990798949" rpy="1.570796326794896558 1.5707963267948961139 0" />
<geometry>
<mesh filename="package:///9g_servo_arm_v1.stl"/>
</geometry>
</collision>
<visual>
<origin xyz="0.0044750000000060227712 -0.012124999999999826888 -0.029999999999996019434" rpy="1.570796326794896336 3.3616012213821440744e-13 -3.141592653589793116" />
<geometry>
<mesh filename="package:///hip_v2.stl"/>
</geometry>
<material name="hip_v2_material">
<color rgba="1 1 1 1.0"/>
</material>
</visual>
<collision>
<origin xyz="0.0044750000000060227712 -0.012124999999999826888 -0.029999999999996019434" rpy="1.570796326794896336 3.3616012213821440744e-13 -3.141592653589793116" />
<geometry>
<mesh filename="package:///hip_v2.stl"/>
</geometry>
</collision>
<visual>
<origin xyz="0.015657067775926226255 -0.0074388637145611008136 -0.030749999999990784705" rpy="-1.57079632679489678 1.5707963267948956698 0" />
<geometry>
<mesh filename="package:///microservosg90.stl"/>
</geometry>
<material name="microservosg90_material">
<color rgba="0.35294117647058825815 0.35294117647058825815 0.35294117647058825815 1.0"/>
</material>
</visual>
<collision>
<origin xyz="0.015657067775926226255 -0.0074388637145611008136 -0.030749999999990784705" rpy="-1.57079632679489678 1.5707963267948956698 0" />
<geometry>
<mesh filename="package:///microservosg90.stl"/>
</geometry>
</collision>
<visual>
<origin xyz="-0.028642932224072444047 -0.0074450181671780121806 -0.025644596317651355277" rpy="-1.5707963267902926852 -1.570319910106017236 -1.5707963267974121013" />
<geometry>
<mesh filename="package:///right_cover_v2.stl"/>
</geometry>
<material name="right_cover_v2_material">
<color rgba="1 1 1 1.0"/>
</material>
</visual>
<collision>
<origin xyz="-0.028642932224072444047 -0.0074450181671780121806 -0.025644596317651355277" rpy="-1.5707963267902926852 -1.570319910106017236 -1.5707963267974121013" />
<geometry>
<mesh filename="package:///right_cover_v2.stl"/>
</geometry>
</collision>
<visual>
<origin xyz="0.015657067775926264419 0.0049611362854387304824 -0.030749999999990784705" rpy="1.570796326794896558 -1.5707963267948956698 0" />
<geometry>
<mesh filename="package:///microservosg90.stl"/>
</geometry>
<material name="microservosg90_material">
<color rgba="0.35294117647058825815 0.35294117647058825815 0.35294117647058825815 1.0"/>
</material>
</visual>
<collision>
<origin xyz="0.015657067775926264419 0.0049611362854387304824 -0.030749999999990784705" rpy="1.570796326794896558 -1.5707963267948956698 0" />
<geometry>
<mesh filename="package:///microservosg90.stl"/>
</geometry>
</collision>
<visual>
<origin xyz="0.0038875000000003837042 -1.6805133673525318727e-17 -0.050899999999988898569" rpy="3.1415926535897926719 3.3749596847204067833e-13 -3.141592653589793116" />
<geometry>
<mesh filename="package:///hip_joint_to_bearing_v3.stl"/>
</geometry>
<material name="hip_joint_to_bearing_v3_material">
<color rgba="1 1 1 1.0"/>
</material>
</visual>
<collision>
<origin xyz="0.0038875000000003837042 -1.6805133673525318727e-17 -0.050899999999988898569" rpy="3.1415926535897926719 3.3749596847204067833e-13 -3.141592653589793116" />
<geometry>
<mesh filename="package:///hip_joint_to_bearing_v3.stl"/>
</geometry>
</collision>
<visual>
<origin xyz="0 0 -0.0014999999999999943934" rpy="1.570796326794896558 -1.490118629063914348e-32 4.3188979002883764005e-32" />
<geometry>
<mesh filename="package:///9g_servo_arm_v1.stl"/>
</geometry>
<material name="9g_servo_arm_v1_material">
<color rgba="0.62745098039215685404 0.62745098039215685404 0.62745098039215685404 1.0"/>
</material>
</visual>
<collision>
<origin xyz="0 0 -0.0014999999999999943934" rpy="1.570796326794896558 -1.490118629063914348e-32 4.3188979002883764005e-32" />
<geometry>
<mesh filename="package:///9g_servo_arm_v1.stl"/>
</geometry>
</collision>
<visual>
<origin xyz="0.0038874999999998910427 -5.3532482266471781429e-18 -0.0090999999999999692246" rpy="-3.3227135703941702828e-16 4.9933461843231528774e-16 3.141592653589793116" />
<geometry>
<mesh filename="package:///hip_joint_to_servo_v2.stl"/>
</geometry>
<material name="hip_joint_to_servo_v2_material">
<color rgba="1 1 1 1.0"/>
</material>
</visual>
<collision>
<origin xyz="0.0038874999999998910427 -5.3532482266471781429e-18 -0.0090999999999999692246" rpy="-3.3227135703941702828e-16 4.9933461843231528774e-16 3.141592653589793116" />
<geometry>
<mesh filename="package:///hip_joint_to_servo_v2.stl"/>
</geometry>
</collision>
<visual>
<origin xyz="-0.019142932224072775615 -0.0061560981491680585864 -0.049365069312650278199" rpy="-3.141592653589793116 1.5707963267948958919 0" />
<geometry>
<mesh filename="package:///bearing_5x8x2.5_v1.stl"/>
</geometry>
<material name="bearing_5x8x2.5_v1_material">
<color rgba="0.62745098039215685404 0.62745098039215685404 0.62745098039215685404 1.0"/>
</material>
</visual>
<collision>
<origin xyz="-0.019142932224072775615 -0.0061560981491680585864 -0.049365069312650278199" rpy="-3.141592653589793116 1.5707963267948958919 0" />
<geometry>
<mesh filename="package:///bearing_5x8x2.5_v1.stl"/>
</geometry>
</collision>
<visual>
<origin xyz="-0.021642932224072743141 -0.007438863714561101681 -0.025649999999990891891" rpy="-3.141592653589793116 -1.5707963267948945596 0" />
<geometry>
<mesh filename="package:///bearing_10x15x4_v1.stl"/>
</geometry>
<material name="bearing_10x15x4_v1_material">
<color rgba="0.62745098039215685404 0.62745098039215685404 0.62745098039215685404 1.0"/>
</material>
</visual>
<collision>
<origin xyz="-0.021642932224072743141 -0.007438863714561101681 -0.025649999999990891891" rpy="-3.141592653589793116 -1.5707963267948945596 0" />
<geometry>
<mesh filename="package:///bearing_10x15x4_v1.stl"/>
</geometry>
</collision>
<inertial>
<origin xyz="-0.0011710670974884279487 -0.0027608821607481479586 -0.028924196672178853484" rpy="0 0 0"/>
<mass value="0.035352377824358502401" />
<inertia ixx="8.7057396674940755194e-06" ixy="-1.5198144212103967883e-06"  ixz="-6.3174231461625394448e-07" iyy="1.1158355849914649899e-05" iyz="1.7209971524295812401e-07" izz="8.3016348716513194513e-06" />
</inertial>
</link>

<link name="rightthigh">
<visual>
<origin xyz="0.034999999999997102873 -5.1174342541315809285e-15 -0.0069999999999990764055" rpy="3.0320190802513065509e-13 -1.5099033134901264358e-14 -4.1015697998360108845e-13" />
<geometry>
<mesh filename="package:///bearing_5x8x2.5_v1.stl"/>
</geometry>
<material name="bearing_5x8x2.5_v1_material">
<color rgba="0.62745098039215685404 0.62745098039215685404 0.62745098039215685404 1.0"/>
</material>
</visual>
<collision>
<origin xyz="0.034999999999997102873 -5.1174342541315809285e-15 -0.0069999999999990764055" rpy="3.0320190802513065509e-13 -1.5099033134901264358e-14 -4.1015697998360108845e-13" />
<geometry>
<mesh filename="package:///bearing_5x8x2.5_v1.stl"/>
</geometry>
</collision>
<visual>
<origin xyz="1.7347234759768070944e-18 0 -0.0044999999999999970579" rpy="3.141592653589793116 -6.3783375485366925332e-32 -4.5984980774841375948e-18" />
<geometry>
<mesh filename="package:///left_thigh_v1.stl"/>
</geometry>
<material name="left_thigh_v1_material">
<color rgba="1 1 1 1.0"/>
</material>
</visual>
<collision>
<origin xyz="1.7347234759768070944e-18 0 -0.0044999999999999970579" rpy="3.141592653589793116 -6.3783375485366925332e-32 -4.5984980774841375948e-18" />
<geometry>
<mesh filename="package:///left_thigh_v1.stl"/>
</geometry>
</collision>
<inertial>
<origin xyz="0.013280795316697640088 0.00036090885672622501816 -0.0044952881914007954481" rpy="0 0 0"/>
<mass value="0.0018464874791640285053" />
<inertia ixx="2.914724509633057378e-08" ixy="-3.1720402745930190973e-09"  ixz="1.4292640858369534041e-08" iyy="3.5092222213976692992e-07" iyz="8.5226615733023802273e-10" izz="3.6712035000665669318e-07" />
</inertial>
</link>

<link name="rightfoot">
<visual>
<origin xyz="3.4694469519536141888e-18 0 -0.0030000000000000026645" rpy="1.570796326794896558 4.7204687109509757542e-29 4.920433792345945422e-17" />
<geometry>
<mesh filename="package:///right_forearm_inside_v1.stl"/>
</geometry>
<material name="right_forearm_inside_v1_material">
<color rgba="1 1 1 1.0"/>
</material>
</visual>
<collision>
<origin xyz="3.4694469519536141888e-18 0 -0.0030000000000000026645" rpy="1.570796326794896558 4.7204687109509757542e-29 4.920433792345945422e-17" />
<geometry>
<mesh filename="package:///right_forearm_inside_v1.stl"/>
</geometry>
</collision>
<visual>
<origin xyz="-1.8388068845354155201e-16 4.1633363423443370266e-17 0.00049999999999988942179" rpy="1.570796326794896558 4.7204687109509757542e-29 4.920433792345945422e-17" />
<geometry>
<mesh filename="package:///right_forearm_outside_v1.stl"/>
</geometry>
<material name="right_forearm_outside_v1_material">
<color rgba="1 1 1 1.0"/>
</material>
</visual>
<collision>
<origin xyz="-1.8388068845354155201e-16 4.1633363423443370266e-17 0.00049999999999988942179" rpy="1.570796326794896558 4.7204687109509757542e-29 4.920433792345945422e-17" />
<geometry>
<mesh filename="package:///right_forearm_outside_v1.stl"/>
</geometry>
</collision>
<inertial>
<origin xyz="-0.011456869649159779484 -0.00069736546686952950204 -0.0010708602591541840909" rpy="0 0 0"/>
<mass value="0.0052504289083666246668" />
<inertia ixx="1.4014220415309422779e-07" ixy="-4.013794514280498124e-08"  ixz="-9.9504406391449952828e-09" iyy="2.2668296909327746683e-06" iyz="6.5923924208721406148e-09" izz="2.2964377908784525941e-06" />
</inertial>
</link>

<joint name="foot_frontright" type="revolute">
<origin xyz="0.034999999999997137567 -5.089678678515952015e-15 -0.0069999999999990764055" rpy="3.141592653589773132 -3.0284421533315752305e-13 1.5873207190023146396" />
<parent link="rightthigh" />
<child link="rightfoot" />
<axis xyz="0 0 1"/>
<limit effort="300" velocity="300" lower="-1.0472" upper="0"/>
<joint_properties friction="0.0"/>
</joint>

<joint name="thigh_frontright" type="revolute">
<origin xyz="-0.01764293222407292 -0.0074388637145611025484 -0.025649999999990867605" rpy="1.5707963267948941155 -0.72169352917961204774 1.5707963267948936714" />
<parent link="righthip" />
<child link="rightthigh" />
<axis xyz="0 0 1"/>
<limit effort="300" velocity="300" lower="-1.0472" upper="0"/>
<joint_properties friction="0.0"/>
</joint>

<link name="leftfemur_3">
<visual>
<origin xyz="0.035000000000010370038 7.4246164771807343641e-15 -3.7470027081099033239e-16" rpy="-3.141592653589793116 3.5233272813599712176e-32 -5.7822084137496022933e-17" />
<geometry>
<mesh filename="package:///bearing_5x8x2.5_v1.stl"/>
</geometry>
<material name="bearing_5x8x2.5_v1_material">
<color rgba="0.62745098039215685404 0.62745098039215685404 0.62745098039215685404 1.0"/>
</material>
</visual>
<collision>
<origin xyz="0.035000000000010370038 7.4246164771807343641e-15 -3.7470027081099033239e-16" rpy="-3.141592653589793116 3.5233272813599712176e-32 -5.7822084137496022933e-17" />
<geometry>
<mesh filename="package:///bearing_5x8x2.5_v1.stl"/>
</geometry>
</collision>
<visual>
<origin xyz="-4.5102810375396984455e-17 2.3592239273284576484e-16 -0.0024999999999997177258" rpy="1.3811174426336987753e-13 2.6423307986071367168e-14 2.0632644222753713332e-13" />
<geometry>
<mesh filename="package:///lever_v1.stl"/>
</geometry>
<material name="lever_v1_material">
<color rgba="1 1 1 1.0"/>
</material>
</visual>
<collision>
<origin xyz="-4.5102810375396984455e-17 2.3592239273284576484e-16 -0.0024999999999997177258" rpy="1.3811174426336987753e-13 2.6423307986071367168e-14 2.0632644222753713332e-13" />
<geometry>
<mesh filename="package:///lever_v1.stl"/>
</geometry>
</collision>
<visual>
<origin xyz="-3.4694469519536141888e-18 0 0" rpy="-3.141592653589793116 3.5233272813599712176e-32 -5.7822084137496022933e-17" />
<geometry>
<mesh filename="package:///bearing_5x8x2.5_v1.stl"/>
</geometry>
<material name="bearing_5x8x2.5_v1_material">
<color rgba="0.62745098039215685404 0.62745098039215685404 0.62745098039215685404 1.0"/>
</material>
</visual>
<collision>
<origin xyz="-3.4694469519536141888e-18 0 0" rpy="-3.141592653589793116 3.5233272813599712176e-32 -5.7822084137496022933e-17" />
<geometry>
<mesh filename="package:///bearing_5x8x2.5_v1.stl"/>
</geometry>
</collision>
<inertial>
<origin xyz="0.016745239433455710865 -0.0019623707901172925128 -0.0012500000000004410795" rpy="0 0 0"/>
<mass value="0.0012188090534078449383" />
<inertia ixx="2.3153914212895976553e-08" ixy="-7.3509510903750770154e-09"  ixz="5.2939533879365728792e-21" iyy="2.7100368005617489404e-07" iyz="-2.7298176281766856058e-21" izz="2.9302349553648826055e-07" />
</inertial>
</link>

<joint name="femur_frontright" type="revolute">
<origin xyz="-0.024642932224072704173 -0.019813232385325556251 -0.013275631329226038335" rpy="-1.5707963267948990005 -0.68346821395421664125 1.5707963267948936714" />
<parent link="righthip" />
<child link="leftfemur_3" />
<axis xyz="0 0 1"/>
<limit effort="300" velocity="300" />
<joint_properties friction="0.0"/>
</joint>

<joint name="frontrighthip" type="revolute">
<origin xyz="-0.036799999999999541411 0.056500000000000057121 -7.047612756298749729e-05" rpy="-1.570796326794896336 -1.732338231197280609e-15 -4.9961410333088865119e-16" />
<parent link="chassis" />
<child link="righthip" />
<axis xyz="0 0 1"/>
<limit effort="300" velocity="300" lower="-1.0472" upper="1.0472"/>
<joint_properties friction="0.0"/>
</joint>

<link name="righthip_2">
<visual>
<origin xyz="-0.024642932224073280101 -0.018555812535806869013 -0.039164960532358433776" rpy="1.5707963267948983344 0.68837531027923493099 1.5707963267949003328" />
<geometry>
<mesh filename="package:///bearing_5x8x2.5_v1.stl"/>
</geometry>
<material name="bearing_5x8x2.5_v1_material">
<color rgba="0.62745098039215685404 0.62745098039215685404 0.62745098039215685404 1.0"/>
</material>
</visual>
<collision>
<origin xyz="-0.024642932224073280101 -0.018555812535806869013 -0.039164960532358433776" rpy="1.5707963267948983344 0.68837531027923493099 1.5707963267949003328" />
<geometry>
<mesh filename="package:///bearing_5x8x2.5_v1.stl"/>
</geometry>
</collision>
<visual>
<origin xyz="-0.02464293222407328704 -0.018555812535806869013 -0.039164960532358433776" rpy="1.5707963267948983344 0.68837531027923493099 1.5707963267949003328" />
<geometry>
<mesh filename="package:///right_forearm_linkage_v1.stl"/>
</geometry>
<material name="right_forearm_linkage_v1_material">
<color rgba="1 1 1 1.0"/>
</material>
</visual>
<collision>
<origin xyz="-0.02464293222407328704 -0.018555812535806869013 -0.039164960532358433776" rpy="1.5707963267948983344 0.68837531027923493099 1.5707963267949003328" />
<geometry>
<mesh filename="package:///right_forearm_linkage_v1.stl"/>
</geometry>
</collision>
<visual>
<origin xyz="-0.015642932224073369252 -0.0074388637145611745394 -0.025649999999990957811" rpy="2.775557561562877053e-16 -1.5707963267948947816 0" />
<geometry>
<mesh filename="package:///9g_thigh_servo_attachment_v1.stl"/>
</geometry>
<material name="9g_thigh_servo_attachment_v1_material">
<color rgba="1 1 1 1.0"/>
</material>
</visual>
<collision>
<origin xyz="-0.015642932224073369252 -0.0074388637145611745394 -0.025649999999990957811" rpy="2.775557561562877053e-16 -1.5707963267948947816 0" />
<geometry>
<mesh filename="package:///9g_thigh_servo_attachment_v1.stl"/>
</geometry>
</collision>
<visual>
<origin xyz="-0.021642932224073360703 -0.0074388637145611754067 -0.025649999999990957811" rpy="-3.141592653589793116 -1.5707963267948947816 0" />
<geometry>
<mesh filename="package:///bearing_10x15x4_v1.stl"/>
</geometry>
<material name="bearing_10x15x4_v1_material">
<color rgba="0.62745098039215685404 0.62745098039215685404 0.62745098039215685404 1.0"/>
</material>
</visual>
<collision>
<origin xyz="-0.021642932224073360703 -0.0074388637145611754067 -0.025649999999990957811" rpy="-3.141592653589793116 -1.5707963267948947816 0" />
<geometry>
<mesh filename="package:///bearing_10x15x4_v1.stl"/>
</geometry>
</collision>
<visual>
<origin xyz="0 1.3552527156068805425e-20 -0.0014999999999999735767" rpy="1.570796326794896558 1.3341863213124109917e-32 0" />
<geometry>
<mesh filename="package:///9g_servo_arm_v1.stl"/>
</geometry>
<material name="9g_servo_arm_v1_material">
<color rgba="0.62745098039215685404 0.62745098039215685404 0.62745098039215685404 1.0"/>
</material>
</visual>
<collision>
<origin xyz="0 1.3552527156068805425e-20 -0.0014999999999999735767" rpy="1.570796326794896558 1.3341863213124109917e-32 0" />
<geometry>
<mesh filename="package:///9g_servo_arm_v1.stl"/>
</geometry>
</collision>
<visual>
<origin xyz="-0.019142932224073344605 -0.0061560981491748847233 -0.049365069312658604872" rpy="3.1415926535897926719 1.570796326794747122 0" />
<geometry>
<mesh filename="package:///bearing_5x8x2.5_v1.stl"/>
</geometry>
<material name="bearing_5x8x2.5_v1_material">
<color rgba="0.62745098039215685404 0.62745098039215685404 0.62745098039215685404 1.0"/>
</material>
</visual>
<collision>
<origin xyz="-0.019142932224073344605 -0.0061560981491748847233 -0.049365069312658604872" rpy="3.1415926535897926719 1.570796326794747122 0" />
<geometry>
<mesh filename="package:///bearing_5x8x2.5_v1.stl"/>
</geometry>
</collision>
<visual>
<origin xyz="-6.9388939039072283776e-18 1.7482760031328758998e-18 -0.0014999999999999458211" rpy="-3.141592653589793116 1.334186321314235964e-32 -9.8607613152626716525e-32" />
<geometry>
<mesh filename="package:///18g_thigh_servo_attachment_v3.stl"/>
</geometry>
<material name="18g_thigh_servo_attachment_v3_material">
<color rgba="1 1 1 1.0"/>
</material>
</visual>
<collision>
<origin xyz="-6.9388939039072283776e-18 1.7482760031328758998e-18 -0.0014999999999999458211" rpy="-3.141592653589793116 1.334186321314235964e-32 -9.8607613152626716525e-32" />
<geometry>
<mesh filename="package:///18g_thigh_servo_attachment_v3.stl"/>
</geometry>
</collision>
<visual>
<origin xyz="-0.015642932224073341496 0.0049611362854387964019 -0.035849999999990930788" rpy="1.570796326794896558 1.5707963267948956698 0" />
<geometry>
<mesh filename="package:///9g_servo_arm_v1.stl"/>
</geometry>
<material name="9g_servo_arm_v1_material">
<color rgba="0.62745098039215685404 0.62745098039215685404 0.62745098039215685404 1.0"/>
</material>
</visual>
<collision>
<origin xyz="-0.015642932224073341496 0.0049611362854387964019 -0.035849999999990930788" rpy="1.570796326794896558 1.5707963267948956698 0" />
<geometry>
<mesh filename="package:///9g_servo_arm_v1.stl"/>
</geometry>
</collision>
<visual>
<origin xyz="-0.021642932224073360703 -0.0074388637145611754067 -0.025649999999990957811" rpy="-3.141592653589793116 -1.5707963267948947816 0" />
<geometry>
<mesh filename="package:///right_forearm_pivot_v1.stl"/>
</geometry>
<material name="right_forearm_pivot_v1_material">
<color rgba="1 1 1 1.0"/>
</material>
</visual>
<collision>
<origin xyz="-0.021642932224073360703 -0.0074388637145611754067 -0.025649999999990957811" rpy="-3.141592653589793116 -1.5707963267948947816 0" />
<geometry>
<mesh filename="package:///right_forearm_pivot_v1.stl"/>
</geometry>
</collision>
<visual>
<origin xyz="-0.015642932224073369252 -0.0074388637145611745394 -0.025649999999990957811" rpy="-1.570796326794896336 -1.5707963267948947816 0" />
<geometry>
<mesh filename="package:///9g_servo_arm_v1.stl"/>
</geometry>
<material name="9g_servo_arm_v1_material">
<color rgba="0.62745098039215685404 0.62745098039215685404 0.62745098039215685404 1.0"/>
</material>
</visual>
<collision>
<origin xyz="-0.015642932224073369252 -0.0074388637145611745394 -0.025649999999990957811" rpy="-1.570796326794896336 -1.5707963267948947816 0" />
<geometry>
<mesh filename="package:///9g_servo_arm_v1.stl"/>
</geometry>
</collision>
<visual>
<origin xyz="0.0156570677759265732 0.0049611362854387964019 -0.030749999999990895727" rpy="1.570796326794896558 -1.5707963267948961139 0" />
<geometry>
<mesh filename="package:///microservosg90.stl"/>
</geometry>
<material name="microservosg90_material">
<color rgba="0.35294117647058825815 0.35294117647058825815 0.35294117647058825815 1.0"/>
</material>
</visual>
<collision>
<origin xyz="0.0156570677759265732 0.0049611362854387964019 -0.030749999999990895727" rpy="1.570796326794896558 -1.5707963267948961139 0" />
<geometry>
<mesh filename="package:///microservosg90.stl"/>
</geometry>
</collision>
<visual>
<origin xyz="-0.028642932224073276715 -0.0078107477265611548189 -0.025352155522328417847" rpy="-1.5707963267948872321 -1.5435606468479745601 -1.5707963267948081842" />
<geometry>
<mesh filename="package:///right_cover_v2.stl"/>
</geometry>
<material name="right_cover_v2_material">
<color rgba="1 1 1 1.0"/>
</material>
</visual>
<collision>
<origin xyz="-0.028642932224073276715 -0.0078107477265611548189 -0.025352155522328417847" rpy="-1.5707963267948872321 -1.5435606468479745601 -1.5707963267948081842" />
<geometry>
<mesh filename="package:///right_cover_v2.stl"/>
</geometry>
</collision>
<visual>
<origin xyz="0.0038875000000004461542 -1.8973538018496327595e-18 -0.050899999999989162247" rpy="-3.141592653589793116 3.3733379574538865338e-13 3.141592653589793116" />
<geometry>
<mesh filename="package:///hip_joint_to_bearing_v3.stl"/>
</geometry>
<material name="hip_joint_to_bearing_v3_material">
<color rgba="1 1 1 1.0"/>
</material>
</visual>
<collision>
<origin xyz="0.0038875000000004461542 -1.8973538018496327595e-18 -0.050899999999989162247" rpy="-3.141592653589793116 3.3733379574538865338e-13 3.141592653589793116" />
<geometry>
<mesh filename="package:///hip_joint_to_bearing_v3.stl"/>
</geometry>
</collision>
<visual>
<origin xyz="0.0044750000000061199157 -0.012124999999999958727 -0.029999999999996126987" rpy="1.570796326794896558 3.3599818909922299914e-13 3.141592653589793116" />
<geometry>
<mesh filename="package:///hip_v2.stl"/>
</geometry>
<material name="hip_v2_material">
<color rgba="1 1 1 1.0"/>
</material>
</visual>
<collision>
<origin xyz="0.0044750000000061199157 -0.012124999999999958727 -0.029999999999996126987" rpy="1.570796326794896558 3.3599818909922299914e-13 3.141592653589793116" />
<geometry>
<mesh filename="package:///hip_v2.stl"/>
</geometry>
</collision>
<visual>
<origin xyz="0.0038874999999999812483 -2.2226144535952840897e-18 -0.0090999999999999137135" rpy="-3.9790877452899023628e-17 3.5296043925797794771e-16 3.141592653589793116" />
<geometry>
<mesh filename="package:///hip_joint_to_servo_v2.stl"/>
</geometry>
<material name="hip_joint_to_servo_v2_material">
<color rgba="1 1 1 1.0"/>
</material>
</visual>
<collision>
<origin xyz="0.0038874999999999812483 -2.2226144535952840897e-18 -0.0090999999999999137135" rpy="-3.9790877452899023628e-17 3.5296043925797794771e-16 3.141592653589793116" />
<geometry>
<mesh filename="package:///hip_joint_to_servo_v2.stl"/>
</geometry>
</collision>
<visual>
<origin xyz="0.0044749999999997500111 0.01212499999999994485 -0.029999999999991658339" rpy="-1.570796326794896558 1.6734073723112953892e-15 3.141592653589793116" />
<geometry>
<mesh filename="package:///hip_v2.stl"/>
</geometry>
<material name="hip_v2_material">
<color rgba="1 1 1 1.0"/>
</material>
</visual>
<collision>
<origin xyz="0.0044749999999997500111 0.01212499999999994485 -0.029999999999991658339" rpy="-1.570796326794896558 1.6734073723112953892e-15 3.141592653589793116" />
<geometry>
<mesh filename="package:///hip_v2.stl"/>
</geometry>
</collision>
<visual>
<origin xyz="0.015657067775926583608 -0.0074388637145611676005 -0.030749999999990881849" rpy="-1.5707963267948970021 1.5707963267948961139 0" />
<geometry>
<mesh filename="package:///microservosg90.stl"/>
</geometry>
<material name="microservosg90_material">
<color rgba="0.35294117647058825815 0.35294117647058825815 0.35294117647058825815 1.0"/>
</material>
</visual>
<collision>
<origin xyz="0.015657067775926583608 -0.0074388637145611676005 -0.030749999999990881849" rpy="-1.5707963267948970021 1.5707963267948961139 0" />
<geometry>
<mesh filename="package:///microservosg90.stl"/>
</geometry>
</collision>
<visual>
<origin xyz="-0.021642932224073388459 0.0049611362854387955346 -0.035849999999991138955" rpy="1.5707963267948998887 -1.5707963267948896746 0" />
<geometry>
<mesh filename="package:///right_forearm_servo_attachment_v1.stl"/>
</geometry>
<material name="right_forearm_servo_attachment_v1_material">
<color rgba="1 1 1 1.0"/>
</material>
</visual>
<collision>
<origin xyz="-0.021642932224073388459 0.0049611362854387955346 -0.035849999999991138955" rpy="1.5707963267948998887 -1.5707963267948896746 0" />
<geometry>
<mesh filename="package:///right_forearm_servo_attachment_v1.stl"/>
</geometry>
</collision>
<inertial>
<origin xyz="-0.0011710670974884858451 -0.0027751546053958078657 -0.028924859847319198125" rpy="0 0 0"/>
<mass value="0.035352377824358502401" />
<inertia ixx="8.7221517697940950404e-06" ixy="-1.5327589570214121957e-06"  ixz="-6.3234324719324753196e-07" iyy="1.1158273187212559317e-05" iyz="1.7742325608328235939e-07" izz="8.3181296366537683668e-06" />
</inertial>
</link>

<link name="rightthigh_2">
<visual>
<origin xyz="1.3877787807814456755e-17 2.7755575615628913511e-17 -0.0044999999999999970579" rpy="-3.141592653589793116 4.7404917852612325432e-32 -3.2457621906083611495e-18" />
<geometry>
<mesh filename="package:///left_thigh_v1.stl"/>
</geometry>
<material name="left_thigh_v1_material">
<color rgba="1 1 1 1.0"/>
</material>
</visual>
<collision>
<origin xyz="1.3877787807814456755e-17 2.7755575615628913511e-17 -0.0044999999999999970579" rpy="-3.141592653589793116 4.7404917852612325432e-32 -3.2457621906083611495e-18" />
<geometry>
<mesh filename="package:///left_thigh_v1.stl"/>
</geometry>
</collision>
<visual>
<origin xyz="0.034999999999997338795 5.3013149425851224805e-15 -0.0069999999999999923395" rpy="-1.6653345369377251964e-16 1.1102230246251490462e-15 3.4155826824282646248e-15" />
<geometry>
<mesh filename="package:///bearing_5x8x2.5_v1.stl"/>
</geometry>
<material name="bearing_5x8x2.5_v1_material">
<color rgba="0.62745098039215685404 0.62745098039215685404 0.62745098039215685404 1.0"/>
</material>
</visual>
<collision>
<origin xyz="0.034999999999997338795 5.3013149425851224805e-15 -0.0069999999999999923395" rpy="-1.6653345369377251964e-16 1.1102230246251490462e-15 3.4155826824282646248e-15" />
<geometry>
<mesh filename="package:///bearing_5x8x2.5_v1.stl"/>
</geometry>
</collision>
<inertial>
<origin xyz="0.013280795316697662639 0.00036090885672673670738 -0.0044952881914008353467" rpy="0 0 0"/>
<mass value="0.0018464874791640285053" />
<inertia ixx="2.9147245096330117176e-08" ixy="-3.1720402746123763644e-09"  ixz="1.4292640858371216526e-08" iyy="3.5092222213976814753e-07" iyz="8.5226615733146131946e-10" izz="3.6712035000665695788e-07" />
</inertial>
</link>

<link name="rightfoot_2">
<visual>
<origin xyz="5.5511151231257827021e-17 5.5511151231257827021e-17 0.00050000000000002819966" rpy="1.570796326794896558 -1.0478392514764327793e-31 3.4760228589040924473e-17" />
<geometry>
<mesh filename="package:///right_forearm_outside_v1.stl"/>
</geometry>
<material name="right_forearm_outside_v1_material">
<color rgba="1 1 1 1.0"/>
</material>
</visual>
<collision>
<origin xyz="5.5511151231257827021e-17 5.5511151231257827021e-17 0.00050000000000002819966" rpy="1.570796326794896558 -1.0478392514764327793e-31 3.4760228589040924473e-17" />
<geometry>
<mesh filename="package:///right_forearm_outside_v1.stl"/>
</geometry>
</collision>
<visual>
<origin xyz="-2.7755575615628913511e-17 0 -0.0030000000000000026645" rpy="1.570796326794896558 -1.0478392514764327793e-31 3.4760228589040924473e-17" />
<geometry>
<mesh filename="package:///right_forearm_inside_v1.stl"/>
</geometry>
<material name="right_forearm_inside_v1_material">
<color rgba="1 1 1 1.0"/>
</material>
</visual>
<collision>
<origin xyz="-2.7755575615628913511e-17 0 -0.0030000000000000026645" rpy="1.570796326794896558 -1.0478392514764327793e-31 3.4760228589040924473e-17" />
<geometry>
<mesh filename="package:///right_forearm_inside_v1.stl"/>
</geometry>
</collision>
<inertial>
<origin xyz="-0.011456869649159680605 -0.00069736546686952277999 -0.0010708602591541170872" rpy="0 0 0"/>
<mass value="0.0052504289083666246668" />
<inertia ixx="1.4014220415309639832e-07" ixy="-4.013794514280518638e-08"  ixz="-9.9504406391477646835e-09" iyy="2.2668296909327805976e-06" iyz="6.5923924208722183698e-09" izz="2.2964377908784551352e-06" />
</inertial>
</link>

<joint name="foot_backright" type="revolute">
<origin xyz="0.03499999999999731104 5.273559366969493567e-15 -0.0069999999999999923395" rpy="-3.1415926535897922278 1.278825186765632713e-16 1.605679334027174443" />
<parent link="rightthigh_2" />
<child link="rightfoot_2" />
<axis xyz="0 0 1"/>
<limit effort="300" velocity="300" lower="-1.0472" upper="0"/>
<joint_properties friction="0.0"/>
</joint>

<joint name="thigh_backright" type="revolute">
<origin xyz="-0.017642932224073371028 -0.0074388637145611745394 -0.025649999999990985566" rpy="1.5707963267948943376 -0.68793763179652955841 1.5707963267948961139" />
<parent link="righthip_2" />
<child link="rightthigh_2" />
<axis xyz="0 0 1"/>
<limit effort="300" velocity="300" lower="-1.0472" upper="0"/>
<joint_properties friction="0.0"/>
</joint>

<link name="leftfemur_4">
<visual>
<origin xyz="0 0 -0.0024999999999999952816" rpy="-1.466411107634638122e-30 6.6109342462079019662e-32 8.2224073647639481264e-17" />
<geometry>
<mesh filename="package:///lever_v1.stl"/>
</geometry>
<material name="lever_v1_material">
<color rgba="1 1 1 1.0"/>
</material>
</visual>
<collision>
<origin xyz="0 0 -0.0024999999999999952816" rpy="-1.466411107634638122e-30 6.6109342462079019662e-32 8.2224073647639481264e-17" />
<geometry>
<mesh filename="package:///lever_v1.stl"/>
</geometry>
</collision>
<visual>
<origin xyz="0 0 6.9388939039072283776e-18" rpy="-3.141592653589793116 6.6109342462079019662e-32 8.2224073647639481264e-17" />
<geometry>
<mesh filename="package:///bearing_5x8x2.5_v1.stl"/>
</geometry>
<material name="bearing_5x8x2.5_v1_material">
<color rgba="0.62745098039215685404 0.62745098039215685404 0.62745098039215685404 1.0"/>
</material>
</visual>
<collision>
<origin xyz="0 0 6.9388939039072283776e-18" rpy="-3.141592653589793116 6.6109342462079019662e-32 8.2224073647639481264e-17" />
<geometry>
<mesh filename="package:///bearing_5x8x2.5_v1.stl"/>
</geometry>
</collision>
<visual>
<origin xyz="0.035000000000007427947 -3.7608804959177177807e-15 0" rpy="-3.141592653589793116 6.6109342462079019662e-32 8.2224073647639481264e-17" />
<geometry>
<mesh filename="package:///bearing_5x8x2.5_v1.stl"/>
</geometry>
<material name="bearing_5x8x2.5_v1_material">
<color rgba="0.62745098039215685404 0.62745098039215685404 0.62745098039215685404 1.0"/>
</material>
</visual>
<collision>
<origin xyz="0.035000000000007427947 -3.7608804959177177807e-15 0" rpy="-3.141592653589793116 6.6109342462079019662e-32 8.2224073647639481264e-17" />
<geometry>
<mesh filename="package:///bearing_5x8x2.5_v1.stl"/>
</geometry>
</collision>
<inertial>
<origin xyz="0.016745239433455127998 -0.0019623707901210750773 -0.0012500000000000045797" rpy="0 0 0"/>
<mass value="0.0012188090534078449383" />
<inertia ixx="2.3153914212891731462e-08" ixy="-7.3509510903175234427e-09"  ixz="1.1526726514177677357e-22" iyy="2.710036800561697589e-07" iyz="-3.0358226311273434332e-24" izz="2.9302349553647809615e-07" />
</inertial>
</link>

<joint name="femur_backright" type="revolute">
<origin xyz="-0.024642932224073363368 -0.019813232385326031565 -0.013275631329225989763" rpy="-1.5707963267948987784 -0.69825389664490622454 1.5707963267948938935" />
<parent link="righthip_2" />
<child link="leftfemur_4" />
<axis xyz="0 0 1"/>
<limit effort="300" velocity="300" />
<joint_properties friction="0.0"/>
</joint>

<joint name="backrighthip" type="revolute">
<origin xyz="-0.036799999999999492839 0.15150000000000002354 -7.0476127562964105628e-05" rpy="-1.570796326794896336 -4.1633363423443277821e-17 -1.2972374029647262691e-15" />
<parent link="chassis" />
<child link="righthip_2" />
<axis xyz="0 0 1"/>
<limit effort="300" velocity="300" lower="-1.0472" upper="1.0472"/>
<joint_properties friction="0.0"/>
</joint>


</robot>
