<robot name="onshape">
<link name="chassis">
<visual>
<origin xyz="-0.0049999999999996679045 0.0040000000000000538597 0.016470476127563242474" rpy="1.0648674274956600871e-16 -0 1.57079632679490655" />
<geometry>
<mesh filename="package:///top_body_v21.stl"/>
</geometry>
<material name="top_body_v21_material">
<color rgba="1 1 1 1.0"/>
</material>
</visual>
<collision>
<origin xyz="-0.0049999999999996679045 0.0040000000000000538597 0.016470476127563242474" rpy="1.0648674274956600871e-16 -0 1.57079632679490655" />
<geometry>
<mesh filename="package:///top_body_v21.stl"/>
</geometry>
</collision>
<visual>
<origin xyz="0.031900000000001149658 0.078250000000001110334 0.0056045238724370845251" rpy="3.141592653589793116 1.0668549377256967968e-16 4.9960036108129977503e-15" />
<geometry>
<mesh filename="package:///18g_servo_v1.stl"/>
</geometry>
<material name="18g_servo_v1_material">
<color rgba="0.62745098039215685404 0.62745098039215685404 0.62745098039215685404 1.0"/>
</material>
</visual>
<collision>
<origin xyz="0.031900000000001149658 0.078250000000001110334 0.0056045238724370845251" rpy="3.141592653589793116 1.0668549377256967968e-16 4.9960036108129977503e-15" />
<geometry>
<mesh filename="package:///18g_servo_v1.stl"/>
</geometry>
</collision>
<visual>
<origin xyz="-0.011350000000001572373 0.16440000000000226654 -0.0061454761275630542805" rpy="-1.7733605042685602097e-32 -1.0648674274956318607e-16 3.141592653589793116" />
<geometry>
<mesh filename="package:///bottom_hip_servo_v12.stl"/>
</geometry>
<material name="bottom_hip_servo_v12_material">
<color rgba="1 1 1 1.0"/>
</material>
</visual>
<collision>
<origin xyz="-0.011350000000001572373 0.16440000000000226654 -0.0061454761275630542805" rpy="-1.7733605042685602097e-32 -1.0648674274956318607e-16 3.141592653589793116" />
<geometry>
<mesh filename="package:///bottom_hip_servo_v12.stl"/>
</geometry>
</collision>
<visual>
<origin xyz="-0.011350000000000578376 0.069404000000000909409 0.0056754761275630769002" rpy="-6.1629758220391574667e-33 -5.0975591518307146312e-17 -3.141592653589793116" />
<geometry>
<mesh filename="package:///top_hip_servo_v14.stl"/>
</geometry>
<material name="top_hip_servo_v14_material">
<color rgba="1 1 1 1.0"/>
</material>
</visual>
<collision>
<origin xyz="-0.011350000000000578376 0.069404000000000909409 0.0056754761275630769002" rpy="-6.1629758220391574667e-33 -5.0975591518307146312e-17 -3.141592653589793116" />
<geometry>
<mesh filename="package:///top_hip_servo_v14.stl"/>
</geometry>
</collision>
<visual>
<origin xyz="-0.037000000000001947997 0.14800000000001331535 2.7403080422438690135e-17" rpy="1.570796326794896558 2.1297348549912632284e-16 1.9721522630524478441e-31" />
<geometry>
<mesh filename="package:///bearing_10x15x4_v1.stl"/>
</geometry>
<material name="bearing_10x15x4_v1_material">
<color rgba="0.62745098039215685404 0.62745098039215685404 0.62745098039215685404 1.0"/>
</material>
</visual>
<collision>
<origin xyz="-0.037000000000001947997 0.14800000000001331535 2.7403080422438690135e-17" rpy="1.570796326794896558 2.1297348549912632284e-16 1.9721522630524478441e-31" />
<geometry>
<mesh filename="package:///bearing_10x15x4_v1.stl"/>
</geometry>
</collision>
<visual>
<origin xyz="-0.037000000000000844713 0.053000000000011968093 2.7403080422438690135e-17" rpy="1.570796326794896558 2.1297348549912632284e-16 1.9721522630524517853e-31" />
<geometry>
<mesh filename="package:///bearing_10x15x4_v1.stl"/>
</geometry>
<material name="bearing_10x15x4_v1_material">
<color rgba="0.62745098039215685404 0.62745098039215685404 0.62745098039215685404 1.0"/>
</material>
</visual>
<collision>
<origin xyz="-0.037000000000000844713 0.053000000000011968093 2.7403080422438690135e-17" rpy="1.570796326794896558 2.1297348549912632284e-16 1.9721522630524517853e-31" />
<geometry>
<mesh filename="package:///bearing_10x15x4_v1.stl"/>
</geometry>
</collision>
<visual>
<origin xyz="0.037000000000001545541 1.7347234759768009314e-18 1.6994739566577847568e-17" rpy="-1.570796326794896558 2.8515549047850972074e-75 1.9721522630524520042e-31" />
<geometry>
<mesh filename="package:///bearing_10x15x4_v1.stl"/>
</geometry>
<material name="bearing_10x15x4_v1_material">
<color rgba="0.62745098039215685404 0.62745098039215685404 0.62745098039215685404 1.0"/>
</material>
</visual>
<collision>
<origin xyz="0.037000000000001545541 1.7347234759768009314e-18 1.6994739566577847568e-17" rpy="-1.570796326794896558 2.8515549047850972074e-75 1.9721522630524520042e-31" />
<geometry>
<mesh filename="package:///bearing_10x15x4_v1.stl"/>
</geometry>
</collision>
<visual>
<origin xyz="-0.037000000000001448397 0.0040000000000000538597 2.0464186518531461757e-17" rpy="1.570796326794896558 2.8515549047850972074e-75 1.9721522630524520042e-31" />
<geometry>
<mesh filename="package:///bearing_10x15x4_v1.stl"/>
</geometry>
<material name="bearing_10x15x4_v1_material">
<color rgba="0.62745098039215685404 0.62745098039215685404 0.62745098039215685404 1.0"/>
</material>
</visual>
<collision>
<origin xyz="-0.037000000000001448397 0.0040000000000000538597 2.0464186518531461757e-17" rpy="1.570796326794896558 2.8515549047850972074e-75 1.9721522630524520042e-31" />
<geometry>
<mesh filename="package:///bearing_10x15x4_v1.stl"/>
</geometry>
</collision>
<visual>
<origin xyz="0.037000000000001073697 0.14800000000001328759 1.005584566267061919e-17" rpy="1.570796326794896558 2.1297348549912632284e-16 1.9721522630524478441e-31" />
<geometry>
<mesh filename="package:///bearing_10x15x4_v1.stl"/>
</geometry>
<material name="bearing_10x15x4_v1_material">
<color rgba="0.62745098039215685404 0.62745098039215685404 0.62745098039215685404 1.0"/>
</material>
</visual>
<collision>
<origin xyz="0.037000000000001073697 0.14800000000001328759 1.005584566267061919e-17" rpy="1.570796326794896558 2.1297348549912632284e-16 1.9721522630524478441e-31" />
<geometry>
<mesh filename="package:///bearing_10x15x4_v1.stl"/>
</geometry>
</collision>
<visual>
<origin xyz="-0.037000000000002357392 0.095000000000001263989 2.0464186518531461757e-17" rpy="0 2.8515549047850972074e-75 1.9721522630524520042e-31" />
<geometry>
<mesh filename="package:///hip_cage_v4.stl"/>
</geometry>
<material name="hip_cage_v4_material">
<color rgba="1 1 1 1.0"/>
</material>
</visual>
<collision>
<origin xyz="-0.037000000000002357392 0.095000000000001263989 2.0464186518531461757e-17" rpy="0 2.8515549047850972074e-75 1.9721522630524520042e-31" />
<geometry>
<mesh filename="package:///hip_cage_v4.stl"/>
</geometry>
</collision>
<visual>
<origin xyz="-1.6011497683265929481e-15 0.21299000000000289923 0.0055000238724371014465" rpy="3.141592653589793116 -1.570796326794896558 0" />
<geometry>
<mesh filename="package:///servo_controller_v1.stl"/>
</geometry>
<material name="servo_controller_v1_material">
<color rgba="0.63921568627450975342 0.66666666666666662966 0.67843137254901964006 1.0"/>
</material>
</visual>
<collision>
<origin xyz="-1.6011497683265929481e-15 0.21299000000000289923 0.0055000238724371014465" rpy="3.141592653589793116 -1.570796326794896558 0" />
<geometry>
<mesh filename="package:///servo_controller_v1.stl"/>
</geometry>
</collision>
<visual>
<origin xyz="-0.031900000000002495804 0.17325000000000242983 -0.0061454761275630525458" rpy="-1.7733605042685675994e-32 -1.0648674274956321072e-16 3.141592653589793116" />
<geometry>
<mesh filename="package:///18g_servo_v1.stl"/>
</geometry>
<material name="18g_servo_v1_material">
<color rgba="0.62745098039215685404 0.62745098039215685404 0.62745098039215685404 1.0"/>
</material>
</visual>
<collision>
<origin xyz="-0.031900000000002495804 0.17325000000000242983 -0.0061454761275630525458" rpy="-1.7733605042685675994e-32 -1.0648674274956321072e-16 3.141592653589793116" />
<geometry>
<mesh filename="package:///18g_servo_v1.stl"/>
</geometry>
</collision>
<visual>
<origin xyz="-0.03190000000000157987 0.078250000000001110334 -0.0061454761275630664236" rpy="-1.1102230246251582661e-16 1.7106901340671706202e-16 3.141592653589793116" />
<geometry>
<mesh filename="package:///18g_servo_v1.stl"/>
</geometry>
<material name="18g_servo_v1_material">
<color rgba="0.62745098039215685404 0.62745098039215685404 0.62745098039215685404 1.0"/>
</material>
</visual>
<collision>
<origin xyz="-0.03190000000000157987 0.078250000000001110334 -0.0061454761275630664236" rpy="-1.1102230246251582661e-16 1.7106901340671706202e-16 3.141592653589793116" />
<geometry>
<mesh filename="package:///18g_servo_v1.stl"/>
</geometry>
</collision>
<visual>
<origin xyz="-0.037000000000002392087 0.099000000000001323053 2.7403080422438690135e-17" rpy="1.570796326794896558 2.8515549047850972074e-75 1.9721522630524520042e-31" />
<geometry>
<mesh filename="package:///bearing_10x15x4_v1.stl"/>
</geometry>
<material name="bearing_10x15x4_v1_material">
<color rgba="0.62745098039215685404 0.62745098039215685404 0.62745098039215685404 1.0"/>
</material>
</visual>
<collision>
<origin xyz="-0.037000000000002392087 0.099000000000001323053 2.7403080422438690135e-17" rpy="1.570796326794896558 2.8515549047850972074e-75 1.9721522630524520042e-31" />
<geometry>
<mesh filename="package:///bearing_10x15x4_v1.stl"/>
</geometry>
</collision>
<visual>
<origin xyz="0.037000000000002031264 0.053000000000011961154 1.005584566267061919e-17" rpy="-9.4423431678150758974e-47 -2.1297348549912632284e-16 -3.141592653589793116" />
<geometry>
<mesh filename="package:///hip_cage_v4.stl"/>
</geometry>
<material name="hip_cage_v4_material">
<color rgba="1 1 1 1.0"/>
</material>
</visual>
<collision>
<origin xyz="0.037000000000002031264 0.053000000000011961154 1.005584566267061919e-17" rpy="-9.4423431678150758974e-47 -2.1297348549912632284e-16 -3.141592653589793116" />
<geometry>
<mesh filename="package:///hip_cage_v4.stl"/>
</geometry>
</collision>
<visual>
<origin xyz="-0.011350000000001522066 0.16440400000000221503 0.0056754761275631046558" rpy="2.7369110631418401047e-48 -1.0648674274956316142e-16 -3.141592653589793116" />
<geometry>
<mesh filename="package:///top_hip_servo_v14.stl"/>
</geometry>
<material name="top_hip_servo_v14_material">
<color rgba="1 1 1 1.0"/>
</material>
</visual>
<collision>
<origin xyz="-0.011350000000001522066 0.16440400000000221503 0.0056754761275631046558" rpy="2.7369110631418401047e-48 -1.0648674274956316142e-16 -3.141592653589793116" />
<geometry>
<mesh filename="package:///top_hip_servo_v14.stl"/>
</geometry>
</collision>
<visual>
<origin xyz="-0.011350000000000606132 0.06940000000000096092 -0.0061454761275630681583" rpy="-1.7733605042685684204e-32 -1.0648674274956318607e-16 3.141592653589793116" />
<geometry>
<mesh filename="package:///bottom_hip_servo_v12.stl"/>
</geometry>
<material name="bottom_hip_servo_v12_material">
<color rgba="1 1 1 1.0"/>
</material>
</visual>
<collision>
<origin xyz="-0.011350000000000606132 0.06940000000000096092 -0.0061454761275630681583" rpy="-1.7733605042685684204e-32 -1.0648674274956318607e-16 3.141592653589793116" />
<geometry>
<mesh filename="package:///bottom_hip_servo_v12.stl"/>
</geometry>
</collision>
<visual>
<origin xyz="-1.6375789613221058971e-15 0.2165000000000029956 0.0055000238724371014465" rpy="1.773360504268559936e-32 1.0648674274956316142e-16 -1.6653345369376877255e-16" />
<geometry>
<mesh filename="package:///servo_driver_mount_v9.stl"/>
</geometry>
<material name="servo_driver_mount_v9_material">
<color rgba="1 1 1 1.0"/>
</material>
</visual>
<collision>
<origin xyz="-1.6375789613221058971e-15 0.2165000000000029956 0.0055000238724371014465" rpy="1.773360504268559936e-32 1.0648674274956316142e-16 -1.6653345369376877255e-16" />
<geometry>
<mesh filename="package:///servo_driver_mount_v9.stl"/>
</geometry>
</collision>
<visual>
<origin xyz="0.037000000000002072897 0.04900000000001190209 1.005584566267061919e-17" rpy="-1.570796326794896558 2.1297348549912632284e-16 1.9721522630524517853e-31" />
<geometry>
<mesh filename="package:///bearing_10x15x4_v1.stl"/>
</geometry>
<material name="bearing_10x15x4_v1_material">
<color rgba="0.62745098039215685404 0.62745098039215685404 0.62745098039215685404 1.0"/>
</material>
</visual>
<collision>
<origin xyz="0.037000000000002072897 0.04900000000001190209 1.005584566267061919e-17" rpy="-1.570796326794896558 2.1297348549912632284e-16 1.9721522630524517853e-31" />
<geometry>
<mesh filename="package:///bearing_10x15x4_v1.stl"/>
</geometry>
</collision>
<visual>
<origin xyz="-0.037000000000001406764 -6.1629758220391547298e-33 2.0464186518531461757e-17" rpy="0 2.8515549047850972074e-75 1.9721522630524520042e-31" />
<geometry>
<mesh filename="package:///hip_cage_v4.stl"/>
</geometry>
<material name="hip_cage_v4_material">
<color rgba="1 1 1 1.0"/>
</material>
</visual>
<collision>
<origin xyz="-0.037000000000001406764 -6.1629758220391547298e-33 2.0464186518531461757e-17" rpy="0 2.8515549047850972074e-75 1.9721522630524520042e-31" />
<geometry>
<mesh filename="package:///hip_cage_v4.stl"/>
</geometry>
</collision>
<visual>
<origin xyz="0.031900000000000108824 0.17325000000000240208 0.0056045238724371053418" rpy="3.141592653589793116 1.0648674274956321072e-16 -1.6653345369376872325e-16" />
<geometry>
<mesh filename="package:///18g_servo_v1.stl"/>
</geometry>
<material name="18g_servo_v1_material">
<color rgba="0.62745098039215685404 0.62745098039215685404 0.62745098039215685404 1.0"/>
</material>
</visual>
<collision>
<origin xyz="0.031900000000000108824 0.17325000000000240208 0.0056045238724371053418" rpy="3.141592653589793116 1.0648674274956321072e-16 -1.6653345369376872325e-16" />
<geometry>
<mesh filename="package:///18g_servo_v1.stl"/>
</geometry>
</collision>
<visual>
<origin xyz="0.037000000000000601852 0.095000000000001277867 1.6994739566577847568e-17" rpy="-1.570796326794896558 2.8515549047850972074e-75 1.9721522630524520042e-31" />
<geometry>
<mesh filename="package:///bearing_10x15x4_v1.stl"/>
</geometry>
<material name="bearing_10x15x4_v1_material">
<color rgba="0.62745098039215685404 0.62745098039215685404 0.62745098039215685404 1.0"/>
</material>
</visual>
<collision>
<origin xyz="0.037000000000000601852 0.095000000000001277867 1.6994739566577847568e-17" rpy="-1.570796326794896558 2.8515549047850972074e-75 1.9721522630524520042e-31" />
<geometry>
<mesh filename="package:///bearing_10x15x4_v1.stl"/>
</geometry>
</collision>
<visual>
<origin xyz="0.0050000000000007330248 0.0040000000000000573291 -0.01647047612756320431" rpy="-3.141592653589793116 -1.773360504268559936e-32 1.5707963267949067721" />
<geometry>
<mesh filename="package:///bottom_body_v3.stl"/>
</geometry>
<material name="bottom_body_v3_material">
<color rgba="1 1 1 1.0"/>
</material>
</visual>
<collision>
<origin xyz="0.0050000000000007330248 0.0040000000000000573291 -0.01647047612756320431" rpy="-3.141592653589793116 -1.773360504268559936e-32 1.5707963267949067721" />
<geometry>
<mesh filename="package:///bottom_body_v3.stl"/>
</geometry>
</collision>
<visual>
<origin xyz="0.037000000000001073697 0.14800000000001328759 1.005584566267061919e-17" rpy="5.4738221262836802094e-48 -2.1297348549912632284e-16 -3.141592653589793116" />
<geometry>
<mesh filename="package:///hip_cage_v4.stl"/>
</geometry>
<material name="hip_cage_v4_material">
<color rgba="1 1 1 1.0"/>
</material>
</visual>
<collision>
<origin xyz="0.037000000000001073697 0.14800000000001328759 1.005584566267061919e-17" rpy="5.4738221262836802094e-48 -2.1297348549912632284e-16 -3.141592653589793116" />
<geometry>
<mesh filename="package:///hip_cage_v4.stl"/>
</geometry>
</collision>
<visual>
<origin xyz="-0.013000000000000570127 0.011010500000000271806 -0.016470476127563200841" rpy="-3.8988753679793854128e-31 1.0648674274956303816e-16 1.2767564783187988734e-15" />
<geometry>
<mesh filename="package:///battery.stl"/>
</geometry>
<material name="battery_material">
<color rgba="0.61568627450980395466 0.81176470588235294379 0.92941176470588238168 1.0"/>
</material>
</visual>
<collision>
<origin xyz="-0.013000000000000570127 0.011010500000000271806 -0.016470476127563200841" rpy="-3.8988753679793854128e-31 1.0648674274956303816e-16 1.2767564783187988734e-15" />
<geometry>
<mesh filename="package:///battery.stl"/>
</geometry>
</collision>
<inertial>
<origin xyz="-1.9855471345741387205e-05 0.065861838296961724981 -0.00061754104040922326493" rpy="0 0 0"/>
<mass value="0.33140859148618373453" />
<inertia ixx="0.0012165354636305791662" ixy="9.4452254569171999068e-07"  ixz="4.0955178165323166321e-07" iyy="0.00014580262017353782015" iyz="-1.6032689773565337633e-05" izz="0.0013028127932899211464" />
</inertial>
</link>

<link name="lefthip">
<visual>
<origin xyz="0.015650000000006106943 0.0071750000000001725592 -0.029249999999993094024" rpy="-1.570796326794896336 1.5707963267945610486 0" />
<geometry>
<mesh filename="package:///microservosg90.stl"/>
</geometry>
<material name="microservosg90_material">
<color rgba="0.35294117647058825815 0.35294117647058825815 0.35294117647058825815 1.0"/>
</material>
</visual>
<collision>
<origin xyz="0.015650000000006106943 0.0071750000000001725592 -0.029249999999993094024" rpy="-1.570796326794896336 1.5707963267945610486 0" />
<geometry>
<mesh filename="package:///microservosg90.stl"/>
</geometry>
</collision>
<visual>
<origin xyz="0 0 -0.0015000000000000013323" rpy="3.141592653589793116 -3.3306721717741334313e-16 0" />
<geometry>
<mesh filename="package:///18g_thigh_servo_attachment_v3.stl"/>
</geometry>
<material name="18g_thigh_servo_attachment_v3_material">
<color rgba="1 1 1 1.0"/>
</material>
</visual>
<collision>
<origin xyz="0 0 -0.0015000000000000013323" rpy="3.141592653589793116 -3.3306721717741334313e-16 0" />
<geometry>
<mesh filename="package:///18g_thigh_servo_attachment_v3.stl"/>
</geometry>
</collision>
<visual>
<origin xyz="0.0038875000000001547207 -3.794707603699265519e-18 -0.0090999999999999900413" rpy="3.8154866979698241519e-21 3.3306721717741334313e-16 3.141592653589793116" />
<geometry>
<mesh filename="package:///hip_joint_to_servo_v2.stl"/>
</geometry>
<material name="hip_joint_to_servo_v2_material">
<color rgba="1 1 1 1.0"/>
</material>
</visual>
<collision>
<origin xyz="0.0038875000000001547207 -3.794707603699265519e-18 -0.0090999999999999900413" rpy="3.8154866979698241519e-21 3.3306721717741334313e-16 3.141592653589793116" />
<geometry>
<mesh filename="package:///hip_joint_to_servo_v2.stl"/>
</geometry>
</collision>
<visual>
<origin xyz="0.0044749999999999998113 0.012125000000000460063 -0.029999999999991699973" rpy="-1.570796326794896558 1.6686738633429766159e-15 3.141592653589793116" />
<geometry>
<mesh filename="package:///hip_v2.stl"/>
</geometry>
<material name="hip_v2_material">
<color rgba="1 1 1 1.0"/>
</material>
</visual>
<collision>
<origin xyz="0.0044749999999999998113 0.012125000000000460063 -0.029999999999991699973" rpy="-1.570796326794896558 1.6686738633429766159e-15 3.141592653589793116" />
<geometry>
<mesh filename="package:///hip_v2.stl"/>
</geometry>
</collision>
<visual>
<origin xyz="0.0044750000000063488992 -0.012125000000000468736 -0.029999999999996175559" rpy="1.570796326794896558 3.3599345559024095656e-13 3.141592653589793116" />
<geometry>
<mesh filename="package:///hip_v2.stl"/>
</geometry>
<material name="hip_v2_material">
<color rgba="1 1 1 1.0"/>
</material>
</visual>
<collision>
<origin xyz="0.0044750000000063488992 -0.012125000000000468736 -0.029999999999996175559" rpy="1.570796326794896558 3.3599345559024095656e-13 3.141592653589793116" />
<geometry>
<mesh filename="package:///hip_v2.stl"/>
</geometry>
</collision>
<visual>
<origin xyz="0.015650000000006127759 -0.0052250000000002086442 -0.029249999999993094024" rpy="1.570796326794896558 -1.5707963267945610486 0" />
<geometry>
<mesh filename="package:///microservosg90.stl"/>
</geometry>
<material name="microservosg90_material">
<color rgba="0.35294117647058825815 0.35294117647058825815 0.35294117647058825815 1.0"/>
</material>
</visual>
<collision>
<origin xyz="0.015650000000006127759 -0.0052250000000002086442 -0.029249999999993094024" rpy="1.570796326794896558 -1.5707963267945610486 0" />
<geometry>
<mesh filename="package:///microservosg90.stl"/>
</geometry>
</collision>
<visual>
<origin xyz="0 0 -0.0015000000000000013323" rpy="1.570796326794896558 2.8325808897050026847e-47 0" />
<geometry>
<mesh filename="package:///9g_servo_arm_v1.stl"/>
</geometry>
<material name="9g_servo_arm_v1_material">
<color rgba="0.62745098039215685404 0.62745098039215685404 0.62745098039215685404 1.0"/>
</material>
</visual>
<collision>
<origin xyz="0 0 -0.0015000000000000013323" rpy="1.570796326794896558 2.8325808897050026847e-47 0" />
<geometry>
<mesh filename="package:///9g_servo_arm_v1.stl"/>
</geometry>
</collision>
<visual>
<origin xyz="0.0038875000000135467859 -3.6862873864507150756e-18 -0.050899999999988107535" rpy="-3.141592653589793116 3.3732906223640650982e-13 3.141592653589793116" />
<geometry>
<mesh filename="package:///hip_joint_to_bearing_v3.stl"/>
</geometry>
<material name="hip_joint_to_bearing_v3_material">
<color rgba="1 1 1 1.0"/>
</material>
</visual>
<collision>
<origin xyz="0.0038875000000135467859 -3.6862873864507150756e-18 -0.050899999999988107535" rpy="-3.141592653589793116 3.3732906223640650982e-13 3.141592653589793116" />
<geometry>
<mesh filename="package:///hip_joint_to_bearing_v3.stl"/>
</geometry>
</collision>
<visual>
<origin xyz="-0.015649999999996784539 0.0071750000000001812328 -0.024150000000003599143" rpy="-3.0097452308196661385e-16 -1.5707963267945610486 0" />
<geometry>
<mesh filename="package:///9g_thigh_servo_attachment_v1.stl"/>
</geometry>
<material name="9g_thigh_servo_attachment_v1_material">
<color rgba="1 1 1 1.0"/>
</material>
</visual>
<collision>
<origin xyz="-0.015649999999996784539 0.0071750000000001812328 -0.024150000000003599143" rpy="-3.0097452308196661385e-16 -1.5707963267945610486 0" />
<geometry>
<mesh filename="package:///9g_thigh_servo_attachment_v1.stl"/>
</geometry>
</collision>
<visual>
<origin xyz="-0.015649999999996784539 0.0071750000000001812328 -0.024150000000003599143" rpy="-1.5707963267948970021 -1.5707963267945610486 0" />
<geometry>
<mesh filename="package:///9g_servo_arm_v1.stl"/>
</geometry>
<material name="9g_servo_arm_v1_material">
<color rgba="0.62745098039215685404 0.62745098039215685404 0.62745098039215685404 1.0"/>
</material>
</visual>
<collision>
<origin xyz="-0.015649999999996784539 0.0071750000000001812328 -0.024150000000003599143" rpy="-1.5707963267948970021 -1.5707963267945610486 0" />
<geometry>
<mesh filename="package:///9g_servo_arm_v1.stl"/>
</geometry>
</collision>
<visual>
<origin xyz="-0.022149999999992009414 0.018292109297700007847 -0.037665155617948906097" rpy="1.5707963267953299891 0.68835957731061858667 -1.5707963267946583041" />
<geometry>
<mesh filename="package:///left_forearm_linkage_v1.stl"/>
</geometry>
<material name="left_forearm_linkage_v1_material">
<color rgba="1 1 1 1.0"/>
</material>
</visual>
<collision>
<origin xyz="-0.022149999999992009414 0.018292109297700007847 -0.037665155617948906097" rpy="1.5707963267953299891 0.68835957731061858667 -1.5707963267946583041" />
<geometry>
<mesh filename="package:///left_forearm_linkage_v1.stl"/>
</geometry>
</collision>
<visual>
<origin xyz="-0.028649999999997184663 0.0071955475779957329269 -0.024133107805413583913" rpy="-1.5707963270130320677 -1.5692676824827016535 1.5707963270127294209" />
<geometry>
<mesh filename="package:///left_cover_v2.stl"/>
</geometry>
<material name="left_cover_v2_material">
<color rgba="1 1 1 1.0"/>
</material>
</visual>
<collision>
<origin xyz="-0.028649999999997184663 0.0071955475779957329269 -0.024133107805413583913" rpy="-1.5707963270130320677 -1.5692676824827016535 1.5707963270127294209" />
<geometry>
<mesh filename="package:///left_cover_v2.stl"/>
</geometry>
</collision>
<visual>
<origin xyz="-0.022149999999992009414 0.018292109297700004378 -0.037665155617948906097" rpy="1.570796326795329767 0.68835957731061858667 -1.5707963267946587482" />
<geometry>
<mesh filename="package:///bearing_5x8x2.5_v1.stl"/>
</geometry>
<material name="bearing_5x8x2.5_v1_material">
<color rgba="0.62745098039215685404 0.62745098039215685404 0.62745098039215685404 1.0"/>
</material>
</visual>
<collision>
<origin xyz="-0.022149999999992009414 0.018292109297700004378 -0.037665155617948906097" rpy="1.570796326795329767 0.68835957731061858667 -1.5707963267946587482" />
<geometry>
<mesh filename="package:///bearing_5x8x2.5_v1.stl"/>
</geometry>
</collision>
<visual>
<origin xyz="-0.017649999999996862643 0.0071750000000001812328 -0.024150000000004272216" rpy="-3.0097452308196296537e-16 -1.5707963267945610486 0" />
<geometry>
<mesh filename="package:///bearing_10x15x4_v1.stl"/>
</geometry>
<material name="bearing_10x15x4_v1_material">
<color rgba="0.62745098039215685404 0.62745098039215685404 0.62745098039215685404 1.0"/>
</material>
</visual>
<collision>
<origin xyz="-0.017649999999996862643 0.0071750000000001812328 -0.024150000000004272216" rpy="-3.0097452308196296537e-16 -1.5707963267945610486 0" />
<geometry>
<mesh filename="package:///bearing_10x15x4_v1.stl"/>
</geometry>
</collision>
<visual>
<origin xyz="-0.021649999999997018851 0.0071750000000000025563 -0.024150000000005611422" rpy="7.4578192631993298257e-15 -1.5707963267945408425 0" />
<geometry>
<mesh filename="package:///left_forearm_pivot_v1.stl"/>
</geometry>
<material name="left_forearm_pivot_v1_material">
<color rgba="1 1 1 1.0"/>
</material>
</visual>
<collision>
<origin xyz="-0.021649999999997018851 0.0071750000000000025563 -0.024150000000005611422" rpy="7.4578192631993298257e-15 -1.5707963267945408425 0" />
<geometry>
<mesh filename="package:///left_forearm_pivot_v1.stl"/>
</geometry>
</collision>
<visual>
<origin xyz="-0.019149999999988932819 0.0058922344346109770813 -0.04786506931266857473" rpy="-3.6646417738492049791e-14 -1.5707963267945406205 0" />
<geometry>
<mesh filename="package:///bearing_5x8x2.5_v1.stl"/>
</geometry>
<material name="bearing_5x8x2.5_v1_material">
<color rgba="0.62745098039215685404 0.62745098039215685404 0.62745098039215685404 1.0"/>
</material>
</visual>
<collision>
<origin xyz="-0.019149999999988932819 0.0058922344346109770813 -0.04786506931266857473" rpy="-3.6646417738492049791e-14 -1.5707963267945406205 0" />
<geometry>
<mesh filename="package:///bearing_5x8x2.5_v1.stl"/>
</geometry>
</collision>
<visual>
<origin xyz="-0.019149999999988932819 0.0058922344346109770813 -0.04786506931266857473" rpy="3.1415926535897558125 -1.5707963267945406205 0" />
<geometry>
<mesh filename="package:///servo_arm_retainer_v1.stl"/>
</geometry>
<material name="servo_arm_retainer_v1_material">
<color rgba="1 1 1 1.0"/>
</material>
</visual>
<collision>
<origin xyz="-0.019149999999988932819 0.0058922344346109770813 -0.04786506931266857473" rpy="3.1415926535897558125 -1.5707963267945406205 0" />
<geometry>
<mesh filename="package:///servo_arm_retainer_v1.stl"/>
</geometry>
</collision>
<visual>
<origin xyz="-0.01564999999999332897 -0.0052250000000002086442 -0.034350000000003599876" rpy="1.570796326794896558 1.5707963267945610486 0" />
<geometry>
<mesh filename="package:///9g_servo_arm_v1.stl"/>
</geometry>
<material name="9g_servo_arm_v1_material">
<color rgba="0.62745098039215685404 0.62745098039215685404 0.62745098039215685404 1.0"/>
</material>
</visual>
<collision>
<origin xyz="-0.01564999999999332897 -0.0052250000000002086442 -0.034350000000003599876" rpy="1.570796326794896558 1.5707963267945610486 0" />
<geometry>
<mesh filename="package:///9g_servo_arm_v1.stl"/>
</geometry>
</collision>
<visual>
<origin xyz="-0.019149999999993463917 -0.0052250000000002069095 -0.03435000000000476561" rpy="-1.570796326794896558 -1.5707963267945619368 0" />
<geometry>
<mesh filename="package:///left_forearm_servo_attachment_v1.stl"/>
</geometry>
<material name="left_forearm_servo_attachment_v1_material">
<color rgba="1 1 1 1.0"/>
</material>
</visual>
<collision>
<origin xyz="-0.019149999999993463917 -0.0052250000000002069095 -0.03435000000000476561" rpy="-1.570796326794896558 -1.5707963267945619368 0" />
<geometry>
<mesh filename="package:///left_forearm_servo_attachment_v1.stl"/>
</geometry>
</collision>
<inertial>
<origin xyz="-0.0014149870812316511087 0.0026262653552970864797 -0.028173125869927904269" rpy="0 0 0"/>
<mass value="0.035898853366757604855" />
<inertia ixx="8.8254316677968386426e-06" ixy="1.532114426534107359e-06"  ixz="-7.0751529199990173755e-07" iyy="1.1416196796456221988e-05" iyz="-1.87044727501796116e-07" izz="8.4326370763718319835e-06" />
</inertial>
</link>

<link name="leftfemur">
<visual>
<origin xyz="0.034999999999999940881 -7.6327832942979512154e-17 -0.0025000000000000438538" rpy="4.7568284676275055001e-29 -8.5779697974769760301e-30 7.863641712915428063e-17" />
<geometry>
<mesh filename="package:///bearing_5x8x2.5_v1.stl"/>
</geometry>
<material name="bearing_5x8x2.5_v1_material">
<color rgba="0.62745098039215685404 0.62745098039215685404 0.62745098039215685404 1.0"/>
</material>
</visual>
<collision>
<origin xyz="0.034999999999999940881 -7.6327832942979512154e-17 -0.0025000000000000438538" rpy="4.7568284676275055001e-29 -8.5779697974769760301e-30 7.863641712915428063e-17" />
<geometry>
<mesh filename="package:///bearing_5x8x2.5_v1.stl"/>
</geometry>
</collision>
<visual>
<origin xyz="3.2959746043559334794e-17 2.0816681711721685133e-17 0" rpy="-3.141592653589793116 -8.5779697974769760301e-30 7.863641712915428063e-17" />
<geometry>
<mesh filename="package:///lever_v1.stl"/>
</geometry>
<material name="lever_v1_material">
<color rgba="1 1 1 1.0"/>
</material>
</visual>
<collision>
<origin xyz="3.2959746043559334794e-17 2.0816681711721685133e-17 0" rpy="-3.141592653589793116 -8.5779697974769760301e-30 7.863641712915428063e-17" />
<geometry>
<mesh filename="package:///lever_v1.stl"/>
</geometry>
</collision>
<visual>
<origin xyz="3.4694469519536141888e-18 0 -0.0025000000000000022204" rpy="4.7568284676275055001e-29 -8.5779697974769760301e-30 7.863641712915428063e-17" />
<geometry>
<mesh filename="package:///bearing_5x8x2.5_v1.stl"/>
</geometry>
<material name="bearing_5x8x2.5_v1_material">
<color rgba="0.62745098039215685404 0.62745098039215685404 0.62745098039215685404 1.0"/>
</material>
</visual>
<collision>
<origin xyz="3.4694469519536141888e-18 0 -0.0025000000000000022204" rpy="4.7568284676275055001e-29 -8.5779697974769760301e-30 7.863641712915428063e-17" />
<geometry>
<mesh filename="package:///bearing_5x8x2.5_v1.stl"/>
</geometry>
</collision>
<inertial>
<origin xyz="0.016745239433454645744 0.0019623707901208313487 -0.0012499999999999941713" rpy="0 0 0"/>
<mass value="0.0012188090534078449383" />
<inertia ixx="2.3153914212892995394e-08" ixy="7.3509510903220456391e-09"  ixz="6.4677673442838312695e-23" iyy="2.7100368005614667726e-07" iyz="-1.1013682103627191855e-23" izz="2.9302349553645665563e-07" />
</inertial>
</link>

<joint name="femur_leftfront" type="revolute">
<origin xyz="-0.024650000000001379141 0.019549368670763494354 -0.011775631329240955625" rpy="1.5707963267953350961 -0.66646697390099118863 -1.5707963267951601249" />
<parent link="lefthip" />
<child link="leftfemur" />
<axis xyz="0 0 1"/>
<limit effort="1" velocity="20" />
<joint_properties friction="0.0"/>
</joint>

<link name="leftthigh">
<visual>
<origin xyz="-3.4694469519536141888e-18 0 -0.0070000000000000062172" rpy="5.4742687698995843745e-31 -3.6535692386386408112e-31 -2.5408264050719269255e-17" />
<geometry>
<mesh filename="package:///right_thigh_v1.stl"/>
</geometry>
<material name="right_thigh_v1_material">
<color rgba="1 1 1 1.0"/>
</material>
</visual>
<collision>
<origin xyz="-3.4694469519536141888e-18 0 -0.0070000000000000062172" rpy="5.4742687698995843745e-31 -3.6535692386386408112e-31 -2.5408264050719269255e-17" />
<geometry>
<mesh filename="package:///right_thigh_v1.stl"/>
</geometry>
</collision>
<visual>
<origin xyz="0.034999999999982031595 -7.9866668833972198627e-15 -0.0044999999999999137912" rpy="-3.1415926535897917837 -3.4416913763379604262e-15 -9.3086176128034095306e-16" />
<geometry>
<mesh filename="package:///bearing_5x8x2.5_v1.stl"/>
</geometry>
<material name="bearing_5x8x2.5_v1_material">
<color rgba="0.62745098039215685404 0.62745098039215685404 0.62745098039215685404 1.0"/>
</material>
</visual>
<collision>
<origin xyz="0.034999999999982031595 -7.9866668833972198627e-15 -0.0044999999999999137912" rpy="-3.1415926535897917837 -3.4416913763379604262e-15 -9.3086176128034095306e-16" />
<geometry>
<mesh filename="package:///bearing_5x8x2.5_v1.stl"/>
</geometry>
</collision>
<inertial>
<origin xyz="0.013280795299928628561 -0.00036090962217551761848 -0.0044952882793202562223" rpy="0 0 0"/>
<mass value="0.0018464875329195406996" />
<inertia ixx="2.9147242782952542949e-08" ixy="3.1720502075642909226e-09"  ixz="1.4292641337521414662e-08" iyy="3.5092221986757939663e-07" iyz="-8.5226644673134721281e-10" izz="3.6712034510499322975e-07" />
</inertial>
</link>

<link name="leftfoot">
<visual>
<origin xyz="6.9388939039072283776e-18 0 -0.0030000000000000026645" rpy="-1.570796326794896558 6.2554387988365730492e-31 -6.3841240699234761017e-17" />
<geometry>
<mesh filename="package:///left_forearm_inside_v1.stl"/>
</geometry>
<material name="left_forearm_inside_v1_material">
<color rgba="1 1 1 1.0"/>
</material>
</visual>
<collision>
<origin xyz="6.9388939039072283776e-18 0 -0.0030000000000000026645" rpy="-1.570796326794896558 6.2554387988365730492e-31 -6.3841240699234761017e-17" />
<geometry>
<mesh filename="package:///left_forearm_inside_v1.stl"/>
</geometry>
</collision>
<visual>
<origin xyz="2.2898349882893853646e-16 -6.9388939039072283776e-18 0.0004999999999999935052" rpy="-1.570796326794896336 7.0829393489087497923e-28 -1.8930827081845103288e-16" />
<geometry>
<mesh filename="package:///left_forearm_outside_v1.stl"/>
</geometry>
<material name="left_forearm_outside_v1_material">
<color rgba="1 1 1 1.0"/>
</material>
</visual>
<collision>
<origin xyz="2.2898349882893853646e-16 -6.9388939039072283776e-18 0.0004999999999999935052" rpy="-1.570796326794896336 7.0829393489087497923e-28 -1.8930827081845103288e-16" />
<geometry>
<mesh filename="package:///left_forearm_outside_v1.stl"/>
</geometry>
</collision>
<inertial>
<origin xyz="-0.011359259428207637774 0.00069384123630962600115 -0.0010747482996256516995" rpy="0 0 0"/>
<mass value="0.0052313671076180037062" />
<inertia ixx="1.3990969757495892314e-07" ixy="3.9342837035930358058e-08"  ixz="-1.017404545663355283e-08" iyy="2.2588013896284998625e-06" iyz="-6.5844125899862462313e-09" izz="2.2886673861905136574e-06" />
</inertial>
</link>

<joint name="foot_leftfront" type="revolute">
<origin xyz="0.034999999999982038534 -7.9831974364452662485e-15 -0.0069999999999999090727" rpy="-3.1415926535897900074 1.5819249601435661476e-15 -1.6352595016448581156" />
<parent link="leftthigh" />
<child link="leftfoot" />
<axis xyz="0 0 1"/>
<limit effort="1" velocity="20" lower="0" upper="1.0472"/>
<joint_properties friction="0.0"/>
</joint>

<joint name="thigh_leftfront" type="revolute">
<origin xyz="-0.017649999999997466327 0.0071749999999998707173 -0.024150000000004362422" rpy="-1.5707963267949041075 -0.68299626649609701534 -1.5707963267948936714" />
<parent link="lefthip" />
<child link="leftthigh" />
<axis xyz="0 0 1"/>
<limit effort="1" velocity="20" lower="0" upper="1.0472"/>
<joint_properties friction="0.0"/>
</joint>

<joint name="frontlefthip" type="revolute">
<origin xyz="0.036800000000001262257 0.05650000000000113265 -0.00047047612756291601332" rpy="1.570796326794896558 -1.0668549377256967968e-16 -3.141592653589788231" />
<parent link="chassis" />
<child link="lefthip" />
<axis xyz="0 0 1"/>
<limit effort="1" velocity="20" lower="-0.261799" upper="0.261799"/>
<joint_properties friction="0.0"/>
</joint>

<link name="lefthip_2">
<visual>
<origin xyz="0.015650000000005537953 0.0071749999999998950034 -0.029249999999993128719" rpy="-1.570796326794896558 1.5707963267945610486 0" />
<geometry>
<mesh filename="package:///microservosg90.stl"/>
</geometry>
<material name="microservosg90_material">
<color rgba="0.35294117647058825815 0.35294117647058825815 0.35294117647058825815 1.0"/>
</material>
</visual>
<collision>
<origin xyz="0.015650000000005537953 0.0071749999999998950034 -0.029249999999993128719" rpy="-1.570796326794896558 1.5707963267945610486 0" />
<geometry>
<mesh filename="package:///microservosg90.stl"/>
</geometry>
</collision>
<visual>
<origin xyz="0 0 -0.0015000000000000013323" rpy="3.141592653589793116 1.8883938382011724743e-48 -2.0141931291528256535e-33" />
<geometry>
<mesh filename="package:///18g_thigh_servo_attachment_v3.stl"/>
</geometry>
<material name="18g_thigh_servo_attachment_v3_material">
<color rgba="1 1 1 1.0"/>
</material>
</visual>
<collision>
<origin xyz="0 0 -0.0015000000000000013323" rpy="3.141592653589793116 1.8883938382011724743e-48 -2.0141931291528256535e-33" />
<geometry>
<mesh filename="package:///18g_thigh_servo_attachment_v3.stl"/>
</geometry>
</collision>
<visual>
<origin xyz="0.0038875000000000159428 -3.794707603699265519e-18 -0.0090999999999999969802" rpy="1.939190072544337729e-32 -1.8883938382011724743e-48 3.141592653589793116" />
<geometry>
<mesh filename="package:///hip_joint_to_servo_v2.stl"/>
</geometry>
<material name="hip_joint_to_servo_v2_material">
<color rgba="1 1 1 1.0"/>
</material>
</visual>
<collision>
<origin xyz="0.0038875000000000159428 -3.794707603699265519e-18 -0.0090999999999999969802" rpy="1.939190072544337729e-32 -1.8883938382011724743e-48 3.141592653589793116" />
<geometry>
<mesh filename="package:///hip_joint_to_servo_v2.stl"/>
</geometry>
</collision>
<visual>
<origin xyz="0.0044749999999998402167 0.012124999999999991687 -0.029999999999991755484" rpy="-1.570796326794896558 1.3356066461656161757e-15 3.141592653589793116" />
<geometry>
<mesh filename="package:///hip_v2.stl"/>
</geometry>
<material name="hip_v2_material">
<color rgba="1 1 1 1.0"/>
</material>
</visual>
<collision>
<origin xyz="0.0044749999999998402167 0.012124999999999991687 -0.029999999999991755484" rpy="-1.570796326794896558 1.3356066461656161757e-15 3.141592653589793116" />
<geometry>
<mesh filename="package:///hip_v2.stl"/>
</geometry>
</collision>
<visual>
<origin xyz="0.0044750000000061962435 -0.012125000000000002096 -0.029999999999996210254" rpy="1.570796326794896558 3.3566038837307654211e-13 3.141592653589793116" />
<geometry>
<mesh filename="package:///hip_v2.stl"/>
</geometry>
<material name="hip_v2_material">
<color rgba="1 1 1 1.0"/>
</material>
</visual>
<collision>
<origin xyz="0.0044750000000061962435 -0.012125000000000002096 -0.029999999999996210254" rpy="1.570796326794896558 3.3566038837307654211e-13 3.141592653589793116" />
<geometry>
<mesh filename="package:///hip_v2.stl"/>
</geometry>
</collision>
<visual>
<origin xyz="0.01565000000000555877 -0.0052250000000000100184 -0.029249999999993128719" rpy="1.570796326794896558 -1.5707963267945610486 0" />
<geometry>
<mesh filename="package:///microservosg90.stl"/>
</geometry>
<material name="microservosg90_material">
<color rgba="0.35294117647058825815 0.35294117647058825815 0.35294117647058825815 1.0"/>
</material>
</visual>
<collision>
<origin xyz="0.01565000000000555877 -0.0052250000000000100184 -0.029249999999993128719" rpy="1.570796326794896558 -1.5707963267945610486 0" />
<geometry>
<mesh filename="package:///microservosg90.stl"/>
</geometry>
</collision>
<visual>
<origin xyz="0 0 -0.0015000000000000013323" rpy="1.570796326794896558 1.8883938382011724743e-48 -2.0141931291528711546e-33" />
<geometry>
<mesh filename="package:///9g_servo_arm_v1.stl"/>
</geometry>
<material name="9g_servo_arm_v1_material">
<color rgba="0.62745098039215685404 0.62745098039215685404 0.62745098039215685404 1.0"/>
</material>
</visual>
<collision>
<origin xyz="0 0 -0.0015000000000000013323" rpy="1.570796326794896558 1.8883938382011724743e-48 -2.0141931291528711546e-33" />
<geometry>
<mesh filename="package:///9g_servo_arm_v1.stl"/>
</geometry>
</collision>
<visual>
<origin xyz="0.0038875000000134218858 -3.3610267347050637454e-18 -0.050899999999988163046" rpy="-3.141592653589793116 3.3699599501924214586e-13 3.141592653589793116" />
<geometry>
<mesh filename="package:///hip_joint_to_bearing_v3.stl"/>
</geometry>
<material name="hip_joint_to_bearing_v3_material">
<color rgba="1 1 1 1.0"/>
</material>
</visual>
<collision>
<origin xyz="0.0038875000000134218858 -3.3610267347050637454e-18 -0.050899999999988163046" rpy="-3.141592653589793116 3.3699599501924214586e-13 3.141592653589793116" />
<geometry>
<mesh filename="package:///hip_joint_to_bearing_v3.stl"/>
</geometry>
</collision>
<visual>
<origin xyz="-0.015649999999996201672 0.0071749999999999002076 -0.024150000000003585265" rpy="-1.6653345369385113456e-16 -1.5707963267945610486 0" />
<geometry>
<mesh filename="package:///9g_thigh_servo_attachment_v1.stl"/>
</geometry>
<material name="9g_thigh_servo_attachment_v1_material">
<color rgba="1 1 1 1.0"/>
</material>
</visual>
<collision>
<origin xyz="-0.015649999999996201672 0.0071749999999999002076 -0.024150000000003585265" rpy="-1.6653345369385113456e-16 -1.5707963267945610486 0" />
<geometry>
<mesh filename="package:///9g_thigh_servo_attachment_v1.stl"/>
</geometry>
</collision>
<visual>
<origin xyz="-0.015649999999996201672 0.0071749999999999002076 -0.024150000000003585265" rpy="-1.57079632679489678 -1.5707963267945610486 0" />
<geometry>
<mesh filename="package:///9g_servo_arm_v1.stl"/>
</geometry>
<material name="9g_servo_arm_v1_material">
<color rgba="0.62745098039215685404 0.62745098039215685404 0.62745098039215685404 1.0"/>
</material>
</visual>
<collision>
<origin xyz="-0.015649999999996201672 0.0071749999999999002076 -0.024150000000003585265" rpy="-1.57079632679489678 -1.5707963267945610486 0" />
<geometry>
<mesh filename="package:///9g_servo_arm_v1.stl"/>
</geometry>
</collision>
<visual>
<origin xyz="-0.022149999999991724919 0.018292112015483981413 -0.03766515892191818482" rpy="1.5707963267953330977 0.68835931085885382341 -1.5707963267946181141" />
<geometry>
<mesh filename="package:///left_forearm_linkage_v1.stl"/>
</geometry>
<material name="left_forearm_linkage_v1_material">
<color rgba="1 1 1 1.0"/>
</material>
</visual>
<collision>
<origin xyz="-0.022149999999991724919 0.018292112015483981413 -0.03766515892191818482" rpy="1.5707963267953330977 0.68835931085885382341 -1.5707963267946181141" />
<geometry>
<mesh filename="package:///left_forearm_linkage_v1.stl"/>
</geometry>
</collision>
<visual>
<origin xyz="-0.028649999999996268729 0.0071911362092343623573 -0.024136731956856588566" rpy="-1.5707963270749540907 -1.569593921142050208 1.570796327074955423" />
<geometry>
<mesh filename="package:///left_cover_v2.stl"/>
</geometry>
<material name="left_cover_v2_material">
<color rgba="1 1 1 1.0"/>
</material>
</visual>
<collision>
<origin xyz="-0.028649999999996268729 0.0071911362092343623573 -0.024136731956856588566" rpy="-1.5707963270749540907 -1.569593921142050208 1.570796327074955423" />
<geometry>
<mesh filename="package:///left_cover_v2.stl"/>
</geometry>
</collision>
<visual>
<origin xyz="-0.022149999999991724919 0.018292112015483981413 -0.03766515892191818482" rpy="1.5707963267953328756 0.68835931085885382341 -1.5707963267946185582" />
<geometry>
<mesh filename="package:///bearing_5x8x2.5_v1.stl"/>
</geometry>
<material name="bearing_5x8x2.5_v1_material">
<color rgba="0.62745098039215685404 0.62745098039215685404 0.62745098039215685404 1.0"/>
</material>
</visual>
<collision>
<origin xyz="-0.022149999999991724919 0.018292112015483981413 -0.03766515892191818482" rpy="1.5707963267953328756 0.68835931085885382341 -1.5707963267946185582" />
<geometry>
<mesh filename="package:///bearing_5x8x2.5_v1.stl"/>
</geometry>
</collision>
<visual>
<origin xyz="-0.017649999999996203448 0.0071749999999999002076 -0.024150000000004223644" rpy="-1.6653345369384598231e-16 -1.5707963267945610486 0" />
<geometry>
<mesh filename="package:///bearing_10x15x4_v1.stl"/>
</geometry>
<material name="bearing_10x15x4_v1_material">
<color rgba="0.62745098039215685404 0.62745098039215685404 0.62745098039215685404 1.0"/>
</material>
</visual>
<collision>
<origin xyz="-0.017649999999996203448 0.0071749999999999002076 -0.024150000000004223644" rpy="-1.6653345369384598231e-16 -1.5707963267945610486 0" />
<geometry>
<mesh filename="package:///bearing_10x15x4_v1.stl"/>
</geometry>
</collision>
<visual>
<origin xyz="-0.021649999999996207001 0.0071749999999998707173 -0.024150000000005639178" rpy="7.515325517993973856e-15 -1.5707963267945397323 0" />
<geometry>
<mesh filename="package:///left_forearm_pivot_v1.stl"/>
</geometry>
<material name="left_forearm_pivot_v1_material">
<color rgba="1 1 1 1.0"/>
</material>
</visual>
<collision>
<origin xyz="-0.021649999999996207001 0.0071749999999998707173 -0.024150000000005639178" rpy="7.515325517993973856e-15 -1.5707963267945397323 0" />
<geometry>
<mesh filename="package:///left_forearm_pivot_v1.stl"/>
</geometry>
</collision>
<visual>
<origin xyz="-0.019149999999988266686 0.0058922344346107767207 -0.047865069312668720447" rpy="1.3121801045090071902e-15 -1.5707963267945455055 0" />
<geometry>
<mesh filename="package:///bearing_5x8x2.5_v1.stl"/>
</geometry>
<material name="bearing_5x8x2.5_v1_material">
<color rgba="0.62745098039215685404 0.62745098039215685404 0.62745098039215685404 1.0"/>
</material>
</visual>
<collision>
<origin xyz="-0.019149999999988266686 0.0058922344346107767207 -0.047865069312668720447" rpy="1.3121801045090071902e-15 -1.5707963267945455055 0" />
<geometry>
<mesh filename="package:///bearing_5x8x2.5_v1.stl"/>
</geometry>
</collision>
<visual>
<origin xyz="-0.019149999999988266686 0.0058922344346107767207 -0.047865069312668720447" rpy="3.141592653589793116 -1.5707963267945455055 0" />
<geometry>
<mesh filename="package:///servo_arm_retainer_v1.stl"/>
</geometry>
<material name="servo_arm_retainer_v1_material">
<color rgba="1 1 1 1.0"/>
</material>
</visual>
<collision>
<origin xyz="-0.019149999999988266686 0.0058922344346107767207 -0.047865069312668720447" rpy="3.141592653589793116 -1.5707963267945455055 0" />
<geometry>
<mesh filename="package:///servo_arm_retainer_v1.stl"/>
</geometry>
</collision>
<visual>
<origin xyz="-0.015649999999992801614 -0.0052250000000000100184 -0.034350000000003613754" rpy="1.570796326794896558 1.5707963267945610486 0" />
<geometry>
<mesh filename="package:///9g_servo_arm_v1.stl"/>
</geometry>
<material name="9g_servo_arm_v1_material">
<color rgba="0.62745098039215685404 0.62745098039215685404 0.62745098039215685404 1.0"/>
</material>
</visual>
<collision>
<origin xyz="-0.015649999999992801614 -0.0052250000000000100184 -0.034350000000003613754" rpy="1.570796326794896558 1.5707963267945610486 0" />
<geometry>
<mesh filename="package:///9g_servo_arm_v1.stl"/>
</geometry>
</collision>
<visual>
<origin xyz="-0.019149999999992804722 -0.0052250000000000048142 -0.034350000000004821121" rpy="-1.570796326794896558 -1.5707963267945614927 0" />
<geometry>
<mesh filename="package:///left_forearm_servo_attachment_v1.stl"/>
</geometry>
<material name="left_forearm_servo_attachment_v1_material">
<color rgba="1 1 1 1.0"/>
</material>
</visual>
<collision>
<origin xyz="-0.019149999999992804722 -0.0052250000000000048142 -0.034350000000004821121" rpy="-1.570796326794896558 -1.5707963267945614927 0" />
<geometry>
<mesh filename="package:///left_forearm_servo_attachment_v1.stl"/>
</geometry>
</collision>
<inertial>
<origin xyz="-0.0014149870812316159806 0.0026260940434307085065 -0.028173120215437514463" rpy="0 0 0"/>
<mass value="0.035898853366757604855" />
<inertia ixx="8.8252350075534863192e-06" ixy="1.5319581048346755496e-06"  ixz="-7.0751013417707437857e-07" iyy="1.1416196374334960703e-05" iyz="-1.8697377752515767672e-07" izz="8.432440838249219173e-06" />
</inertial>
</link>

<link name="leftthigh_2">
<visual>
<origin xyz="2.7755575615628913511e-17 -1.3877787807814456755e-17 -0.0069999999999999992784" rpy="-1.6587655943793013598e-30 7.1848564593495938115e-31 -8.2698090563950440512e-17" />
<geometry>
<mesh filename="package:///right_thigh_v1.stl"/>
</geometry>
<material name="right_thigh_v1_material">
<color rgba="1 1 1 1.0"/>
</material>
</visual>
<collision>
<origin xyz="2.7755575615628913511e-17 -1.3877787807814456755e-17 -0.0069999999999999992784" rpy="-1.6587655943793013598e-30 7.1848564593495938115e-31 -8.2698090563950440512e-17" />
<geometry>
<mesh filename="package:///right_thigh_v1.stl"/>
</geometry>
</collision>
<visual>
<origin xyz="0.035000000000000114353 -2.4286128663675299322e-15 -0.0044999999999998721578" rpy="-3.1415926535897868987 -1.3878168082507866525e-15 -1.0612352477184145494e-13" />
<geometry>
<mesh filename="package:///bearing_5x8x2.5_v1.stl"/>
</geometry>
<material name="bearing_5x8x2.5_v1_material">
<color rgba="0.62745098039215685404 0.62745098039215685404 0.62745098039215685404 1.0"/>
</material>
</visual>
<collision>
<origin xyz="0.035000000000000114353 -2.4286128663675299322e-15 -0.0044999999999998721578" rpy="-3.1415926535897868987 -1.3878168082507866525e-15 -1.0612352477184145494e-13" />
<geometry>
<mesh filename="package:///bearing_5x8x2.5_v1.stl"/>
</geometry>
</collision>
<inertial>
<origin xyz="0.013280795299929471637 -0.00036090962217528164187 -0.004495288279320248416" rpy="0 0 0"/>
<mass value="0.0018464875329195406996" />
<inertia ixx="2.9147242782952867204e-08" ixy="3.1720502075536843992e-09"  ixz="1.4292641337523231151e-08" iyy="3.5092221986764440641e-07" iyz="-8.5226644673077056452e-10" izz="3.6712034510505861011e-07" />
</inertial>
</link>

<link name="leftfoot_2">
<visual>
<origin xyz="0 1.3877787807814456755e-17 -0.0029999999999999957256" rpy="-1.570796326794896558 3.1312747343029501189e-31 3.2883220873265247532e-17" />
<geometry>
<mesh filename="package:///left_forearm_inside_v1.stl"/>
</geometry>
<material name="left_forearm_inside_v1_material">
<color rgba="1 1 1 1.0"/>
</material>
</visual>
<collision>
<origin xyz="0 1.3877787807814456755e-17 -0.0029999999999999957256" rpy="-1.570796326794896558 3.1312747343029501189e-31 3.2883220873265247532e-17" />
<geometry>
<mesh filename="package:///left_forearm_inside_v1.stl"/>
</geometry>
</collision>
<visual>
<origin xyz="-5.9674487573602164048e-16 -1.3877787807814456755e-17 0.00050000000000000738298" rpy="-1.57079632679489678 -1.9003765303402921395e-28 -9.6648317970636003512e-17" />
<geometry>
<mesh filename="package:///left_forearm_outside_v1.stl"/>
</geometry>
<material name="left_forearm_outside_v1_material">
<color rgba="1 1 1 1.0"/>
</material>
</visual>
<collision>
<origin xyz="-5.9674487573602164048e-16 -1.3877787807814456755e-17 0.00050000000000000738298" rpy="-1.57079632679489678 -1.9003765303402921395e-28 -9.6648317970636003512e-17" />
<geometry>
<mesh filename="package:///left_forearm_outside_v1.stl"/>
</geometry>
</collision>
<inertial>
<origin xyz="-0.011359259428207929207 0.00069384123630961461703 -0.0010747482996256412912" rpy="0 0 0"/>
<mass value="0.0052313671076180037062" />
<inertia ixx="1.3990969757495656733e-07" ixy="3.9342837035929702931e-08"  ixz="-1.0174045456629052967e-08" iyy="2.258801389628446923e-06" iyz="-6.5844125899861618589e-09" izz="2.2886673861905085752e-06" />
</inertial>
</link>

<joint name="foot_leftback" type="revolute">
<origin xyz="0.035000000000000114353 -2.4286128663675299322e-15 -0.0069999999999998813172" rpy="-3.1415926535897926719 6.666559147123260302e-15 -1.6625457993150511982" />
<parent link="leftthigh_2" />
<child link="leftfoot_2" />
<axis xyz="0 0 1"/>
<limit effort="1" velocity="20" lower="0" upper="1.0472"/>
<joint_properties friction="0.0"/>
</joint>

<joint name="thigh_leftback" type="revolute">
<origin xyz="-0.017649999999996203448 0.0071749999999998993402 -0.024150000000004251399" rpy="-1.5707963267948976682 -0.64616105155389358394 -1.5707963267948978903" />
<parent link="lefthip_2" />
<child link="leftthigh_2" />
<axis xyz="0 0 1"/>
<limit effort="1" velocity="20" lower="0" upper="1.0472"/>
<joint_properties friction="0.0"/>
</joint>

<link name="leftfemur_2">
<visual>
<origin xyz="0.034999999999999989453 -5.5511151231257827021e-17 -0.0025000000000000785483" rpy="-4.7003320330476297992e-29 5.3474257298405755403e-31 -1.8089770761682631591e-17" />
<geometry>
<mesh filename="package:///bearing_5x8x2.5_v1.stl"/>
</geometry>
<material name="bearing_5x8x2.5_v1_material">
<color rgba="0.62745098039215685404 0.62745098039215685404 0.62745098039215685404 1.0"/>
</material>
</visual>
<collision>
<origin xyz="0.034999999999999989453 -5.5511151231257827021e-17 -0.0025000000000000785483" rpy="-4.7003320330476297992e-29 5.3474257298405755403e-31 -1.8089770761682631591e-17" />
<geometry>
<mesh filename="package:///bearing_5x8x2.5_v1.stl"/>
</geometry>
</collision>
<visual>
<origin xyz="-1.3877787807814456755e-17 0 -6.9388939039072283776e-18" rpy="3.141592653589793116 5.3474257298405755403e-31 -1.8089770761682631591e-17" />
<geometry>
<mesh filename="package:///lever_v1.stl"/>
</geometry>
<material name="lever_v1_material">
<color rgba="1 1 1 1.0"/>
</material>
</visual>
<collision>
<origin xyz="-1.3877787807814456755e-17 0 -6.9388939039072283776e-18" rpy="3.141592653589793116 5.3474257298405755403e-31 -1.8089770761682631591e-17" />
<geometry>
<mesh filename="package:///lever_v1.stl"/>
</geometry>
</collision>
<visual>
<origin xyz="1.3877787807814456755e-17 1.3877787807814456755e-17 -0.0025000000000000022204" rpy="-4.7003320330476297992e-29 5.3474257298405755403e-31 -1.8089770761682631591e-17" />
<geometry>
<mesh filename="package:///bearing_5x8x2.5_v1.stl"/>
</geometry>
<material name="bearing_5x8x2.5_v1_material">
<color rgba="0.62745098039215685404 0.62745098039215685404 0.62745098039215685404 1.0"/>
</material>
</visual>
<collision>
<origin xyz="1.3877787807814456755e-17 1.3877787807814456755e-17 -0.0025000000000000022204" rpy="-4.7003320330476297992e-29 5.3474257298405755403e-31 -1.8089770761682631591e-17" />
<geometry>
<mesh filename="package:///bearing_5x8x2.5_v1.stl"/>
</geometry>
</collision>
<inertial>
<origin xyz="0.01674523943345460758 0.0019623707901208148688 -0.0012500000000000024113" rpy="0 0 0"/>
<mass value="0.0012188090534078449383" />
<inertia ixx="2.3153914212892968924e-08" ixy="7.3509510903220762448e-09"  ixz="1.1634909507890988143e-22" iyy="2.7100368005614683607e-07" iyz="-1.4402507366291264109e-23" izz="2.9302349553645681445e-07" />
</inertial>
</link>

<joint name="femur_leftback" type="revolute">
<origin xyz="-0.024650000000000588107 0.019549368670763497824 -0.011775631329240782152" rpy="1.5707963267953368725 -0.67051192598255138222 -1.5707963267951625674" />
<parent link="lefthip_2" />
<child link="leftfemur_2" />
<axis xyz="0 0 1"/>
<limit effort="1" velocity="20" />
<joint_properties friction="0.0"/>
</joint>

<joint name="backlefthip" type="revolute">
<origin xyz="0.036800000000000526734 0.15150000000000207745 -0.00047047612756298231229" rpy="1.570796326794896558 -1.0648674274956321072e-16 -3.141592653589783346" />
<parent link="chassis" />
<child link="lefthip_2" />
<axis xyz="0 0 1"/>
<limit effort="1" velocity="20" lower="-0.261799" upper="0.261799"/>
<joint_properties friction="0.0"/>
</joint>

<link name="righthip">
<visual>
<origin xyz="0.015657067775926254011 0.0049611362854387417581 -0.030749999999990756949" rpy="1.570796326794896558 -1.570796326794896336 0" />
<geometry>
<mesh filename="package:///microservosg90.stl"/>
</geometry>
<material name="microservosg90_material">
<color rgba="0.35294117647058825815 0.35294117647058825815 0.35294117647058825815 1.0"/>
</material>
</visual>
<collision>
<origin xyz="0.015657067775926254011 0.0049611362854387417581 -0.030749999999990756949" rpy="1.570796326794896558 -1.570796326794896336 0" />
<geometry>
<mesh filename="package:///microservosg90.stl"/>
</geometry>
</collision>
<visual>
<origin xyz="0.0044749999999997083777 0.012124999999999811276 -0.029999999999991502214" rpy="-1.5707963267948972241 1.3356066461656469413e-15 -3.141592653589793116" />
<geometry>
<mesh filename="package:///hip_v2.stl"/>
</geometry>
<material name="hip_v2_material">
<color rgba="1 1 1 1.0"/>
</material>
</visual>
<collision>
<origin xyz="0.0044749999999997083777 0.012124999999999811276 -0.029999999999991502214" rpy="-1.5707963267948972241 1.3356066461656469413e-15 -3.141592653589793116" />
<geometry>
<mesh filename="package:///hip_v2.stl"/>
</geometry>
</collision>
<visual>
<origin xyz="0.0044750000000060019545 -0.012124999999999814745 -0.029999999999995991679" rpy="1.5707963267948958919 3.35660388373080884e-13 -3.141592653589793116" />
<geometry>
<mesh filename="package:///hip_v2.stl"/>
</geometry>
<material name="hip_v2_material">
<color rgba="1 1 1 1.0"/>
</material>
</visual>
<collision>
<origin xyz="0.0044750000000060019545 -0.012124999999999814745 -0.029999999999995991679" rpy="1.5707963267948958919 3.35660388373080884e-13 -3.141592653589793116" />
<geometry>
<mesh filename="package:///hip_v2.stl"/>
</geometry>
</collision>
<visual>
<origin xyz="0 0 -0.0015000000000000013323" rpy="-3.1415926535897926719 -1.7790256896821891905e-30 2.1974391885873893687e-31" />
<geometry>
<mesh filename="package:///18g_thigh_servo_attachment_v3.stl"/>
</geometry>
<material name="18g_thigh_servo_attachment_v3_material">
<color rgba="1 1 1 1.0"/>
</material>
</visual>
<collision>
<origin xyz="0 0 -0.0015000000000000013323" rpy="-3.1415926535897926719 -1.7790256896821891905e-30 2.1974391885873893687e-31" />
<geometry>
<mesh filename="package:///18g_thigh_servo_attachment_v3.stl"/>
</geometry>
</collision>
<visual>
<origin xyz="0.0038875000000003698264 1.3145951341386741262e-18 -0.050899999999988863875" rpy="3.1415926535897926719 3.369959950192466897e-13 3.141592653589793116" />
<geometry>
<mesh filename="package:///hip_joint_to_bearing_v3.stl"/>
</geometry>
<material name="hip_joint_to_bearing_v3_material">
<color rgba="1 1 1 1.0"/>
</material>
</visual>
<collision>
<origin xyz="0.0038875000000003698264 1.3145951341386741262e-18 -0.050899999999988863875" rpy="3.1415926535897926719 3.369959950192466897e-13 3.141592653589793116" />
<geometry>
<mesh filename="package:///hip_joint_to_bearing_v3.stl"/>
</geometry>
</collision>
<visual>
<origin xyz="0 0 -0.0015000000000000013323" rpy="1.570796326794896558 -2.01303879236435367e-31 -2.1232107345180670311e-33" />
<geometry>
<mesh filename="package:///9g_servo_arm_v1.stl"/>
</geometry>
<material name="9g_servo_arm_v1_material">
<color rgba="0.62745098039215685404 0.62745098039215685404 0.62745098039215685404 1.0"/>
</material>
</visual>
<collision>
<origin xyz="0 0 -0.0015000000000000013323" rpy="1.570796326794896558 -2.01303879236435367e-31 -2.1232107345180670311e-33" />
<geometry>
<mesh filename="package:///9g_servo_arm_v1.stl"/>
</geometry>
</collision>
<visual>
<origin xyz="0.015657067775926205438 -0.0074388637145611086199 -0.030749999999990760419" rpy="-1.5707963267948952257 1.570796326794896336 0" />
<geometry>
<mesh filename="package:///microservosg90.stl"/>
</geometry>
<material name="microservosg90_material">
<color rgba="0.35294117647058825815 0.35294117647058825815 0.35294117647058825815 1.0"/>
</material>
</visual>
<collision>
<origin xyz="0.015657067775926205438 -0.0074388637145611086199 -0.030749999999990760419" rpy="-1.5707963267948952257 1.570796326794896336 0" />
<geometry>
<mesh filename="package:///microservosg90.stl"/>
</geometry>
</collision>
<visual>
<origin xyz="0.0038874999999998910427 -3.8353651851674719353e-18 -0.0090999999999999345301" rpy="-6.6612207091510841665e-16 1.7790256896821898912e-30 -3.141592653589793116" />
<geometry>
<mesh filename="package:///hip_joint_to_servo_v2.stl"/>
</geometry>
<material name="hip_joint_to_servo_v2_material">
<color rgba="1 1 1 1.0"/>
</material>
</visual>
<collision>
<origin xyz="0.0038874999999998910427 -3.8353651851674719353e-18 -0.0090999999999999345301" rpy="-6.6612207091510841665e-16 1.7790256896821898912e-30 -3.141592653589793116" />
<geometry>
<mesh filename="package:///hip_joint_to_servo_v2.stl"/>
</geometry>
</collision>
<visual>
<origin xyz="-0.021642932224072770897 -0.0074388637145610522414 -0.025649999999990850258" rpy="3.1415926535897917837 -1.5707963267948950037 0" />
<geometry>
<mesh filename="package:///bearing_10x15x4_v1.stl"/>
</geometry>
<material name="bearing_10x15x4_v1_material">
<color rgba="0.62745098039215685404 0.62745098039215685404 0.62745098039215685404 1.0"/>
</material>
</visual>
<collision>
<origin xyz="-0.021642932224072770897 -0.0074388637145610522414 -0.025649999999990850258" rpy="3.1415926535897917837 -1.5707963267948950037 0" />
<geometry>
<mesh filename="package:///bearing_10x15x4_v1.stl"/>
</geometry>
</collision>
<visual>
<origin xyz="-0.021642932224072770897 -0.0074388637145610522414 -0.025649999999990850258" rpy="3.1415926535897917837 -1.5707963267948950037 0" />
<geometry>
<mesh filename="package:///right_forearm_pivot_v1.stl"/>
</geometry>
<material name="right_forearm_pivot_v1_material">
<color rgba="1 1 1 1.0"/>
</material>
</visual>
<collision>
<origin xyz="-0.021642932224072770897 -0.0074388637145610522414 -0.025649999999990850258" rpy="3.1415926535897917837 -1.5707963267948950037 0" />
<geometry>
<mesh filename="package:///right_forearm_pivot_v1.stl"/>
</geometry>
</collision>
<visual>
<origin xyz="-0.015642932224073015368 -0.0074388637145610617823 -0.02564999999999083985" rpy="-1.5707963267948981123 -1.570796326794896336 0" />
<geometry>
<mesh filename="package:///9g_servo_arm_v1.stl"/>
</geometry>
<material name="9g_servo_arm_v1_material">
<color rgba="0.62745098039215685404 0.62745098039215685404 0.62745098039215685404 1.0"/>
</material>
</visual>
<collision>
<origin xyz="-0.015642932224073015368 -0.0074388637145610617823 -0.02564999999999083985" rpy="-1.5707963267948981123 -1.570796326794896336 0" />
<geometry>
<mesh filename="package:///9g_servo_arm_v1.stl"/>
</geometry>
</collision>
<visual>
<origin xyz="-0.015642932224073015368 -0.0074388637145610617823 -0.02564999999999083985" rpy="-1.4821224591991386098e-15 -1.570796326794896336 0" />
<geometry>
<mesh filename="package:///9g_thigh_servo_attachment_v1.stl"/>
</geometry>
<material name="9g_thigh_servo_attachment_v1_material">
<color rgba="1 1 1 1.0"/>
</material>
</visual>
<collision>
<origin xyz="-0.015642932224073015368 -0.0074388637145610617823 -0.02564999999999083985" rpy="-1.4821224591991386098e-15 -1.570796326794896336 0" />
<geometry>
<mesh filename="package:///9g_thigh_servo_attachment_v1.stl"/>
</geometry>
</collision>
<visual>
<origin xyz="-0.024642932224072607028 -0.018555812535801022994 -0.039164960532352147138" rpy="1.5707963267948950037 0.68837531027909637515 1.5707963267948925612" />
<geometry>
<mesh filename="package:///right_forearm_linkage_v1.stl"/>
</geometry>
<material name="right_forearm_linkage_v1_material">
<color rgba="1 1 1 1.0"/>
</material>
</visual>
<collision>
<origin xyz="-0.024642932224072607028 -0.018555812535801022994 -0.039164960532352147138" rpy="1.5707963267948950037 0.68837531027909637515 1.5707963267948925612" />
<geometry>
<mesh filename="package:///right_forearm_linkage_v1.stl"/>
</geometry>
</collision>
<visual>
<origin xyz="-0.028642932224072450986 -0.0074450181671779887618 -0.025644596317651313644" rpy="-1.5707963267910707295 -1.570319910106017014 -1.5707963267966360554" />
<geometry>
<mesh filename="package:///right_cover_v2.stl"/>
</geometry>
<material name="right_cover_v2_material">
<color rgba="1 1 1 1.0"/>
</material>
</visual>
<collision>
<origin xyz="-0.028642932224072450986 -0.0074450181671779887618 -0.025644596317651313644" rpy="-1.5707963267910707295 -1.570319910106017014 -1.5707963267966360554" />
<geometry>
<mesh filename="package:///right_cover_v2.stl"/>
</geometry>
</collision>
<visual>
<origin xyz="-0.024642932224072620906 -0.018555812535801022994 -0.039164960532352147138" rpy="1.5707963267948943376 0.68837531027909637515 1.5707963267948925612" />
<geometry>
<mesh filename="package:///bearing_5x8x2.5_v1.stl"/>
</geometry>
<material name="bearing_5x8x2.5_v1_material">
<color rgba="0.62745098039215685404 0.62745098039215685404 0.62745098039215685404 1.0"/>
</material>
</visual>
<collision>
<origin xyz="-0.024642932224072620906 -0.018555812535801022994 -0.039164960532352147138" rpy="1.5707963267948943376 0.68837531027909637515 1.5707963267948925612" />
<geometry>
<mesh filename="package:///bearing_5x8x2.5_v1.stl"/>
</geometry>
</collision>
<visual>
<origin xyz="-0.019142932224072803371 -0.0061560981491680438413 -0.049365069312650243505" rpy="-3.141592653589793116 1.570796326794896336 0" />
<geometry>
<mesh filename="package:///bearing_5x8x2.5_v1.stl"/>
</geometry>
<material name="bearing_5x8x2.5_v1_material">
<color rgba="0.62745098039215685404 0.62745098039215685404 0.62745098039215685404 1.0"/>
</material>
</visual>
<collision>
<origin xyz="-0.019142932224072803371 -0.0061560981491680438413 -0.049365069312650243505" rpy="-3.141592653589793116 1.570796326794896336 0" />
<geometry>
<mesh filename="package:///bearing_5x8x2.5_v1.stl"/>
</geometry>
</collision>
<visual>
<origin xyz="-0.021642932224072888858 0.0049611362854388423721 -0.035849999999990750377" rpy="1.570796326794896558 -1.570796326794896336 0" />
<geometry>
<mesh filename="package:///right_forearm_servo_attachment_v1.stl"/>
</geometry>
<material name="right_forearm_servo_attachment_v1_material">
<color rgba="1 1 1 1.0"/>
</material>
</visual>
<collision>
<origin xyz="-0.021642932224072888858 0.0049611362854388423721 -0.035849999999990750377" rpy="1.570796326794896558 -1.570796326794896336 0" />
<geometry>
<mesh filename="package:///right_forearm_servo_attachment_v1.stl"/>
</geometry>
</collision>
<visual>
<origin xyz="-0.015642932224072932101 0.0049611362854387426255 -0.035849999999990750377" rpy="1.570796326794896558 1.570796326794896558 0" />
<geometry>
<mesh filename="package:///9g_servo_arm_v1.stl"/>
</geometry>
<material name="9g_servo_arm_v1_material">
<color rgba="0.62745098039215685404 0.62745098039215685404 0.62745098039215685404 1.0"/>
</material>
</visual>
<collision>
<origin xyz="-0.015642932224072932101 0.0049611362854387426255 -0.035849999999990750377" rpy="1.570796326794896558 1.570796326794896558 0" />
<geometry>
<mesh filename="package:///9g_servo_arm_v1.stl"/>
</geometry>
</collision>
<inertial>
<origin xyz="-0.0011710670974884431275 -0.0027608821607481332135 -0.028924196672178822259" rpy="0 0 0"/>
<mass value="0.035352377824358502401" />
<inertia ixx="8.7057396674940704372e-06" ixy="-1.5198144212103965765e-06"  ixz="-6.3174231461625426212e-07" iyy="1.1158355849914649899e-05" iyz="1.7209971524295926221e-07" izz="8.3016348716513262276e-06" />
</inertial>
</link>

<link name="rightthigh">
<visual>
<origin xyz="0.034999999999991301958 -3.3029134982598407078e-15 -0.0069999999999990347721" rpy="3.0314639687389874093e-13 -1.4543921622588651378e-14 -4.0973473680615598513e-13" />
<geometry>
<mesh filename="package:///bearing_5x8x2.5_v1.stl"/>
</geometry>
<material name="bearing_5x8x2.5_v1_material">
<color rgba="0.62745098039215685404 0.62745098039215685404 0.62745098039215685404 1.0"/>
</material>
</visual>
<collision>
<origin xyz="0.034999999999991301958 -3.3029134982598407078e-15 -0.0069999999999990347721" rpy="3.0314639687389874093e-13 -1.4543921622588651378e-14 -4.0973473680615598513e-13" />
<geometry>
<mesh filename="package:///bearing_5x8x2.5_v1.stl"/>
</geometry>
</collision>
<visual>
<origin xyz="1.7347234759768070944e-18 0 -0.0044999999999999970579" rpy="3.141592653589793116 2.6343351684384524882e-31 -4.970420016988152346e-18" />
<geometry>
<mesh filename="package:///left_thigh_v1.stl"/>
</geometry>
<material name="left_thigh_v1_material">
<color rgba="1 1 1 1.0"/>
</material>
</visual>
<collision>
<origin xyz="1.7347234759768070944e-18 0 -0.0044999999999999970579" rpy="3.141592653589793116 2.6343351684384524882e-31 -4.970420016988152346e-18" />
<geometry>
<mesh filename="package:///left_thigh_v1.stl"/>
</geometry>
</collision>
<inertial>
<origin xyz="0.013280795316697381614 0.00036090885672630627912 -0.0044952881914007937134" rpy="0 0 0"/>
<mass value="0.0018464874791640291558" />
<inertia ixx="2.9147245096330451357e-08" ixy="-3.1720402745964907743e-09"  ixz="1.429264085836885079e-08" iyy="3.5092222213974607173e-07" iyz="8.5226615733042806747e-10" izz="3.6712035000663572912e-07" />
</inertial>
</link>

<link name="rightfoot">
<visual>
<origin xyz="-1.561251128379126385e-16 1.7347234759768070944e-16 0.00049999999999988942179" rpy="1.570796326794896558 5.8854124290769399202e-31 4.7717822569229957945e-17" />
<geometry>
<mesh filename="package:///right_forearm_outside_v1.stl"/>
</geometry>
<material name="right_forearm_outside_v1_material">
<color rgba="1 1 1 1.0"/>
</material>
</visual>
<collision>
<origin xyz="-1.561251128379126385e-16 1.7347234759768070944e-16 0.00049999999999988942179" rpy="1.570796326794896558 5.8854124290769399202e-31 4.7717822569229957945e-17" />
<geometry>
<mesh filename="package:///right_forearm_outside_v1.stl"/>
</geometry>
</collision>
<visual>
<origin xyz="3.4694469519536141888e-18 -6.9388939039072283776e-18 -0.0030000000000000026645" rpy="1.570796326794896558 5.8854124290769399202e-31 4.7717822569229957945e-17" />
<geometry>
<mesh filename="package:///right_forearm_inside_v1.stl"/>
</geometry>
<material name="right_forearm_inside_v1_material">
<color rgba="1 1 1 1.0"/>
</material>
</visual>
<collision>
<origin xyz="3.4694469519536141888e-18 -6.9388939039072283776e-18 -0.0030000000000000026645" rpy="1.570796326794896558 5.8854124290769399202e-31 4.7717822569229957945e-17" />
<geometry>
<mesh filename="package:///right_forearm_inside_v1.stl"/>
</geometry>
</collision>
<inertial>
<origin xyz="-0.011456869649159765606 -0.00069736546686946954566 -0.0010708602591541836573" rpy="0 0 0"/>
<mass value="0.0052504289083666264015" />
<inertia ixx="1.4014220415309388369e-07" ixy="-4.0137945142805795185e-08"  ixz="-9.9504406391451954605e-09" iyy="2.2668296909327759389e-06" iyz="6.5923924208710627985e-09" izz="2.2964377908784525941e-06" />
</inertial>
</link>

<joint name="foot_frontright" type="revolute">
<origin xyz="0.034999999999991295019 -3.3098523921637479361e-15 -0.0069999999999990347721" rpy="3.141592653589793116 5.3157713190766779058e-16 1.773434614324501446" />
<parent link="rightthigh" />
<child link="rightfoot" />
<axis xyz="0 0 1"/>
<limit effort="1" velocity="20" lower="-1.0472" upper="0"/>
<joint_properties friction="0.0"/>
</joint>

<joint name="thigh_frontright" type="revolute">
<origin xyz="-0.017642932224072947756 -0.0074388637145610548435 -0.025649999999990853727" rpy="1.5707963267948954478 -0.63152345479824956165 1.5707963267948918951" />
<parent link="righthip" />
<child link="rightthigh" />
<axis xyz="0 0 1"/>
<limit effort="1" velocity="20" lower="-1.0472" upper="0"/>
<joint_properties friction="0.0"/>
</joint>

<link name="leftfemur_3">
<visual>
<origin xyz="0.035000000000010363099 7.4454331588924560492e-15 -3.8163916471489756077e-16" rpy="3.141592653589793116 -5.298083181472347112e-31 -5.7822084137496022933e-17" />
<geometry>
<mesh filename="package:///bearing_5x8x2.5_v1.stl"/>
</geometry>
<material name="bearing_5x8x2.5_v1_material">
<color rgba="0.62745098039215685404 0.62745098039215685404 0.62745098039215685404 1.0"/>
</material>
</visual>
<collision>
<origin xyz="0.035000000000010363099 7.4454331588924560492e-15 -3.8163916471489756077e-16" rpy="3.141592653589793116 -5.298083181472347112e-31 -5.7822084137496022933e-17" />
<geometry>
<mesh filename="package:///bearing_5x8x2.5_v1.stl"/>
</geometry>
</collision>
<visual>
<origin xyz="-5.3776427755281019927e-17 2.4286128663675299322e-16 -0.0024999999999997177258" rpy="1.3811174426336985228e-13 2.6423307986071364012e-14 2.0632644222753713332e-13" />
<geometry>
<mesh filename="package:///lever_v1.stl"/>
</geometry>
<material name="lever_v1_material">
<color rgba="1 1 1 1.0"/>
</material>
</visual>
<collision>
<origin xyz="-5.3776427755281019927e-17 2.4286128663675299322e-16 -0.0024999999999997177258" rpy="1.3811174426336985228e-13 2.6423307986071364012e-14 2.0632644222753713332e-13" />
<geometry>
<mesh filename="package:///lever_v1.stl"/>
</geometry>
</collision>
<visual>
<origin xyz="-6.9388939039072283776e-18 6.9388939039072283776e-18 0" rpy="3.141592653589793116 -5.298083181472347112e-31 -5.7822084137496022933e-17" />
<geometry>
<mesh filename="package:///bearing_5x8x2.5_v1.stl"/>
</geometry>
<material name="bearing_5x8x2.5_v1_material">
<color rgba="0.62745098039215685404 0.62745098039215685404 0.62745098039215685404 1.0"/>
</material>
</visual>
<collision>
<origin xyz="-6.9388939039072283776e-18 6.9388939039072283776e-18 0" rpy="3.141592653589793116 -5.298083181472347112e-31 -5.7822084137496022933e-17" />
<geometry>
<mesh filename="package:///bearing_5x8x2.5_v1.stl"/>
</geometry>
</collision>
<inertial>
<origin xyz="0.016745239433455703926 -0.0019623707901172851402 -0.00125000000000044173" rpy="0 0 0"/>
<mass value="0.0012188090534078449383" />
<inertia ixx="2.3153914212895976553e-08" ixy="-7.3509510903751010036e-09"  ixz="5.3044343046254749679e-21" iyy="2.7100368005617494698e-07" iyz="-2.7287586202821097261e-21" izz="2.9302349553648831349e-07" />
</inertial>
</link>

<joint name="femur_frontright" type="revolute">
<origin xyz="-0.024642932224072711112 -0.019813232385325504209 -0.013275631329226003641" rpy="-1.5707963267948983344 -0.68346821395421686329 1.570796326794891673" />
<parent link="righthip" />
<child link="leftfemur_3" />
<axis xyz="0 0 1"/>
<limit effort="1" velocity="20" />
<joint_properties friction="0.0"/>
</joint>

<joint name="frontrighthip" type="revolute">
<origin xyz="-0.036800000000001581446 0.056500000000000778766 -7.0476127562992511725e-05" rpy="-1.570796326794896558 -1.7106901340672024212e-16 9.1593124686582624559e-15" />
<parent link="chassis" />
<child link="righthip" />
<axis xyz="0 0 1"/>
<limit effort="1" velocity="20" lower="-0.261799" upper="0.261799"/>
<joint_properties friction="0.0"/>
</joint>

<link name="righthip_2">
<visual>
<origin xyz="0.015657067775926583608 0.0049611362854387972693 -0.030749999999990923483" rpy="1.570796326794896558 -1.570796326794896558 0" />
<geometry>
<mesh filename="package:///microservosg90.stl"/>
</geometry>
<material name="microservosg90_material">
<color rgba="0.35294117647058825815 0.35294117647058825815 0.35294117647058825815 1.0"/>
</material>
</visual>
<collision>
<origin xyz="0.015657067775926583608 0.0049611362854387972693 -0.030749999999990923483" rpy="1.570796326794896558 -1.570796326794896558 0" />
<geometry>
<mesh filename="package:///microservosg90.stl"/>
</geometry>
</collision>
<visual>
<origin xyz="0.0044749999999997638889 0.012124999999999946584 -0.029999999999991672217" rpy="-1.57079632679489678 1.3356066461656234727e-15 3.141592653589793116" />
<geometry>
<mesh filename="package:///hip_v2.stl"/>
</geometry>
<material name="hip_v2_material">
<color rgba="1 1 1 1.0"/>
</material>
</visual>
<collision>
<origin xyz="0.0044749999999997638889 0.012124999999999946584 -0.029999999999991672217" rpy="-1.57079632679489678 1.3356066461656234727e-15 3.141592653589793116" />
<geometry>
<mesh filename="package:///hip_v2.stl"/>
</geometry>
</collision>
<visual>
<origin xyz="0.0044750000000061199157 -0.012124999999999956993 -0.029999999999996140865" rpy="1.570796326794896336 3.3566038837307755185e-13 3.141592653589793116" />
<geometry>
<mesh filename="package:///hip_v2.stl"/>
</geometry>
<material name="hip_v2_material">
<color rgba="1 1 1 1.0"/>
</material>
</visual>
<collision>
<origin xyz="0.0044750000000061199157 -0.012124999999999956993 -0.029999999999996140865" rpy="1.570796326794896336 3.3566038837307755185e-13 3.141592653589793116" />
<geometry>
<mesh filename="package:///hip_v2.stl"/>
</geometry>
</collision>
<visual>
<origin xyz="0 0 -0.0014999999999999735767" rpy="-3.141592653589793116 -2.127942819740166194e-30 3.802887658476176292e-32" />
<geometry>
<mesh filename="package:///18g_thigh_servo_attachment_v3.stl"/>
</geometry>
<material name="18g_thigh_servo_attachment_v3_material">
<color rgba="1 1 1 1.0"/>
</material>
</visual>
<collision>
<origin xyz="0 0 -0.0014999999999999735767" rpy="-3.141592653589793116 -2.127942819740166194e-30 3.802887658476176292e-32" />
<geometry>
<mesh filename="package:///18g_thigh_servo_attachment_v3.stl"/>
</geometry>
</collision>
<visual>
<origin xyz="0.0038875000000004392153 3.6591823321385774648e-18 -0.050899999999989176125" rpy="3.141592653589793116 3.3699599501924295366e-13 3.141592653589793116" />
<geometry>
<mesh filename="package:///hip_joint_to_bearing_v3.stl"/>
</geometry>
<material name="hip_joint_to_bearing_v3_material">
<color rgba="1 1 1 1.0"/>
</material>
</visual>
<collision>
<origin xyz="0.0038875000000004392153 3.6591823321385774648e-18 -0.050899999999989176125" rpy="3.141592653589793116 3.3699599501924295366e-13 3.141592653589793116" />
<geometry>
<mesh filename="package:///hip_joint_to_bearing_v3.stl"/>
</geometry>
</collision>
<visual>
<origin xyz="0 0 -0.0014999999999999735767" rpy="1.570796326794896558 -5.5022100929803731063e-31 1.0510216525242782661e-33" />
<geometry>
<mesh filename="package:///9g_servo_arm_v1.stl"/>
</geometry>
<material name="9g_servo_arm_v1_material">
<color rgba="0.62745098039215685404 0.62745098039215685404 0.62745098039215685404 1.0"/>
</material>
</visual>
<collision>
<origin xyz="0 0 -0.0014999999999999735767" rpy="1.570796326794896558 -5.5022100929803731063e-31 1.0510216525242782661e-33" />
<geometry>
<mesh filename="package:///9g_servo_arm_v1.stl"/>
</geometry>
</collision>
<visual>
<origin xyz="0.015657067775926594017 -0.0074388637145611684678 -0.030749999999990909605" rpy="-1.57079632679489678 1.570796326794896336 0" />
<geometry>
<mesh filename="package:///microservosg90.stl"/>
</geometry>
<material name="microservosg90_material">
<color rgba="0.35294117647058825815 0.35294117647058825815 0.35294117647058825815 1.0"/>
</material>
</visual>
<collision>
<origin xyz="0.015657067775926594017 -0.0074388637145611684678 -0.030749999999990909605" rpy="-1.57079632679489678 1.570796326794896336 0" />
<geometry>
<mesh filename="package:///microservosg90.stl"/>
</geometry>
</collision>
<visual>
<origin xyz="0.0038874999999999743094 -3.8218126580114031299e-18 -0.009099999999999941469" rpy="-1.9988767292402708881e-16 2.127942819740166194e-30 3.141592653589793116" />
<geometry>
<mesh filename="package:///hip_joint_to_servo_v2.stl"/>
</geometry>
<material name="hip_joint_to_servo_v2_material">
<color rgba="1 1 1 1.0"/>
</material>
</visual>
<collision>
<origin xyz="0.0038874999999999743094 -3.8218126580114031299e-18 -0.009099999999999941469" rpy="-1.9988767292402708881e-16 2.127942819740166194e-30 3.141592653589793116" />
<geometry>
<mesh filename="package:///hip_joint_to_servo_v2.stl"/>
</geometry>
</collision>
<visual>
<origin xyz="-0.021642932224073367642 -0.0074388637145611719373 -0.025649999999990957811" rpy="-3.141592653589793116 -1.5707963267948956698 0" />
<geometry>
<mesh filename="package:///bearing_10x15x4_v1.stl"/>
</geometry>
<material name="bearing_10x15x4_v1_material">
<color rgba="0.62745098039215685404 0.62745098039215685404 0.62745098039215685404 1.0"/>
</material>
</visual>
<collision>
<origin xyz="-0.021642932224073367642 -0.0074388637145611719373 -0.025649999999990957811" rpy="-3.141592653589793116 -1.5707963267948956698 0" />
<geometry>
<mesh filename="package:///bearing_10x15x4_v1.stl"/>
</geometry>
</collision>
<visual>
<origin xyz="-0.021642932224073367642 -0.0074388637145611719373 -0.025649999999990957811" rpy="-3.141592653589793116 -1.5707963267948956698 0" />
<geometry>
<mesh filename="package:///right_forearm_pivot_v1.stl"/>
</geometry>
<material name="right_forearm_pivot_v1_material">
<color rgba="1 1 1 1.0"/>
</material>
</visual>
<collision>
<origin xyz="-0.021642932224073367642 -0.0074388637145611719373 -0.025649999999990957811" rpy="-3.141592653589793116 -1.5707963267948956698 0" />
<geometry>
<mesh filename="package:///right_forearm_pivot_v1.stl"/>
</geometry>
</collision>
<visual>
<origin xyz="-0.015642932224073369252 -0.0074388637145611702026 -0.025649999999990957811" rpy="-1.570796326794896558 -1.5707963267948956698 0" />
<geometry>
<mesh filename="package:///9g_servo_arm_v1.stl"/>
</geometry>
<material name="9g_servo_arm_v1_material">
<color rgba="0.62745098039215685404 0.62745098039215685404 0.62745098039215685404 1.0"/>
</material>
</visual>
<collision>
<origin xyz="-0.015642932224073369252 -0.0074388637145611702026 -0.025649999999990957811" rpy="-1.570796326794896558 -1.5707963267948956698 0" />
<geometry>
<mesh filename="package:///9g_servo_arm_v1.stl"/>
</geometry>
</collision>
<visual>
<origin xyz="-0.015642932224073369252 -0.0074388637145611702026 -0.025649999999990957811" rpy="1.2943564998328542606e-16 -1.5707963267948956698 0" />
<geometry>
<mesh filename="package:///9g_thigh_servo_attachment_v1.stl"/>
</geometry>
<material name="9g_thigh_servo_attachment_v1_material">
<color rgba="1 1 1 1.0"/>
</material>
</visual>
<collision>
<origin xyz="-0.015642932224073369252 -0.0074388637145611702026 -0.025649999999990957811" rpy="1.2943564998328542606e-16 -1.5707963267948956698 0" />
<geometry>
<mesh filename="package:///9g_thigh_servo_attachment_v1.stl"/>
</geometry>
</collision>
<visual>
<origin xyz="-0.02464293222407328704 -0.018555812535806862074 -0.039164960532358475409" rpy="1.5707963267948987784 0.68837531027923459792 1.5707963267949005548" />
<geometry>
<mesh filename="package:///right_forearm_linkage_v1.stl"/>
</geometry>
<material name="right_forearm_linkage_v1_material">
<color rgba="1 1 1 1.0"/>
</material>
</visual>
<collision>
<origin xyz="-0.02464293222407328704 -0.018555812535806862074 -0.039164960532358475409" rpy="1.5707963267948987784 0.68837531027923459792 1.5707963267949005548" />
<geometry>
<mesh filename="package:///right_forearm_linkage_v1.stl"/>
</geometry>
</collision>
<visual>
<origin xyz="-0.028642932224073235081 -0.0078107477265611418085 -0.025352155522328417847" rpy="-1.57079632679495651 -1.5435606468479745601 -1.5707963267947400166" />
<geometry>
<mesh filename="package:///right_cover_v2.stl"/>
</geometry>
<material name="right_cover_v2_material">
<color rgba="1 1 1 1.0"/>
</material>
</visual>
<collision>
<origin xyz="-0.028642932224073235081 -0.0078107477265611418085 -0.025352155522328417847" rpy="-1.57079632679495651 -1.5435606468479745601 -1.5707963267947400166" />
<geometry>
<mesh filename="package:///right_cover_v2.stl"/>
</geometry>
</collision>
<visual>
<origin xyz="-0.024642932224073280101 -0.018555812535806862074 -0.039164960532358475409" rpy="1.5707963267948987784 0.68837531027923459792 1.5707963267949005548" />
<geometry>
<mesh filename="package:///bearing_5x8x2.5_v1.stl"/>
</geometry>
<material name="bearing_5x8x2.5_v1_material">
<color rgba="0.62745098039215685404 0.62745098039215685404 0.62745098039215685404 1.0"/>
</material>
</visual>
<collision>
<origin xyz="-0.024642932224073280101 -0.018555812535806862074 -0.039164960532358475409" rpy="1.5707963267948987784 0.68837531027923459792 1.5707963267949005548" />
<geometry>
<mesh filename="package:///bearing_5x8x2.5_v1.stl"/>
</geometry>
</collision>
<visual>
<origin xyz="-0.019142932224073351544 -0.0061560981491748777844 -0.04936506931265861875" rpy="3.1415926535897926719 1.570796326794747344 0" />
<geometry>
<mesh filename="package:///bearing_5x8x2.5_v1.stl"/>
</geometry>
<material name="bearing_5x8x2.5_v1_material">
<color rgba="0.62745098039215685404 0.62745098039215685404 0.62745098039215685404 1.0"/>
</material>
</visual>
<collision>
<origin xyz="-0.019142932224073351544 -0.0061560981491748777844 -0.04936506931265861875" rpy="3.1415926535897926719 1.570796326794747344 0" />
<geometry>
<mesh filename="package:///bearing_5x8x2.5_v1.stl"/>
</geometry>
</collision>
<visual>
<origin xyz="-0.021642932224073402336 0.0049611362854387981366 -0.035849999999991152833" rpy="1.5707963267948998887 -1.5707963267948898967 0" />
<geometry>
<mesh filename="package:///right_forearm_servo_attachment_v1.stl"/>
</geometry>
<material name="right_forearm_servo_attachment_v1_material">
<color rgba="1 1 1 1.0"/>
</material>
</visual>
<collision>
<origin xyz="-0.021642932224073402336 0.0049611362854387981366 -0.035849999999991152833" rpy="1.5707963267948998887 -1.5707963267948898967 0" />
<geometry>
<mesh filename="package:///right_forearm_servo_attachment_v1.stl"/>
</geometry>
</collision>
<visual>
<origin xyz="-0.015642932224073355374 0.0049611362854387981366 -0.035849999999990958544" rpy="1.570796326794896558 1.5707963267948954478 0" />
<geometry>
<mesh filename="package:///9g_servo_arm_v1.stl"/>
</geometry>
<material name="9g_servo_arm_v1_material">
<color rgba="0.62745098039215685404 0.62745098039215685404 0.62745098039215685404 1.0"/>
</material>
</visual>
<collision>
<origin xyz="-0.015642932224073355374 0.0049611362854387981366 -0.035849999999990958544" rpy="1.570796326794896558 1.5707963267948954478 0" />
<geometry>
<mesh filename="package:///9g_servo_arm_v1.stl"/>
</geometry>
</collision>
<inertial>
<origin xyz="-0.0011710670974884795567 -0.0027751546053958056973 -0.028924859847319225881" rpy="0 0 0"/>
<mass value="0.035352377824358502401" />
<inertia ixx="8.7221517697940916523e-06" ixy="-1.5327589570214113487e-06"  ixz="-6.3234324719324679081e-07" iyy="1.1158273187212561011e-05" iyz="1.7742325608328413287e-07" izz="8.318129636653771755e-06" />
</inertial>
</link>

<link name="rightthigh_2">
<visual>
<origin xyz="0.034999999999997297162 5.2458037913538646535e-15 -0.0069999999999999923395" rpy="-1.6653345369377251964e-16 1.1102230246251490462e-15 3.5149683797554561726e-15" />
<geometry>
<mesh filename="package:///bearing_5x8x2.5_v1.stl"/>
</geometry>
<material name="bearing_5x8x2.5_v1_material">
<color rgba="0.62745098039215685404 0.62745098039215685404 0.62745098039215685404 1.0"/>
</material>
</visual>
<collision>
<origin xyz="0.034999999999997297162 5.2458037913538646535e-15 -0.0069999999999999923395" rpy="-1.6653345369377251964e-16 1.1102230246251490462e-15 3.5149683797554561726e-15" />
<geometry>
<mesh filename="package:///bearing_5x8x2.5_v1.stl"/>
</geometry>
</collision>
<visual>
<origin xyz="-1.3877787807814456755e-17 0 -0.0044999999999999970579" rpy="3.141592653589793116 -3.0067787733014283374e-31 5.1787811654151683233e-18" />
<geometry>
<mesh filename="package:///left_thigh_v1.stl"/>
</geometry>
<material name="left_thigh_v1_material">
<color rgba="1 1 1 1.0"/>
</material>
</visual>
<collision>
<origin xyz="-1.3877787807814456755e-17 0 -0.0044999999999999970579" rpy="3.141592653589793116 -3.0067787733014283374e-31 5.1787811654151683233e-18" />
<geometry>
<mesh filename="package:///left_thigh_v1.stl"/>
</geometry>
</collision>
<inertial>
<origin xyz="0.013280795316697638353 0.00036090885672670765076 -0.0044952881914008353467" rpy="0 0 0"/>
<mass value="0.0018464874791640291558" />
<inertia ixx="2.9147245096330113867e-08" ixy="-3.1720402746123387277e-09"  ixz="1.4292640858371211563e-08" iyy="3.5092222213976820047e-07" iyz="8.5226615733145883791e-10" izz="3.6712035000665690494e-07" />
</inertial>
</link>

<link name="rightfoot_2">
<visual>
<origin xyz="1.1102230246251565404e-16 4.1633363423443370266e-17 0.00050000000000002126077" rpy="1.570796326794896558 -3.9586185168284505047e-31 -5.8107756656542900288e-18" />
<geometry>
<mesh filename="package:///right_forearm_outside_v1.stl"/>
</geometry>
<material name="right_forearm_outside_v1_material">
<color rgba="1 1 1 1.0"/>
</material>
</visual>
<collision>
<origin xyz="1.1102230246251565404e-16 4.1633363423443370266e-17 0.00050000000000002126077" rpy="1.570796326794896558 -3.9586185168284505047e-31 -5.8107756656542900288e-18" />
<geometry>
<mesh filename="package:///right_forearm_outside_v1.stl"/>
</geometry>
</collision>
<visual>
<origin xyz="2.7755575615628913511e-17 -2.7755575615628913511e-17 -0.0030000000000000096034" rpy="1.570796326794896558 -3.9586185168284505047e-31 -5.8107756656542900288e-18" />
<geometry>
<mesh filename="package:///right_forearm_inside_v1.stl"/>
</geometry>
<material name="right_forearm_inside_v1_material">
<color rgba="1 1 1 1.0"/>
</material>
</visual>
<collision>
<origin xyz="2.7755575615628913511e-17 -2.7755575615628913511e-17 -0.0030000000000000096034" rpy="1.570796326794896558 -3.9586185168284505047e-31 -5.8107756656542900288e-18" />
<geometry>
<mesh filename="package:///right_forearm_inside_v1.stl"/>
</geometry>
</collision>
<inertial>
<origin xyz="-0.011456869649159625094 -0.00069736546686954316299 -0.0010708602591541235925" rpy="0 0 0"/>
<mass value="0.0052504289083666264015" />
<inertia ixx="1.4014220415309637185e-07" ixy="-4.0137945142805001092e-08"  ixz="-9.9504406391477547573e-09" iyy="2.2668296909327797505e-06" iyz="6.5923924208721100091e-09" izz="2.2964377908784551352e-06" />
</inertial>
</link>

<joint name="foot_backright" type="revolute">
<origin xyz="0.034999999999997297162 5.2458037913538646535e-15 -0.0069999999999999923395" rpy="-3.141592653589793116 2.2441480830048960661e-16 1.4414733445528478128" />
<parent link="rightthigh_2" />
<child link="rightfoot_2" />
<axis xyz="0 0 1"/>
<limit effort="1" velocity="20" lower="-1.0472" upper="0"/>
<joint_properties friction="0.0"/>
</joint>

<joint name="thigh_backright" type="revolute">
<origin xyz="-0.017642932224073377967 -0.0074388637145611710699 -0.025649999999990985566" rpy="1.5707963267948950037 -0.76963751995166607145 1.5707963267948952257" />
<parent link="righthip_2" />
<child link="rightthigh_2" />
<axis xyz="0 0 1"/>
<limit effort="1" velocity="20" lower="-1.0472" upper="0"/>
<joint_properties friction="0.0"/>
</joint>

<link name="leftfemur_4">
<visual>
<origin xyz="0.035000000000007427947 -3.7608804959177177807e-15 -6.9388939039072283776e-18" rpy="-3.141592653589793116 -1.2311024387039410825e-31 8.2224073647639481264e-17" />
<geometry>
<mesh filename="package:///bearing_5x8x2.5_v1.stl"/>
</geometry>
<material name="bearing_5x8x2.5_v1_material">
<color rgba="0.62745098039215685404 0.62745098039215685404 0.62745098039215685404 1.0"/>
</material>
</visual>
<collision>
<origin xyz="0.035000000000007427947 -3.7608804959177177807e-15 -6.9388939039072283776e-18" rpy="-3.141592653589793116 -1.2311024387039410825e-31 8.2224073647639481264e-17" />
<geometry>
<mesh filename="package:///bearing_5x8x2.5_v1.stl"/>
</geometry>
</collision>
<visual>
<origin xyz="0 -1.3877787807814456755e-17 -0.0025000000000000022204" rpy="-2.6449001541149107017e-30 -1.2311024387039410825e-31 8.2224073647639481264e-17" />
<geometry>
<mesh filename="package:///lever_v1.stl"/>
</geometry>
<material name="lever_v1_material">
<color rgba="1 1 1 1.0"/>
</material>
</visual>
<collision>
<origin xyz="0 -1.3877787807814456755e-17 -0.0025000000000000022204" rpy="-2.6449001541149107017e-30 -1.2311024387039410825e-31 8.2224073647639481264e-17" />
<geometry>
<mesh filename="package:///lever_v1.stl"/>
</geometry>
</collision>
<visual>
<origin xyz="0 0 0" rpy="-3.141592653589793116 -1.2311024387039410825e-31 8.2224073647639481264e-17" />
<geometry>
<mesh filename="package:///bearing_5x8x2.5_v1.stl"/>
</geometry>
<material name="bearing_5x8x2.5_v1_material">
<color rgba="0.62745098039215685404 0.62745098039215685404 0.62745098039215685404 1.0"/>
</material>
</visual>
<collision>
<origin xyz="0 0 0" rpy="-3.141592653589793116 -1.2311024387039410825e-31 8.2224073647639481264e-17" />
<geometry>
<mesh filename="package:///bearing_5x8x2.5_v1.stl"/>
</geometry>
</collision>
<inertial>
<origin xyz="0.016745239433455127998 -0.0019623707901210867867 -0.0012500000000000115186" rpy="0 0 0"/>
<mass value="0.0012188090534078449383" />
<inertia ixx="2.3153914212891741388e-08" ixy="-7.350951090317529233e-09"  ixz="1.1524011100072402002e-22" iyy="2.710036800561697589e-07" iyz="-3.1064231574327919494e-24" izz="2.9302349553647814909e-07" />
</inertial>
</link>

<joint name="femur_backright" type="revolute">
<origin xyz="-0.024642932224073370306 -0.019813232385326069729 -0.013275631329226017519" rpy="-1.5707963267948983344 -0.69825389664490655761 1.5707963267948947816" />
<parent link="righthip_2" />
<child link="leftfemur_4" />
<axis xyz="0 0 1"/>
<limit effort="1" velocity="20" />
<joint_properties friction="0.0"/>
</joint>

<joint name="backrighthip" type="revolute">
<origin xyz="-0.036800000000002490441 0.15150000000000204969 -7.0476127562969092958e-05" rpy="-1.570796326794896558 1.0648674274956146044e-16 7.5640658693905968835e-15" />
<parent link="chassis" />
<child link="righthip_2" />
<axis xyz="0 0 1"/>
<limit effort="1" velocity="20" lower="-0.261799" upper="0.261799"/>
<joint_properties friction="0.0"/>
</joint>


</robot>
