<robot name="onshape">
<link name="chassis">
<visual>
<origin xyz="-0.013000000000000330735 0.011010500000000270071 -0.01647047612756320431" rpy="-3.6058330253460787669e-31 1.0648674274956316142e-16 -3.7192471324941710696e-15" />
<geometry>
<mesh filename="package:///battery.stl"/>
</geometry>
<material name="battery_material">
<color rgba="0.61568627450980395466 0.81176470588235294379 0.92941176470588238168 1.0"/>
</material>
</visual>
<collision>
<origin xyz="-0.013000000000000330735 0.011010500000000270071 -0.01647047612756320431" rpy="-3.6058330253460787669e-31 1.0648674274956316142e-16 -3.7192471324941710696e-15" />
<geometry>
<mesh filename="package:///battery.stl"/>
</geometry>
</collision>
<visual>
<origin xyz="-0.0049999999999996679045 0.0040000000000000538597 0.016470476127563242474" rpy="1.0648674274956600871e-16 -0 1.57079632679490655" />
<geometry>
<mesh filename="package:///top_body_v21.stl"/>
</geometry>
<material name="top_body_v21_material">
<color rgba="1 1 1 1.0"/>
</material>
</visual>
<collision>
<origin xyz="-0.0049999999999996679045 0.0040000000000000538597 0.016470476127563242474" rpy="1.0648674274956600871e-16 -0 1.57079632679490655" />
<geometry>
<mesh filename="package:///top_body_v21.stl"/>
</geometry>
</collision>
<visual>
<origin xyz="0.031900000000000316991 0.078250000000000971556 0.0056045238724370940661" rpy="3.141592653589793116 1.0648674274956318607e-16 -1.665334536937687479e-16" />
<geometry>
<mesh filename="package:///18g_servo_v1.stl"/>
</geometry>
<material name="18g_servo_v1_material">
<color rgba="0.62745098039215685404 0.62745098039215685404 0.62745098039215685404 1.0"/>
</material>
</visual>
<collision>
<origin xyz="0.031900000000000316991 0.078250000000000971556 0.0056045238724370940661" rpy="3.141592653589793116 1.0648674274956318607e-16 -1.665334536937687479e-16" />
<geometry>
<mesh filename="package:///18g_servo_v1.stl"/>
</geometry>
</collision>
<visual>
<origin xyz="-0.011350000000001572373 0.16440000000000226654 -0.0061454761275630542805" rpy="-1.7733605042685602097e-32 -1.0648674274956318607e-16 3.141592653589793116" />
<geometry>
<mesh filename="package:///bottom_hip_servo_v12.stl"/>
</geometry>
<material name="bottom_hip_servo_v12_material">
<color rgba="1 1 1 1.0"/>
</material>
</visual>
<collision>
<origin xyz="-0.011350000000001572373 0.16440000000000226654 -0.0061454761275630542805" rpy="-1.7733605042685602097e-32 -1.0648674274956318607e-16 3.141592653589793116" />
<geometry>
<mesh filename="package:///bottom_hip_servo_v12.stl"/>
</geometry>
</collision>
<visual>
<origin xyz="-0.011350000000000578376 0.069404000000000909409 0.0056754761275630769002" rpy="-6.1629758220391574667e-33 -5.0975591518307146312e-17 -3.141592653589793116" />
<geometry>
<mesh filename="package:///top_hip_servo_v14.stl"/>
</geometry>
<material name="top_hip_servo_v14_material">
<color rgba="1 1 1 1.0"/>
</material>
</visual>
<collision>
<origin xyz="-0.011350000000000578376 0.069404000000000909409 0.0056754761275630769002" rpy="-6.1629758220391574667e-33 -5.0975591518307146312e-17 -3.141592653589793116" />
<geometry>
<mesh filename="package:///top_hip_servo_v14.stl"/>
</geometry>
</collision>
<visual>
<origin xyz="-0.037000000000001947997 0.14800000000001331535 2.7403080422438690135e-17" rpy="1.570796326794896558 2.1297348549912632284e-16 1.9721522630524478441e-31" />
<geometry>
<mesh filename="package:///bearing_10x15x4_v1.stl"/>
</geometry>
<material name="bearing_10x15x4_v1_material">
<color rgba="0.62745098039215685404 0.62745098039215685404 0.62745098039215685404 1.0"/>
</material>
</visual>
<collision>
<origin xyz="-0.037000000000001947997 0.14800000000001331535 2.7403080422438690135e-17" rpy="1.570796326794896558 2.1297348549912632284e-16 1.9721522630524478441e-31" />
<geometry>
<mesh filename="package:///bearing_10x15x4_v1.stl"/>
</geometry>
</collision>
<visual>
<origin xyz="-0.037000000000000844713 0.053000000000011968093 2.7403080422438690135e-17" rpy="1.570796326794896558 2.1297348549912632284e-16 1.9721522630524517853e-31" />
<geometry>
<mesh filename="package:///bearing_10x15x4_v1.stl"/>
</geometry>
<material name="bearing_10x15x4_v1_material">
<color rgba="0.62745098039215685404 0.62745098039215685404 0.62745098039215685404 1.0"/>
</material>
</visual>
<collision>
<origin xyz="-0.037000000000000844713 0.053000000000011968093 2.7403080422438690135e-17" rpy="1.570796326794896558 2.1297348549912632284e-16 1.9721522630524517853e-31" />
<geometry>
<mesh filename="package:///bearing_10x15x4_v1.stl"/>
</geometry>
</collision>
<visual>
<origin xyz="0.037000000000001545541 1.7347234759768009314e-18 1.6994739566577847568e-17" rpy="-1.570796326794896558 2.8515549047850972074e-75 1.9721522630524520042e-31" />
<geometry>
<mesh filename="package:///bearing_10x15x4_v1.stl"/>
</geometry>
<material name="bearing_10x15x4_v1_material">
<color rgba="0.62745098039215685404 0.62745098039215685404 0.62745098039215685404 1.0"/>
</material>
</visual>
<collision>
<origin xyz="0.037000000000001545541 1.7347234759768009314e-18 1.6994739566577847568e-17" rpy="-1.570796326794896558 2.8515549047850972074e-75 1.9721522630524520042e-31" />
<geometry>
<mesh filename="package:///bearing_10x15x4_v1.stl"/>
</geometry>
</collision>
<visual>
<origin xyz="-0.037000000000001448397 0.0040000000000000538597 2.0464186518531461757e-17" rpy="1.570796326794896558 2.8515549047850972074e-75 1.9721522630524520042e-31" />
<geometry>
<mesh filename="package:///bearing_10x15x4_v1.stl"/>
</geometry>
<material name="bearing_10x15x4_v1_material">
<color rgba="0.62745098039215685404 0.62745098039215685404 0.62745098039215685404 1.0"/>
</material>
</visual>
<collision>
<origin xyz="-0.037000000000001448397 0.0040000000000000538597 2.0464186518531461757e-17" rpy="1.570796326794896558 2.8515549047850972074e-75 1.9721522630524520042e-31" />
<geometry>
<mesh filename="package:///bearing_10x15x4_v1.stl"/>
</geometry>
</collision>
<visual>
<origin xyz="0.037000000000001073697 0.14800000000001328759 1.005584566267061919e-17" rpy="1.570796326794896558 2.1297348549912632284e-16 1.9721522630524478441e-31" />
<geometry>
<mesh filename="package:///bearing_10x15x4_v1.stl"/>
</geometry>
<material name="bearing_10x15x4_v1_material">
<color rgba="0.62745098039215685404 0.62745098039215685404 0.62745098039215685404 1.0"/>
</material>
</visual>
<collision>
<origin xyz="0.037000000000001073697 0.14800000000001328759 1.005584566267061919e-17" rpy="1.570796326794896558 2.1297348549912632284e-16 1.9721522630524478441e-31" />
<geometry>
<mesh filename="package:///bearing_10x15x4_v1.stl"/>
</geometry>
</collision>
<visual>
<origin xyz="-0.037000000000002357392 0.095000000000001263989 2.0464186518531461757e-17" rpy="0 2.8515549047850972074e-75 1.9721522630524520042e-31" />
<geometry>
<mesh filename="package:///hip_cage_v4.stl"/>
</geometry>
<material name="hip_cage_v4_material">
<color rgba="1 1 1 1.0"/>
</material>
</visual>
<collision>
<origin xyz="-0.037000000000002357392 0.095000000000001263989 2.0464186518531461757e-17" rpy="0 2.8515549047850972074e-75 1.9721522630524520042e-31" />
<geometry>
<mesh filename="package:///hip_cage_v4.stl"/>
</geometry>
</collision>
<visual>
<origin xyz="-0.031900000000002495804 0.17325000000000242983 -0.0061454761275630525458" rpy="-1.7733605042685675994e-32 -1.0648674274956321072e-16 3.141592653589793116" />
<geometry>
<mesh filename="package:///18g_servo_v1.stl"/>
</geometry>
<material name="18g_servo_v1_material">
<color rgba="0.62745098039215685404 0.62745098039215685404 0.62745098039215685404 1.0"/>
</material>
</visual>
<collision>
<origin xyz="-0.031900000000002495804 0.17325000000000242983 -0.0061454761275630525458" rpy="-1.7733605042685675994e-32 -1.0648674274956321072e-16 3.141592653589793116" />
<geometry>
<mesh filename="package:///18g_servo_v1.stl"/>
</geometry>
</collision>
<visual>
<origin xyz="-0.03190000000000157987 0.078250000000001110334 -0.0061454761275630664236" rpy="-1.1102230246251582661e-16 1.7106901340671706202e-16 3.141592653589793116" />
<geometry>
<mesh filename="package:///18g_servo_v1.stl"/>
</geometry>
<material name="18g_servo_v1_material">
<color rgba="0.62745098039215685404 0.62745098039215685404 0.62745098039215685404 1.0"/>
</material>
</visual>
<collision>
<origin xyz="-0.03190000000000157987 0.078250000000001110334 -0.0061454761275630664236" rpy="-1.1102230246251582661e-16 1.7106901340671706202e-16 3.141592653589793116" />
<geometry>
<mesh filename="package:///18g_servo_v1.stl"/>
</geometry>
</collision>
<visual>
<origin xyz="-0.037000000000002392087 0.099000000000001323053 2.7403080422438690135e-17" rpy="1.570796326794896558 2.8515549047850972074e-75 1.9721522630524520042e-31" />
<geometry>
<mesh filename="package:///bearing_10x15x4_v1.stl"/>
</geometry>
<material name="bearing_10x15x4_v1_material">
<color rgba="0.62745098039215685404 0.62745098039215685404 0.62745098039215685404 1.0"/>
</material>
</visual>
<collision>
<origin xyz="-0.037000000000002392087 0.099000000000001323053 2.7403080422438690135e-17" rpy="1.570796326794896558 2.8515549047850972074e-75 1.9721522630524520042e-31" />
<geometry>
<mesh filename="package:///bearing_10x15x4_v1.stl"/>
</geometry>
</collision>
<visual>
<origin xyz="0.037000000000002031264 0.053000000000011961154 1.005584566267061919e-17" rpy="-9.4423431678150758974e-47 -2.1297348549912632284e-16 -3.141592653589793116" />
<geometry>
<mesh filename="package:///hip_cage_v4.stl"/>
</geometry>
<material name="hip_cage_v4_material">
<color rgba="1 1 1 1.0"/>
</material>
</visual>
<collision>
<origin xyz="0.037000000000002031264 0.053000000000011961154 1.005584566267061919e-17" rpy="-9.4423431678150758974e-47 -2.1297348549912632284e-16 -3.141592653589793116" />
<geometry>
<mesh filename="package:///hip_cage_v4.stl"/>
</geometry>
</collision>
<visual>
<origin xyz="-0.011350000000001522066 0.16440400000000221503 0.0056754761275631046558" rpy="2.7369110631418401047e-48 -1.0648674274956316142e-16 -3.141592653589793116" />
<geometry>
<mesh filename="package:///top_hip_servo_v14.stl"/>
</geometry>
<material name="top_hip_servo_v14_material">
<color rgba="1 1 1 1.0"/>
</material>
</visual>
<collision>
<origin xyz="-0.011350000000001522066 0.16440400000000221503 0.0056754761275631046558" rpy="2.7369110631418401047e-48 -1.0648674274956316142e-16 -3.141592653589793116" />
<geometry>
<mesh filename="package:///top_hip_servo_v14.stl"/>
</geometry>
</collision>
<visual>
<origin xyz="-0.011350000000000606132 0.06940000000000096092 -0.0061454761275630681583" rpy="-1.7733605042685684204e-32 -1.0648674274956318607e-16 3.141592653589793116" />
<geometry>
<mesh filename="package:///bottom_hip_servo_v12.stl"/>
</geometry>
<material name="bottom_hip_servo_v12_material">
<color rgba="1 1 1 1.0"/>
</material>
</visual>
<collision>
<origin xyz="-0.011350000000000606132 0.06940000000000096092 -0.0061454761275630681583" rpy="-1.7733605042685684204e-32 -1.0648674274956318607e-16 3.141592653589793116" />
<geometry>
<mesh filename="package:///bottom_hip_servo_v12.stl"/>
</geometry>
</collision>
<visual>
<origin xyz="0.037000000000002072897 0.04900000000001190209 1.005584566267061919e-17" rpy="-1.570796326794896558 2.1297348549912632284e-16 1.9721522630524517853e-31" />
<geometry>
<mesh filename="package:///bearing_10x15x4_v1.stl"/>
</geometry>
<material name="bearing_10x15x4_v1_material">
<color rgba="0.62745098039215685404 0.62745098039215685404 0.62745098039215685404 1.0"/>
</material>
</visual>
<collision>
<origin xyz="0.037000000000002072897 0.04900000000001190209 1.005584566267061919e-17" rpy="-1.570796326794896558 2.1297348549912632284e-16 1.9721522630524517853e-31" />
<geometry>
<mesh filename="package:///bearing_10x15x4_v1.stl"/>
</geometry>
</collision>
<visual>
<origin xyz="-0.037000000000001406764 -6.1629758220391547298e-33 2.0464186518531461757e-17" rpy="0 2.8515549047850972074e-75 1.9721522630524520042e-31" />
<geometry>
<mesh filename="package:///hip_cage_v4.stl"/>
</geometry>
<material name="hip_cage_v4_material">
<color rgba="1 1 1 1.0"/>
</material>
</visual>
<collision>
<origin xyz="-0.037000000000001406764 -6.1629758220391547298e-33 2.0464186518531461757e-17" rpy="0 2.8515549047850972074e-75 1.9721522630524520042e-31" />
<geometry>
<mesh filename="package:///hip_cage_v4.stl"/>
</geometry>
</collision>
<visual>
<origin xyz="0.031900000000000108824 0.17325000000000240208 0.0056045238724371053418" rpy="3.141592653589793116 1.0648674274956321072e-16 -1.6653345369376872325e-16" />
<geometry>
<mesh filename="package:///18g_servo_v1.stl"/>
</geometry>
<material name="18g_servo_v1_material">
<color rgba="0.62745098039215685404 0.62745098039215685404 0.62745098039215685404 1.0"/>
</material>
</visual>
<collision>
<origin xyz="0.031900000000000108824 0.17325000000000240208 0.0056045238724371053418" rpy="3.141592653589793116 1.0648674274956321072e-16 -1.6653345369376872325e-16" />
<geometry>
<mesh filename="package:///18g_servo_v1.stl"/>
</geometry>
</collision>
<visual>
<origin xyz="0.037000000000000601852 0.095000000000001277867 1.6994739566577847568e-17" rpy="-1.570796326794896558 2.8515549047850972074e-75 1.9721522630524520042e-31" />
<geometry>
<mesh filename="package:///bearing_10x15x4_v1.stl"/>
</geometry>
<material name="bearing_10x15x4_v1_material">
<color rgba="0.62745098039215685404 0.62745098039215685404 0.62745098039215685404 1.0"/>
</material>
</visual>
<collision>
<origin xyz="0.037000000000000601852 0.095000000000001277867 1.6994739566577847568e-17" rpy="-1.570796326794896558 2.8515549047850972074e-75 1.9721522630524520042e-31" />
<geometry>
<mesh filename="package:///bearing_10x15x4_v1.stl"/>
</geometry>
</collision>
<visual>
<origin xyz="0.0050000000000007330248 0.0040000000000000573291 -0.01647047612756320431" rpy="-3.141592653589793116 -1.773360504268559936e-32 1.5707963267949067721" />
<geometry>
<mesh filename="package:///bottom_body_v3.stl"/>
</geometry>
<material name="bottom_body_v3_material">
<color rgba="1 1 1 1.0"/>
</material>
</visual>
<collision>
<origin xyz="0.0050000000000007330248 0.0040000000000000573291 -0.01647047612756320431" rpy="-3.141592653589793116 -1.773360504268559936e-32 1.5707963267949067721" />
<geometry>
<mesh filename="package:///bottom_body_v3.stl"/>
</geometry>
</collision>
<visual>
<origin xyz="0.037000000000001073697 0.14800000000001328759 1.005584566267061919e-17" rpy="5.4738221262836802094e-48 -2.1297348549912632284e-16 -3.141592653589793116" />
<geometry>
<mesh filename="package:///hip_cage_v4.stl"/>
</geometry>
<material name="hip_cage_v4_material">
<color rgba="1 1 1 1.0"/>
</material>
</visual>
<collision>
<origin xyz="0.037000000000001073697 0.14800000000001328759 1.005584566267061919e-17" rpy="5.4738221262836802094e-48 -2.1297348549912632284e-16 -3.141592653589793116" />
<geometry>
<mesh filename="package:///hip_cage_v4.stl"/>
</geometry>
</collision>
<inertial>
<origin xyz="-2.0823268732730611485e-05 0.059718744592301975516 -0.00076328326978397913628" rpy="0 0 0"/>
<mass value="0.31717023469841981731" />
<inertia ixx="0.00093061101649678790171" ixy="4.0629875381688456458e-07"  ixz="2.9439233637508856385e-07" iyy="0.00013732595054241216012" iyz="-9.2656366584959357307e-06" izz="0.001014395765821176406" />
</inertial>
</link>

<link name="lefthip">
<visual>
<origin xyz="0.01565000000000612429 0.0071750000000001708245 -0.029249999999993087085" rpy="-1.570796326794896336 1.5707963267945610486 0" />
<geometry>
<mesh filename="package:///microservosg90.stl"/>
</geometry>
<material name="microservosg90_material">
<color rgba="0.35294117647058825815 0.35294117647058825815 0.35294117647058825815 1.0"/>
</material>
</visual>
<collision>
<origin xyz="0.01565000000000612429 0.0071750000000001708245 -0.029249999999993087085" rpy="-1.570796326794896336 1.5707963267945610486 0" />
<geometry>
<mesh filename="package:///microservosg90.stl"/>
</geometry>
</collision>
<visual>
<origin xyz="0 0 -0.0015000000000000013323" rpy="3.141592653589793116 -3.3306721717741334313e-16 0" />
<geometry>
<mesh filename="package:///18g_thigh_servo_attachment_v3.stl"/>
</geometry>
<material name="18g_thigh_servo_attachment_v3_material">
<color rgba="1 1 1 1.0"/>
</material>
</visual>
<collision>
<origin xyz="0 0 -0.0015000000000000013323" rpy="3.141592653589793116 -3.3306721717741334313e-16 0" />
<geometry>
<mesh filename="package:///18g_thigh_servo_attachment_v3.stl"/>
</geometry>
</collision>
<visual>
<origin xyz="0.0038875000000001477818 -3.794707603699265519e-18 -0.0090999999999999831024" rpy="3.815486698192717441e-21 3.3306721717741334313e-16 3.141592653589793116" />
<geometry>
<mesh filename="package:///hip_joint_to_servo_v2.stl"/>
</geometry>
<material name="hip_joint_to_servo_v2_material">
<color rgba="1 1 1 1.0"/>
</material>
</visual>
<collision>
<origin xyz="0.0038875000000001477818 -3.794707603699265519e-18 -0.0090999999999999831024" rpy="3.815486698192717441e-21 3.3306721717741334313e-16 3.141592653589793116" />
<geometry>
<mesh filename="package:///hip_joint_to_servo_v2.stl"/>
</geometry>
</collision>
<visual>
<origin xyz="0.004475000000000013689 0.012125000000000460063 -0.029999999999991696503" rpy="-1.570796326794896558 1.6686738633429766159e-15 3.141592653589793116" />
<geometry>
<mesh filename="package:///hip_v2.stl"/>
</geometry>
<material name="hip_v2_material">
<color rgba="1 1 1 1.0"/>
</material>
</visual>
<collision>
<origin xyz="0.004475000000000013689 0.012125000000000460063 -0.029999999999991696503" rpy="-1.570796326794896558 1.6686738633429766159e-15 3.141592653589793116" />
<geometry>
<mesh filename="package:///hip_v2.stl"/>
</geometry>
</collision>
<visual>
<origin xyz="0.004475000000006362777 -0.012125000000000468736 -0.029999999999996165151" rpy="1.570796326794896558 3.3599345559024095656e-13 3.141592653589793116" />
<geometry>
<mesh filename="package:///hip_v2.stl"/>
</geometry>
<material name="hip_v2_material">
<color rgba="1 1 1 1.0"/>
</material>
</visual>
<collision>
<origin xyz="0.004475000000006362777 -0.012125000000000468736 -0.029999999999996165151" rpy="1.570796326794896558 3.3599345559024095656e-13 3.141592653589793116" />
<geometry>
<mesh filename="package:///hip_v2.stl"/>
</geometry>
</collision>
<visual>
<origin xyz="0.015650000000006138168 -0.0052250000000002103789 -0.029249999999993087085" rpy="1.570796326794896558 -1.5707963267945610486 0" />
<geometry>
<mesh filename="package:///microservosg90.stl"/>
</geometry>
<material name="microservosg90_material">
<color rgba="0.35294117647058825815 0.35294117647058825815 0.35294117647058825815 1.0"/>
</material>
</visual>
<collision>
<origin xyz="0.015650000000006138168 -0.0052250000000002103789 -0.029249999999993087085" rpy="1.570796326794896558 -1.5707963267945610486 0" />
<geometry>
<mesh filename="package:///microservosg90.stl"/>
</geometry>
</collision>
<visual>
<origin xyz="0 0 -0.0015000000000000013323" rpy="1.570796326794896558 1.159043565970083256e-46 0" />
<geometry>
<mesh filename="package:///9g_servo_arm_v1.stl"/>
</geometry>
<material name="9g_servo_arm_v1_material">
<color rgba="0.62745098039215685404 0.62745098039215685404 0.62745098039215685404 1.0"/>
</material>
</visual>
<collision>
<origin xyz="0 0 -0.0015000000000000013323" rpy="1.570796326794896558 1.159043565970083256e-46 0" />
<geometry>
<mesh filename="package:///9g_servo_arm_v1.stl"/>
</geometry>
</collision>
<visual>
<origin xyz="0.0038875000000135537248 -2.8189256484623115284e-18 -0.050899999999988100596" rpy="-3.141592653589793116 3.3732906223640650982e-13 3.141592653589793116" />
<geometry>
<mesh filename="package:///hip_joint_to_bearing_v3.stl"/>
</geometry>
<material name="hip_joint_to_bearing_v3_material">
<color rgba="1 1 1 1.0"/>
</material>
</visual>
<collision>
<origin xyz="0.0038875000000135537248 -2.8189256484623115284e-18 -0.050899999999988100596" rpy="-3.141592653589793116 3.3732906223640650982e-13 3.141592653589793116" />
<geometry>
<mesh filename="package:///hip_joint_to_bearing_v3.stl"/>
</geometry>
</collision>
<visual>
<origin xyz="-0.015649999999996770661 0.0071750000000001794981 -0.024150000000003599143" rpy="-3.0077577205896187053e-16 -1.5707963267945610486 0" />
<geometry>
<mesh filename="package:///9g_thigh_servo_attachment_v1.stl"/>
</geometry>
<material name="9g_thigh_servo_attachment_v1_material">
<color rgba="1 1 1 1.0"/>
</material>
</visual>
<collision>
<origin xyz="-0.015649999999996770661 0.0071750000000001794981 -0.024150000000003599143" rpy="-3.0077577205896187053e-16 -1.5707963267945610486 0" />
<geometry>
<mesh filename="package:///9g_thigh_servo_attachment_v1.stl"/>
</geometry>
</collision>
<visual>
<origin xyz="-0.015649999999996770661 0.0071750000000001794981 -0.024150000000003599143" rpy="-1.5707963267948970021 -1.5707963267945610486 0" />
<geometry>
<mesh filename="package:///9g_servo_arm_v1.stl"/>
</geometry>
<material name="9g_servo_arm_v1_material">
<color rgba="0.62745098039215685404 0.62745098039215685404 0.62745098039215685404 1.0"/>
</material>
</visual>
<collision>
<origin xyz="-0.015649999999996770661 0.0071750000000001794981 -0.024150000000003599143" rpy="-1.5707963267948970021 -1.5707963267945610486 0" />
<geometry>
<mesh filename="package:///9g_servo_arm_v1.stl"/>
</geometry>
</collision>
<visual>
<origin xyz="-0.022149999999992002475 0.018292109297700004378 -0.037665155617948892219" rpy="1.5707963267953299891 0.68835957731061858667 -1.5707963267946583041" />
<geometry>
<mesh filename="package:///left_forearm_linkage_v1.stl"/>
</geometry>
<material name="left_forearm_linkage_v1_material">
<color rgba="1 1 1 1.0"/>
</material>
</visual>
<collision>
<origin xyz="-0.022149999999992002475 0.018292109297700004378 -0.037665155617948892219" rpy="1.5707963267953299891 0.68835957731061858667 -1.5707963267946583041" />
<geometry>
<mesh filename="package:///left_forearm_linkage_v1.stl"/>
</geometry>
</collision>
<visual>
<origin xyz="-0.028649999999997177724 0.0071955475779957294574 -0.024133107805413576974" rpy="-1.5707963270130320677 -1.5692676824827016535 1.5707963270127294209" />
<geometry>
<mesh filename="package:///left_cover_v2.stl"/>
</geometry>
<material name="left_cover_v2_material">
<color rgba="1 1 1 1.0"/>
</material>
</visual>
<collision>
<origin xyz="-0.028649999999997177724 0.0071955475779957294574 -0.024133107805413576974" rpy="-1.5707963270130320677 -1.5692676824827016535 1.5707963270127294209" />
<geometry>
<mesh filename="package:///left_cover_v2.stl"/>
</geometry>
</collision>
<visual>
<origin xyz="-0.022149999999992002475 0.018292109297700000908 -0.037665155617948892219" rpy="1.570796326795329767 0.68835957731061858667 -1.5707963267946587482" />
<geometry>
<mesh filename="package:///bearing_5x8x2.5_v1.stl"/>
</geometry>
<material name="bearing_5x8x2.5_v1_material">
<color rgba="0.62745098039215685404 0.62745098039215685404 0.62745098039215685404 1.0"/>
</material>
</visual>
<collision>
<origin xyz="-0.022149999999992002475 0.018292109297700000908 -0.037665155617948892219" rpy="1.570796326795329767 0.68835957731061858667 -1.5707963267946587482" />
<geometry>
<mesh filename="package:///bearing_5x8x2.5_v1.stl"/>
</geometry>
</collision>
<visual>
<origin xyz="-0.017649999999996848765 0.0071750000000001812328 -0.024150000000004272216" rpy="-3.0077577205895822205e-16 -1.5707963267945610486 0" />
<geometry>
<mesh filename="package:///bearing_10x15x4_v1.stl"/>
</geometry>
<material name="bearing_10x15x4_v1_material">
<color rgba="0.62745098039215685404 0.62745098039215685404 0.62745098039215685404 1.0"/>
</material>
</visual>
<collision>
<origin xyz="-0.017649999999996848765 0.0071750000000001812328 -0.024150000000004272216" rpy="-3.0077577205895822205e-16 -1.5707963267945610486 0" />
<geometry>
<mesh filename="package:///bearing_10x15x4_v1.stl"/>
</geometry>
</collision>
<visual>
<origin xyz="-0.021649999999997004974 0.0071750000000000025563 -0.024150000000005604484" rpy="7.4580180142223346183e-15 -1.5707963267945408425 0" />
<geometry>
<mesh filename="package:///left_forearm_pivot_v1.stl"/>
</geometry>
<material name="left_forearm_pivot_v1_material">
<color rgba="1 1 1 1.0"/>
</material>
</visual>
<collision>
<origin xyz="-0.021649999999997004974 0.0071750000000000025563 -0.024150000000005604484" rpy="7.4580180142223346183e-15 -1.5707963267945408425 0" />
<geometry>
<mesh filename="package:///left_forearm_pivot_v1.stl"/>
</geometry>
</collision>
<visual>
<origin xyz="-0.019149999999988925881 0.0058922344346109753466 -0.047865069312668567791" rpy="-3.6646417738492049791e-14 -1.5707963267945406205 0" />
<geometry>
<mesh filename="package:///bearing_5x8x2.5_v1.stl"/>
</geometry>
<material name="bearing_5x8x2.5_v1_material">
<color rgba="0.62745098039215685404 0.62745098039215685404 0.62745098039215685404 1.0"/>
</material>
</visual>
<collision>
<origin xyz="-0.019149999999988925881 0.0058922344346109753466 -0.047865069312668567791" rpy="-3.6646417738492049791e-14 -1.5707963267945406205 0" />
<geometry>
<mesh filename="package:///bearing_5x8x2.5_v1.stl"/>
</geometry>
</collision>
<visual>
<origin xyz="-0.019149999999988925881 0.0058922344346109753466 -0.047865069312668567791" rpy="3.1415926535897558125 -1.5707963267945406205 0" />
<geometry>
<mesh filename="package:///servo_arm_retainer_v1.stl"/>
</geometry>
<material name="servo_arm_retainer_v1_material">
<color rgba="1 1 1 1.0"/>
</material>
</visual>
<collision>
<origin xyz="-0.019149999999988925881 0.0058922344346109753466 -0.047865069312668567791" rpy="3.1415926535897558125 -1.5707963267945406205 0" />
<geometry>
<mesh filename="package:///servo_arm_retainer_v1.stl"/>
</geometry>
</collision>
<visual>
<origin xyz="-0.015649999999993315092 -0.0052250000000002103789 -0.034350000000003585998" rpy="1.570796326794896558 1.5707963267945610486 0" />
<geometry>
<mesh filename="package:///9g_servo_arm_v1.stl"/>
</geometry>
<material name="9g_servo_arm_v1_material">
<color rgba="0.62745098039215685404 0.62745098039215685404 0.62745098039215685404 1.0"/>
</material>
</visual>
<collision>
<origin xyz="-0.015649999999993315092 -0.0052250000000002103789 -0.034350000000003585998" rpy="1.570796326794896558 1.5707963267945610486 0" />
<geometry>
<mesh filename="package:///9g_servo_arm_v1.stl"/>
</geometry>
</collision>
<visual>
<origin xyz="-0.019149999999993450039 -0.0052250000000002086442 -0.034350000000004751732" rpy="-1.570796326794896558 -1.5707963267945619368 0" />
<geometry>
<mesh filename="package:///left_forearm_servo_attachment_v1.stl"/>
</geometry>
<material name="left_forearm_servo_attachment_v1_material">
<color rgba="1 1 1 1.0"/>
</material>
</visual>
<collision>
<origin xyz="-0.019149999999993450039 -0.0052250000000002086442 -0.034350000000004751732" rpy="-1.570796326794896558 -1.5707963267945619368 0" />
<geometry>
<mesh filename="package:///left_forearm_servo_attachment_v1.stl"/>
</geometry>
</collision>
<inertial>
<origin xyz="-0.0014149870812316415677 0.002626265355297086046 -0.028173125869927904269" rpy="0 0 0"/>
<mass value="0.035898853366757604855" />
<inertia ixx="8.8254316677968369485e-06" ixy="1.5321144265341069355e-06"  ixz="-7.0751529199990025524e-07" iyy="1.1416196796456221988e-05" iyz="-1.8704472750179598365e-07" izz="8.4326370763718302894e-06" />
</inertial>
</link>

<link name="leftthigh">
<visual>
<origin xyz="1.7347234759768070944e-18 -3.4694469519536141888e-18 -0.0069999999999999923395" rpy="-2.5287510867569001881e-31 -3.5459223571265033789e-31 -2.5408264050719269255e-17" />
<geometry>
<mesh filename="package:///right_thigh_v1.stl"/>
</geometry>
<material name="right_thigh_v1_material">
<color rgba="1 1 1 1.0"/>
</material>
</visual>
<collision>
<origin xyz="1.7347234759768070944e-18 -3.4694469519536141888e-18 -0.0069999999999999923395" rpy="-2.5287510867569001881e-31 -3.5459223571265033789e-31 -2.5408264050719269255e-17" />
<geometry>
<mesh filename="package:///right_thigh_v1.stl"/>
</geometry>
</collision>
<visual>
<origin xyz="0.034999999999982031595 -7.9797279894933126343e-15 -0.0044999999999999068523" rpy="-3.1415926535897917837 -3.4416913763379541153e-15 -9.3086176128034095306e-16" />
<geometry>
<mesh filename="package:///bearing_5x8x2.5_v1.stl"/>
</geometry>
<material name="bearing_5x8x2.5_v1_material">
<color rgba="0.62745098039215685404 0.62745098039215685404 0.62745098039215685404 1.0"/>
</material>
</visual>
<collision>
<origin xyz="0.034999999999982031595 -7.9797279894933126343e-15 -0.0044999999999999068523" rpy="-3.1415926535897917837 -3.4416913763379541153e-15 -9.3086176128034095306e-16" />
<geometry>
<mesh filename="package:///bearing_5x8x2.5_v1.stl"/>
</geometry>
</collision>
<inertial>
<origin xyz="0.013280795299928633765 -0.00036090962217552081687 -0.0044952882793202423445" rpy="0 0 0"/>
<mass value="0.0018464875329195404828" />
<inertia ixx="2.9147242782952549567e-08" ixy="3.1720502075642727247e-09"  ixz="1.4292641337521421279e-08" iyy="3.5092221986757934369e-07" iyz="-8.5226644673134628223e-10" izz="3.6712034510499317681e-07" />
</inertial>
</link>

<link name="leftfoot">
<visual>
<origin xyz="3.4694469519536141888e-18 -6.9388939039072283776e-18 -0.0030000000000000026645" rpy="-1.570796326794896558 1.2446569572129028691e-30 -6.3841240699234761017e-17" />
<geometry>
<mesh filename="package:///left_forearm_inside_v1.stl"/>
</geometry>
<material name="left_forearm_inside_v1_material">
<color rgba="1 1 1 1.0"/>
</material>
</visual>
<collision>
<origin xyz="3.4694469519536141888e-18 -6.9388939039072283776e-18 -0.0030000000000000026645" rpy="-1.570796326794896558 1.2446569572129028691e-30 -6.3841240699234761017e-17" />
<geometry>
<mesh filename="package:///left_forearm_inside_v1.stl"/>
</geometry>
</collision>
<visual>
<origin xyz="2.2204460492503130808e-16 -6.9388939039072283776e-18 0.00050000000000000044409" rpy="-1.570796326794896336 7.6813771076823225514e-28 -1.8930827081845103288e-16" />
<geometry>
<mesh filename="package:///left_forearm_outside_v1.stl"/>
</geometry>
<material name="left_forearm_outside_v1_material">
<color rgba="1 1 1 1.0"/>
</material>
</visual>
<collision>
<origin xyz="2.2204460492503130808e-16 -6.9388939039072283776e-18 0.00050000000000000044409" rpy="-1.570796326794896336 7.6813771076823225514e-28 -1.8930827081845103288e-16" />
<geometry>
<mesh filename="package:///left_forearm_outside_v1.stl"/>
</geometry>
</collision>
<inertial>
<origin xyz="-0.010270892890926622623 0.00083347437420344780597 -0.0010681367800692183334" rpy="0 0 0"/>
<mass value="0.0050411870565304911507" />
<inertia ixx="1.3517140742803418396e-07" ixy="5.9963138630909410324e-08"  ixz="-9.1762103748677447928e-09" iyy="2.0930300010810945099e-06" iyz="-6.4563982185088374652e-09" izz="2.1205101954398075575e-06" />
</inertial>
</link>

<joint name="foot_leftfront" type="revolute">
<origin xyz="0.034999999999982045473 -7.9831974364452662485e-15 -0.0069999999999999090727" rpy="-3.1415926535897900074 1.5819249601435221686e-15 -1.6352595016448581156" />
<parent link="leftthigh" />
<child link="leftfoot" />
<axis xyz="0 0 1"/>
<limit effort="1" velocity="20" lower="0" upper="1.0472"/>
<joint_properties friction="0.0"/>
</joint>

<joint name="thigh_leftfront" type="revolute">
<origin xyz="-0.017649999999996862643 0.0071750000000001812328 -0.024150000000004272216" rpy="-1.5707963267949105468 -0.68299626649609701534 -1.5707963267948894526" />
<parent link="lefthip" />
<child link="leftthigh" />
<axis xyz="0 0 1"/>
<limit effort="1" velocity="20" lower="0" upper="1.0472"/>
<joint_properties friction="0.0"/>
</joint>

<joint name="frontlefthip" type="revolute">
<origin xyz="0.036800000000000311629 0.056500000000000973055 -0.00047047612756290647235" rpy="1.570796326794896558 -1.064867427495631984e-16 3.141592653589793116" />
<parent link="chassis" />
<child link="lefthip" />
<axis xyz="0 0 1"/>
<limit effort="1" velocity="20" lower="-0.261799" upper="0.261799"/>
<joint_properties friction="0.0"/>
</joint>

<link name="lefthip_2">
<visual>
<origin xyz="0.015650000000005537953 0.0071749999999998950034 -0.029249999999993128719" rpy="-1.570796326794896558 1.5707963267945610486 0" />
<geometry>
<mesh filename="package:///microservosg90.stl"/>
</geometry>
<material name="microservosg90_material">
<color rgba="0.35294117647058825815 0.35294117647058825815 0.35294117647058825815 1.0"/>
</material>
</visual>
<collision>
<origin xyz="0.015650000000005537953 0.0071749999999998950034 -0.029249999999993128719" rpy="-1.570796326794896558 1.5707963267945610486 0" />
<geometry>
<mesh filename="package:///microservosg90.stl"/>
</geometry>
</collision>
<visual>
<origin xyz="0 0 -0.0015000000000000013323" rpy="3.141592653589793116 1.8883938382011724743e-48 -2.0141931291528256535e-33" />
<geometry>
<mesh filename="package:///18g_thigh_servo_attachment_v3.stl"/>
</geometry>
<material name="18g_thigh_servo_attachment_v3_material">
<color rgba="1 1 1 1.0"/>
</material>
</visual>
<collision>
<origin xyz="0 0 -0.0015000000000000013323" rpy="3.141592653589793116 1.8883938382011724743e-48 -2.0141931291528256535e-33" />
<geometry>
<mesh filename="package:///18g_thigh_servo_attachment_v3.stl"/>
</geometry>
</collision>
<visual>
<origin xyz="0.0038875000000000159428 -3.794707603699265519e-18 -0.0090999999999999969802" rpy="1.939190072544337729e-32 -1.8883938382011724743e-48 3.141592653589793116" />
<geometry>
<mesh filename="package:///hip_joint_to_servo_v2.stl"/>
</geometry>
<material name="hip_joint_to_servo_v2_material">
<color rgba="1 1 1 1.0"/>
</material>
</visual>
<collision>
<origin xyz="0.0038875000000000159428 -3.794707603699265519e-18 -0.0090999999999999969802" rpy="1.939190072544337729e-32 -1.8883938382011724743e-48 3.141592653589793116" />
<geometry>
<mesh filename="package:///hip_joint_to_servo_v2.stl"/>
</geometry>
</collision>
<visual>
<origin xyz="0.0044749999999998402167 0.012124999999999991687 -0.029999999999991755484" rpy="-1.570796326794896558 1.3356066461656161757e-15 3.141592653589793116" />
<geometry>
<mesh filename="package:///hip_v2.stl"/>
</geometry>
<material name="hip_v2_material">
<color rgba="1 1 1 1.0"/>
</material>
</visual>
<collision>
<origin xyz="0.0044749999999998402167 0.012124999999999991687 -0.029999999999991755484" rpy="-1.570796326794896558 1.3356066461656161757e-15 3.141592653589793116" />
<geometry>
<mesh filename="package:///hip_v2.stl"/>
</geometry>
</collision>
<visual>
<origin xyz="0.0044750000000061962435 -0.012125000000000002096 -0.029999999999996210254" rpy="1.570796326794896558 3.3566038837307654211e-13 3.141592653589793116" />
<geometry>
<mesh filename="package:///hip_v2.stl"/>
</geometry>
<material name="hip_v2_material">
<color rgba="1 1 1 1.0"/>
</material>
</visual>
<collision>
<origin xyz="0.0044750000000061962435 -0.012125000000000002096 -0.029999999999996210254" rpy="1.570796326794896558 3.3566038837307654211e-13 3.141592653589793116" />
<geometry>
<mesh filename="package:///hip_v2.stl"/>
</geometry>
</collision>
<visual>
<origin xyz="0.01565000000000555877 -0.0052250000000000100184 -0.029249999999993128719" rpy="1.570796326794896558 -1.5707963267945610486 0" />
<geometry>
<mesh filename="package:///microservosg90.stl"/>
</geometry>
<material name="microservosg90_material">
<color rgba="0.35294117647058825815 0.35294117647058825815 0.35294117647058825815 1.0"/>
</material>
</visual>
<collision>
<origin xyz="0.01565000000000555877 -0.0052250000000000100184 -0.029249999999993128719" rpy="1.570796326794896558 -1.5707963267945610486 0" />
<geometry>
<mesh filename="package:///microservosg90.stl"/>
</geometry>
</collision>
<visual>
<origin xyz="0 0 -0.0015000000000000013323" rpy="1.570796326794896558 1.8883938382011724743e-48 -2.0141931291528711546e-33" />
<geometry>
<mesh filename="package:///9g_servo_arm_v1.stl"/>
</geometry>
<material name="9g_servo_arm_v1_material">
<color rgba="0.62745098039215685404 0.62745098039215685404 0.62745098039215685404 1.0"/>
</material>
</visual>
<collision>
<origin xyz="0 0 -0.0015000000000000013323" rpy="1.570796326794896558 1.8883938382011724743e-48 -2.0141931291528711546e-33" />
<geometry>
<mesh filename="package:///9g_servo_arm_v1.stl"/>
</geometry>
</collision>
<visual>
<origin xyz="0.0038875000000134218858 -3.3610267347050637454e-18 -0.050899999999988163046" rpy="-3.141592653589793116 3.3699599501924214586e-13 3.141592653589793116" />
<geometry>
<mesh filename="package:///hip_joint_to_bearing_v3.stl"/>
</geometry>
<material name="hip_joint_to_bearing_v3_material">
<color rgba="1 1 1 1.0"/>
</material>
</visual>
<collision>
<origin xyz="0.0038875000000134218858 -3.3610267347050637454e-18 -0.050899999999988163046" rpy="-3.141592653589793116 3.3699599501924214586e-13 3.141592653589793116" />
<geometry>
<mesh filename="package:///hip_joint_to_bearing_v3.stl"/>
</geometry>
</collision>
<visual>
<origin xyz="-0.015649999999996201672 0.0071749999999999002076 -0.024150000000003585265" rpy="-1.6653345369385113456e-16 -1.5707963267945610486 0" />
<geometry>
<mesh filename="package:///9g_thigh_servo_attachment_v1.stl"/>
</geometry>
<material name="9g_thigh_servo_attachment_v1_material">
<color rgba="1 1 1 1.0"/>
</material>
</visual>
<collision>
<origin xyz="-0.015649999999996201672 0.0071749999999999002076 -0.024150000000003585265" rpy="-1.6653345369385113456e-16 -1.5707963267945610486 0" />
<geometry>
<mesh filename="package:///9g_thigh_servo_attachment_v1.stl"/>
</geometry>
</collision>
<visual>
<origin xyz="-0.015649999999996201672 0.0071749999999999002076 -0.024150000000003585265" rpy="-1.57079632679489678 -1.5707963267945610486 0" />
<geometry>
<mesh filename="package:///9g_servo_arm_v1.stl"/>
</geometry>
<material name="9g_servo_arm_v1_material">
<color rgba="0.62745098039215685404 0.62745098039215685404 0.62745098039215685404 1.0"/>
</material>
</visual>
<collision>
<origin xyz="-0.015649999999996201672 0.0071749999999999002076 -0.024150000000003585265" rpy="-1.57079632679489678 -1.5707963267945610486 0" />
<geometry>
<mesh filename="package:///9g_servo_arm_v1.stl"/>
</geometry>
</collision>
<visual>
<origin xyz="-0.022149999999991724919 0.018292112015483981413 -0.03766515892191818482" rpy="1.5707963267953330977 0.68835931085885382341 -1.5707963267946181141" />
<geometry>
<mesh filename="package:///left_forearm_linkage_v1.stl"/>
</geometry>
<material name="left_forearm_linkage_v1_material">
<color rgba="1 1 1 1.0"/>
</material>
</visual>
<collision>
<origin xyz="-0.022149999999991724919 0.018292112015483981413 -0.03766515892191818482" rpy="1.5707963267953330977 0.68835931085885382341 -1.5707963267946181141" />
<geometry>
<mesh filename="package:///left_forearm_linkage_v1.stl"/>
</geometry>
</collision>
<visual>
<origin xyz="-0.028649999999996268729 0.0071911362092343623573 -0.024136731956856588566" rpy="-1.5707963270749540907 -1.569593921142050208 1.570796327074955423" />
<geometry>
<mesh filename="package:///left_cover_v2.stl"/>
</geometry>
<material name="left_cover_v2_material">
<color rgba="1 1 1 1.0"/>
</material>
</visual>
<collision>
<origin xyz="-0.028649999999996268729 0.0071911362092343623573 -0.024136731956856588566" rpy="-1.5707963270749540907 -1.569593921142050208 1.570796327074955423" />
<geometry>
<mesh filename="package:///left_cover_v2.stl"/>
</geometry>
</collision>
<visual>
<origin xyz="-0.022149999999991724919 0.018292112015483981413 -0.03766515892191818482" rpy="1.5707963267953328756 0.68835931085885382341 -1.5707963267946185582" />
<geometry>
<mesh filename="package:///bearing_5x8x2.5_v1.stl"/>
</geometry>
<material name="bearing_5x8x2.5_v1_material">
<color rgba="0.62745098039215685404 0.62745098039215685404 0.62745098039215685404 1.0"/>
</material>
</visual>
<collision>
<origin xyz="-0.022149999999991724919 0.018292112015483981413 -0.03766515892191818482" rpy="1.5707963267953328756 0.68835931085885382341 -1.5707963267946185582" />
<geometry>
<mesh filename="package:///bearing_5x8x2.5_v1.stl"/>
</geometry>
</collision>
<visual>
<origin xyz="-0.017649999999996203448 0.0071749999999999002076 -0.024150000000004223644" rpy="-1.6653345369384598231e-16 -1.5707963267945610486 0" />
<geometry>
<mesh filename="package:///bearing_10x15x4_v1.stl"/>
</geometry>
<material name="bearing_10x15x4_v1_material">
<color rgba="0.62745098039215685404 0.62745098039215685404 0.62745098039215685404 1.0"/>
</material>
</visual>
<collision>
<origin xyz="-0.017649999999996203448 0.0071749999999999002076 -0.024150000000004223644" rpy="-1.6653345369384598231e-16 -1.5707963267945610486 0" />
<geometry>
<mesh filename="package:///bearing_10x15x4_v1.stl"/>
</geometry>
</collision>
<visual>
<origin xyz="-0.021649999999996207001 0.0071749999999998707173 -0.024150000000005639178" rpy="7.515325517993973856e-15 -1.5707963267945397323 0" />
<geometry>
<mesh filename="package:///left_forearm_pivot_v1.stl"/>
</geometry>
<material name="left_forearm_pivot_v1_material">
<color rgba="1 1 1 1.0"/>
</material>
</visual>
<collision>
<origin xyz="-0.021649999999996207001 0.0071749999999998707173 -0.024150000000005639178" rpy="7.515325517993973856e-15 -1.5707963267945397323 0" />
<geometry>
<mesh filename="package:///left_forearm_pivot_v1.stl"/>
</geometry>
</collision>
<visual>
<origin xyz="-0.019149999999988266686 0.0058922344346107767207 -0.047865069312668720447" rpy="1.3121801045090071902e-15 -1.5707963267945455055 0" />
<geometry>
<mesh filename="package:///bearing_5x8x2.5_v1.stl"/>
</geometry>
<material name="bearing_5x8x2.5_v1_material">
<color rgba="0.62745098039215685404 0.62745098039215685404 0.62745098039215685404 1.0"/>
</material>
</visual>
<collision>
<origin xyz="-0.019149999999988266686 0.0058922344346107767207 -0.047865069312668720447" rpy="1.3121801045090071902e-15 -1.5707963267945455055 0" />
<geometry>
<mesh filename="package:///bearing_5x8x2.5_v1.stl"/>
</geometry>
</collision>
<visual>
<origin xyz="-0.019149999999988266686 0.0058922344346107767207 -0.047865069312668720447" rpy="3.141592653589793116 -1.5707963267945455055 0" />
<geometry>
<mesh filename="package:///servo_arm_retainer_v1.stl"/>
</geometry>
<material name="servo_arm_retainer_v1_material">
<color rgba="1 1 1 1.0"/>
</material>
</visual>
<collision>
<origin xyz="-0.019149999999988266686 0.0058922344346107767207 -0.047865069312668720447" rpy="3.141592653589793116 -1.5707963267945455055 0" />
<geometry>
<mesh filename="package:///servo_arm_retainer_v1.stl"/>
</geometry>
</collision>
<visual>
<origin xyz="-0.015649999999992801614 -0.0052250000000000100184 -0.034350000000003613754" rpy="1.570796326794896558 1.5707963267945610486 0" />
<geometry>
<mesh filename="package:///9g_servo_arm_v1.stl"/>
</geometry>
<material name="9g_servo_arm_v1_material">
<color rgba="0.62745098039215685404 0.62745098039215685404 0.62745098039215685404 1.0"/>
</material>
</visual>
<collision>
<origin xyz="-0.015649999999992801614 -0.0052250000000000100184 -0.034350000000003613754" rpy="1.570796326794896558 1.5707963267945610486 0" />
<geometry>
<mesh filename="package:///9g_servo_arm_v1.stl"/>
</geometry>
</collision>
<visual>
<origin xyz="-0.019149999999992804722 -0.0052250000000000048142 -0.034350000000004821121" rpy="-1.570796326794896558 -1.5707963267945614927 0" />
<geometry>
<mesh filename="package:///left_forearm_servo_attachment_v1.stl"/>
</geometry>
<material name="left_forearm_servo_attachment_v1_material">
<color rgba="1 1 1 1.0"/>
</material>
</visual>
<collision>
<origin xyz="-0.019149999999992804722 -0.0052250000000000048142 -0.034350000000004821121" rpy="-1.570796326794896558 -1.5707963267945614927 0" />
<geometry>
<mesh filename="package:///left_forearm_servo_attachment_v1.stl"/>
</geometry>
</collision>
<inertial>
<origin xyz="-0.0014149870812316174985 0.0026260940434307085065 -0.028173120215437521402" rpy="0 0 0"/>
<mass value="0.035898853366757604855" />
<inertia ixx="8.8252350075534897073e-06" ixy="1.5319581048346753378e-06"  ixz="-7.0751013417707469621e-07" iyy="1.1416196374334960703e-05" iyz="-1.8697377752515767672e-07" izz="8.4324408382492174789e-06" />
</inertial>
</link>

<link name="leftthigh_2">
<visual>
<origin xyz="1.3877787807814456755e-17 0 -0.0069999999999999992784" rpy="-6.458154663844572468e-31 -1.0400475394434816594e-31 -8.2698090563950440512e-17" />
<geometry>
<mesh filename="package:///right_thigh_v1.stl"/>
</geometry>
<material name="right_thigh_v1_material">
<color rgba="1 1 1 1.0"/>
</material>
</visual>
<collision>
<origin xyz="1.3877787807814456755e-17 0 -0.0069999999999999992784" rpy="-6.458154663844572468e-31 -1.0400475394434816594e-31 -8.2698090563950440512e-17" />
<geometry>
<mesh filename="package:///right_thigh_v1.stl"/>
</geometry>
</collision>
<visual>
<origin xyz="0.035000000000000100475 -2.4286128663675299322e-15 -0.0044999999999998721578" rpy="-3.1415926535897868987 -1.3878168082508166292e-15 -1.0612352477184145494e-13" />
<geometry>
<mesh filename="package:///bearing_5x8x2.5_v1.stl"/>
</geometry>
<material name="bearing_5x8x2.5_v1_material">
<color rgba="0.62745098039215685404 0.62745098039215685404 0.62745098039215685404 1.0"/>
</material>
</visual>
<collision>
<origin xyz="0.035000000000000100475 -2.4286128663675299322e-15 -0.0044999999999998721578" rpy="-3.1415926535897868987 -1.3878168082508166292e-15 -1.0612352477184145494e-13" />
<geometry>
<mesh filename="package:///bearing_5x8x2.5_v1.stl"/>
</geometry>
</collision>
<inertial>
<origin xyz="0.013280795299929456024 -0.00036090962217526852303 -0.0044952882793202475487" rpy="0 0 0"/>
<mass value="0.0018464875329195404828" />
<inertia ixx="2.9147242782952870513e-08" ixy="3.1720502075537096282e-09"  ixz="1.4292641337523226188e-08" iyy="3.5092221986764435347e-07" iyz="-8.5226644673077232228e-10" izz="3.6712034510505861011e-07" />
</inertial>
</link>

<link name="leftfoot_2">
<visual>
<origin xyz="0 1.3877787807814456755e-17 -0.0030000000000000026645" rpy="-1.570796326794896558 7.5260947882829911547e-31 3.2883220873265247532e-17" />
<geometry>
<mesh filename="package:///left_forearm_inside_v1.stl"/>
</geometry>
<material name="left_forearm_inside_v1_material">
<color rgba="1 1 1 1.0"/>
</material>
</visual>
<collision>
<origin xyz="0 1.3877787807814456755e-17 -0.0030000000000000026645" rpy="-1.570796326794896558 7.5260947882829911547e-31 3.2883220873265247532e-17" />
<geometry>
<mesh filename="package:///left_forearm_inside_v1.stl"/>
</geometry>
</collision>
<visual>
<origin xyz="-6.1062266354383609723e-16 1.3877787807814456755e-17 0.00050000000000000044409" rpy="-1.57079632679489678 -1.3183777795750768813e-28 -9.6648317970636003512e-17" />
<geometry>
<mesh filename="package:///left_forearm_outside_v1.stl"/>
</geometry>
<material name="left_forearm_outside_v1_material">
<color rgba="1 1 1 1.0"/>
</material>
</visual>
<collision>
<origin xyz="-6.1062266354383609723e-16 1.3877787807814456755e-17 0.00050000000000000044409" rpy="-1.57079632679489678 -1.3183777795750768813e-28 -9.6648317970636003512e-17" />
<geometry>
<mesh filename="package:///left_forearm_outside_v1.stl"/>
</geometry>
</collision>
<inertial>
<origin xyz="-0.010270892890926927934 0.00083347437420345203436 -0.0010681367800692181166" rpy="0 0 0"/>
<mass value="0.0050411870565304911507" />
<inertia ixx="1.3517140742803182815e-07" ixy="5.9963138630908258888e-08"  ixz="-9.1762103748631010009e-09" iyy="2.093030001081045382e-06" iyz="-6.4563982185088722068e-09" izz="2.1205101954398033223e-06" />
</inertial>
</link>

<joint name="foot_leftback" type="revolute">
<origin xyz="0.035000000000000114353 -2.4147350785597154754e-15 -0.0069999999999998813172" rpy="-3.1415926535897926719 6.6665591471232595132e-15 -1.6625457993150511982" />
<parent link="leftthigh_2" />
<child link="leftfoot_2" />
<axis xyz="0 0 1"/>
<limit effort="1" velocity="20" lower="0" upper="1.0472"/>
<joint_properties friction="0.0"/>
</joint>

<joint name="thigh_leftback" type="revolute">
<origin xyz="-0.017649999999996210387 0.0071749999999999028097 -0.024150000000004334666" rpy="-1.5707963267948976682 -0.64616105155389358394 -1.5707963267948978903" />
<parent link="lefthip_2" />
<child link="leftthigh_2" />
<axis xyz="0 0 1"/>
<limit effort="1" velocity="20" lower="0" upper="1.0472"/>
<joint_properties friction="0.0"/>
</joint>

<joint name="backlefthip" type="revolute">
<origin xyz="0.036800000000000526734 0.15150000000000207745 -0.00047047612756298231229" rpy="1.570796326794896558 -1.0648674274956321072e-16 -3.141592653589783346" />
<parent link="chassis" />
<child link="lefthip_2" />
<axis xyz="0 0 1"/>
<limit effort="1" velocity="20" lower="-0.261799" upper="0.261799"/>
<joint_properties friction="0.0"/>
</joint>

<link name="righthip">
<visual>
<origin xyz="0.015657067775926254011 0.0049611362854387417581 -0.030749999999990756949" rpy="1.570796326794896558 -1.570796326794896336 0" />
<geometry>
<mesh filename="package:///microservosg90.stl"/>
</geometry>
<material name="microservosg90_material">
<color rgba="0.35294117647058825815 0.35294117647058825815 0.35294117647058825815 1.0"/>
</material>
</visual>
<collision>
<origin xyz="0.015657067775926254011 0.0049611362854387417581 -0.030749999999990756949" rpy="1.570796326794896558 -1.570796326794896336 0" />
<geometry>
<mesh filename="package:///microservosg90.stl"/>
</geometry>
</collision>
<visual>
<origin xyz="0.0044749999999997083777 0.012124999999999811276 -0.029999999999991502214" rpy="-1.5707963267948972241 1.3356066461656469413e-15 -3.141592653589793116" />
<geometry>
<mesh filename="package:///hip_v2.stl"/>
</geometry>
<material name="hip_v2_material">
<color rgba="1 1 1 1.0"/>
</material>
</visual>
<collision>
<origin xyz="0.0044749999999997083777 0.012124999999999811276 -0.029999999999991502214" rpy="-1.5707963267948972241 1.3356066461656469413e-15 -3.141592653589793116" />
<geometry>
<mesh filename="package:///hip_v2.stl"/>
</geometry>
</collision>
<visual>
<origin xyz="0.0044750000000060019545 -0.012124999999999814745 -0.029999999999995991679" rpy="1.5707963267948958919 3.35660388373080884e-13 -3.141592653589793116" />
<geometry>
<mesh filename="package:///hip_v2.stl"/>
</geometry>
<material name="hip_v2_material">
<color rgba="1 1 1 1.0"/>
</material>
</visual>
<collision>
<origin xyz="0.0044750000000060019545 -0.012124999999999814745 -0.029999999999995991679" rpy="1.5707963267948958919 3.35660388373080884e-13 -3.141592653589793116" />
<geometry>
<mesh filename="package:///hip_v2.stl"/>
</geometry>
</collision>
<visual>
<origin xyz="0 0 -0.0015000000000000013323" rpy="-3.1415926535897926719 -1.7790256896821891905e-30 2.1974391885873893687e-31" />
<geometry>
<mesh filename="package:///18g_thigh_servo_attachment_v3.stl"/>
</geometry>
<material name="18g_thigh_servo_attachment_v3_material">
<color rgba="1 1 1 1.0"/>
</material>
</visual>
<collision>
<origin xyz="0 0 -0.0015000000000000013323" rpy="-3.1415926535897926719 -1.7790256896821891905e-30 2.1974391885873893687e-31" />
<geometry>
<mesh filename="package:///18g_thigh_servo_attachment_v3.stl"/>
</geometry>
</collision>
<visual>
<origin xyz="0.0038875000000003698264 1.3145951341386741262e-18 -0.050899999999988863875" rpy="3.1415926535897926719 3.369959950192466897e-13 3.141592653589793116" />
<geometry>
<mesh filename="package:///hip_joint_to_bearing_v3.stl"/>
</geometry>
<material name="hip_joint_to_bearing_v3_material">
<color rgba="1 1 1 1.0"/>
</material>
</visual>
<collision>
<origin xyz="0.0038875000000003698264 1.3145951341386741262e-18 -0.050899999999988863875" rpy="3.1415926535897926719 3.369959950192466897e-13 3.141592653589793116" />
<geometry>
<mesh filename="package:///hip_joint_to_bearing_v3.stl"/>
</geometry>
</collision>
<visual>
<origin xyz="0 0 -0.0015000000000000013323" rpy="1.570796326794896558 -2.01303879236435367e-31 -2.1232107345180670311e-33" />
<geometry>
<mesh filename="package:///9g_servo_arm_v1.stl"/>
</geometry>
<material name="9g_servo_arm_v1_material">
<color rgba="0.62745098039215685404 0.62745098039215685404 0.62745098039215685404 1.0"/>
</material>
</visual>
<collision>
<origin xyz="0 0 -0.0015000000000000013323" rpy="1.570796326794896558 -2.01303879236435367e-31 -2.1232107345180670311e-33" />
<geometry>
<mesh filename="package:///9g_servo_arm_v1.stl"/>
</geometry>
</collision>
<visual>
<origin xyz="0.015657067775926205438 -0.0074388637145611086199 -0.030749999999990760419" rpy="-1.5707963267948952257 1.570796326794896336 0" />
<geometry>
<mesh filename="package:///microservosg90.stl"/>
</geometry>
<material name="microservosg90_material">
<color rgba="0.35294117647058825815 0.35294117647058825815 0.35294117647058825815 1.0"/>
</material>
</visual>
<collision>
<origin xyz="0.015657067775926205438 -0.0074388637145611086199 -0.030749999999990760419" rpy="-1.5707963267948952257 1.570796326794896336 0" />
<geometry>
<mesh filename="package:///microservosg90.stl"/>
</geometry>
</collision>
<visual>
<origin xyz="0.0038874999999998910427 -3.8353651851674719353e-18 -0.0090999999999999345301" rpy="-6.6612207091510841665e-16 1.7790256896821898912e-30 -3.141592653589793116" />
<geometry>
<mesh filename="package:///hip_joint_to_servo_v2.stl"/>
</geometry>
<material name="hip_joint_to_servo_v2_material">
<color rgba="1 1 1 1.0"/>
</material>
</visual>
<collision>
<origin xyz="0.0038874999999998910427 -3.8353651851674719353e-18 -0.0090999999999999345301" rpy="-6.6612207091510841665e-16 1.7790256896821898912e-30 -3.141592653589793116" />
<geometry>
<mesh filename="package:///hip_joint_to_servo_v2.stl"/>
</geometry>
</collision>
<visual>
<origin xyz="-0.021642932224072770897 -0.0074388637145610522414 -0.025649999999990850258" rpy="3.1415926535897917837 -1.5707963267948950037 0" />
<geometry>
<mesh filename="package:///bearing_10x15x4_v1.stl"/>
</geometry>
<material name="bearing_10x15x4_v1_material">
<color rgba="0.62745098039215685404 0.62745098039215685404 0.62745098039215685404 1.0"/>
</material>
</visual>
<collision>
<origin xyz="-0.021642932224072770897 -0.0074388637145610522414 -0.025649999999990850258" rpy="3.1415926535897917837 -1.5707963267948950037 0" />
<geometry>
<mesh filename="package:///bearing_10x15x4_v1.stl"/>
</geometry>
</collision>
<visual>
<origin xyz="-0.021642932224072770897 -0.0074388637145610522414 -0.025649999999990850258" rpy="3.1415926535897917837 -1.5707963267948950037 0" />
<geometry>
<mesh filename="package:///right_forearm_pivot_v1.stl"/>
</geometry>
<material name="right_forearm_pivot_v1_material">
<color rgba="1 1 1 1.0"/>
</material>
</visual>
<collision>
<origin xyz="-0.021642932224072770897 -0.0074388637145610522414 -0.025649999999990850258" rpy="3.1415926535897917837 -1.5707963267948950037 0" />
<geometry>
<mesh filename="package:///right_forearm_pivot_v1.stl"/>
</geometry>
</collision>
<visual>
<origin xyz="-0.015642932224073015368 -0.0074388637145610617823 -0.02564999999999083985" rpy="-1.5707963267948981123 -1.570796326794896336 0" />
<geometry>
<mesh filename="package:///9g_servo_arm_v1.stl"/>
</geometry>
<material name="9g_servo_arm_v1_material">
<color rgba="0.62745098039215685404 0.62745098039215685404 0.62745098039215685404 1.0"/>
</material>
</visual>
<collision>
<origin xyz="-0.015642932224073015368 -0.0074388637145610617823 -0.02564999999999083985" rpy="-1.5707963267948981123 -1.570796326794896336 0" />
<geometry>
<mesh filename="package:///9g_servo_arm_v1.stl"/>
</geometry>
</collision>
<visual>
<origin xyz="-0.015642932224073015368 -0.0074388637145610617823 -0.02564999999999083985" rpy="-1.4821224591991386098e-15 -1.570796326794896336 0" />
<geometry>
<mesh filename="package:///9g_thigh_servo_attachment_v1.stl"/>
</geometry>
<material name="9g_thigh_servo_attachment_v1_material">
<color rgba="1 1 1 1.0"/>
</material>
</visual>
<collision>
<origin xyz="-0.015642932224073015368 -0.0074388637145610617823 -0.02564999999999083985" rpy="-1.4821224591991386098e-15 -1.570796326794896336 0" />
<geometry>
<mesh filename="package:///9g_thigh_servo_attachment_v1.stl"/>
</geometry>
</collision>
<visual>
<origin xyz="-0.024642932224072607028 -0.018555812535801022994 -0.039164960532352147138" rpy="1.5707963267948950037 0.68837531027909637515 1.5707963267948925612" />
<geometry>
<mesh filename="package:///right_forearm_linkage_v1.stl"/>
</geometry>
<material name="right_forearm_linkage_v1_material">
<color rgba="1 1 1 1.0"/>
</material>
</visual>
<collision>
<origin xyz="-0.024642932224072607028 -0.018555812535801022994 -0.039164960532352147138" rpy="1.5707963267948950037 0.68837531027909637515 1.5707963267948925612" />
<geometry>
<mesh filename="package:///right_forearm_linkage_v1.stl"/>
</geometry>
</collision>
<visual>
<origin xyz="-0.028642932224072450986 -0.0074450181671779887618 -0.025644596317651313644" rpy="-1.5707963267910707295 -1.570319910106017014 -1.5707963267966360554" />
<geometry>
<mesh filename="package:///right_cover_v2.stl"/>
</geometry>
<material name="right_cover_v2_material">
<color rgba="1 1 1 1.0"/>
</material>
</visual>
<collision>
<origin xyz="-0.028642932224072450986 -0.0074450181671779887618 -0.025644596317651313644" rpy="-1.5707963267910707295 -1.570319910106017014 -1.5707963267966360554" />
<geometry>
<mesh filename="package:///right_cover_v2.stl"/>
</geometry>
</collision>
<visual>
<origin xyz="-0.024642932224072620906 -0.018555812535801022994 -0.039164960532352147138" rpy="1.5707963267948943376 0.68837531027909637515 1.5707963267948925612" />
<geometry>
<mesh filename="package:///bearing_5x8x2.5_v1.stl"/>
</geometry>
<material name="bearing_5x8x2.5_v1_material">
<color rgba="0.62745098039215685404 0.62745098039215685404 0.62745098039215685404 1.0"/>
</material>
</visual>
<collision>
<origin xyz="-0.024642932224072620906 -0.018555812535801022994 -0.039164960532352147138" rpy="1.5707963267948943376 0.68837531027909637515 1.5707963267948925612" />
<geometry>
<mesh filename="package:///bearing_5x8x2.5_v1.stl"/>
</geometry>
</collision>
<visual>
<origin xyz="-0.019142932224072803371 -0.0061560981491680438413 -0.049365069312650243505" rpy="-3.141592653589793116 1.570796326794896336 0" />
<geometry>
<mesh filename="package:///bearing_5x8x2.5_v1.stl"/>
</geometry>
<material name="bearing_5x8x2.5_v1_material">
<color rgba="0.62745098039215685404 0.62745098039215685404 0.62745098039215685404 1.0"/>
</material>
</visual>
<collision>
<origin xyz="-0.019142932224072803371 -0.0061560981491680438413 -0.049365069312650243505" rpy="-3.141592653589793116 1.570796326794896336 0" />
<geometry>
<mesh filename="package:///bearing_5x8x2.5_v1.stl"/>
</geometry>
</collision>
<visual>
<origin xyz="-0.021642932224072888858 0.0049611362854388423721 -0.035849999999990750377" rpy="1.570796326794896558 -1.570796326794896336 0" />
<geometry>
<mesh filename="package:///right_forearm_servo_attachment_v1.stl"/>
</geometry>
<material name="right_forearm_servo_attachment_v1_material">
<color rgba="1 1 1 1.0"/>
</material>
</visual>
<collision>
<origin xyz="-0.021642932224072888858 0.0049611362854388423721 -0.035849999999990750377" rpy="1.570796326794896558 -1.570796326794896336 0" />
<geometry>
<mesh filename="package:///right_forearm_servo_attachment_v1.stl"/>
</geometry>
</collision>
<visual>
<origin xyz="-0.015642932224072932101 0.0049611362854387426255 -0.035849999999990750377" rpy="1.570796326794896558 1.570796326794896558 0" />
<geometry>
<mesh filename="package:///9g_servo_arm_v1.stl"/>
</geometry>
<material name="9g_servo_arm_v1_material">
<color rgba="0.62745098039215685404 0.62745098039215685404 0.62745098039215685404 1.0"/>
</material>
</visual>
<collision>
<origin xyz="-0.015642932224072932101 0.0049611362854387426255 -0.035849999999990750377" rpy="1.570796326794896558 1.570796326794896558 0" />
<geometry>
<mesh filename="package:///9g_servo_arm_v1.stl"/>
</geometry>
</collision>
<inertial>
<origin xyz="-0.0011710670974884431275 -0.0027608821607481336471 -0.028924196672178822259" rpy="0 0 0"/>
<mass value="0.035352377824358502401" />
<inertia ixx="8.7057396674940704372e-06" ixy="-1.5198144212103963648e-06"  ixz="-6.3174231461625405036e-07" iyy="1.1158355849914649899e-05" iyz="1.7209971524295915633e-07" izz="8.3016348716513245335e-06" />
</inertial>
</link>

<link name="rightthigh">
<visual>
<origin xyz="0.034999999999991301958 -3.2994440513078870936e-15 -0.0069999999999990278332" rpy="3.0314639687389869044e-13 -1.4543921622588689243e-14 -4.0973000625029339622e-13" />
<geometry>
<mesh filename="package:///bearing_5x8x2.5_v1.stl"/>
</geometry>
<material name="bearing_5x8x2.5_v1_material">
<color rgba="0.62745098039215685404 0.62745098039215685404 0.62745098039215685404 1.0"/>
</material>
</visual>
<collision>
<origin xyz="0.034999999999991301958 -3.2994440513078870936e-15 -0.0069999999999990278332" rpy="3.0314639687389869044e-13 -1.4543921622588689243e-14 -4.0973000625029339622e-13" />
<geometry>
<mesh filename="package:///bearing_5x8x2.5_v1.stl"/>
</geometry>
</collision>
<visual>
<origin xyz="5.2041704279304212832e-18 0 -0.0044999999999999970579" rpy="3.141592653589793116 5.6275437750980734225e-31 -2.3986415420210210817e-19" />
<geometry>
<mesh filename="package:///left_thigh_v1.stl"/>
</geometry>
<material name="left_thigh_v1_material">
<color rgba="1 1 1 1.0"/>
</material>
</visual>
<collision>
<origin xyz="5.2041704279304212832e-18 0 -0.0044999999999999970579" rpy="3.141592653589793116 5.6275437750980734225e-31 -2.3986415420210210817e-19" />
<geometry>
<mesh filename="package:///left_thigh_v1.stl"/>
</geometry>
</collision>
<inertial>
<origin xyz="0.013280795316697385083 0.00036090885672630665859 -0.0044952881914007919786" rpy="0 0 0"/>
<mass value="0.0018464874791640287222" />
<inertia ixx="2.9147245096330454666e-08" ixy="-3.1720402745964754715e-09"  ixz="1.4292640858368840863e-08" iyy="3.5092222213974612467e-07" iyz="8.5226615733042899805e-10" izz="3.6712035000663567618e-07" />
</inertial>
</link>

<link name="rightfoot">
<visual>
<origin xyz="-1.7347234759768070944e-16 1.7347234759768070944e-16 0.00049999999999988942179" rpy="1.570796326794896558 -2.0583704886760704179e-31 4.7717822569229957945e-17" />
<geometry>
<mesh filename="package:///right_forearm_outside_v1.stl"/>
</geometry>
<material name="right_forearm_outside_v1_material">
<color rgba="1 1 1 1.0"/>
</material>
</visual>
<collision>
<origin xyz="-1.7347234759768070944e-16 1.7347234759768070944e-16 0.00049999999999988942179" rpy="1.570796326794896558 -2.0583704886760704179e-31 4.7717822569229957945e-17" />
<geometry>
<mesh filename="package:///right_forearm_outside_v1.stl"/>
</geometry>
</collision>
<visual>
<origin xyz="-1.0408340855860842566e-17 -6.9388939039072283776e-18 -0.0030000000000000026645" rpy="1.570796326794896558 -2.0583704886760704179e-31 4.7717822569229957945e-17" />
<geometry>
<mesh filename="package:///right_forearm_inside_v1.stl"/>
</geometry>
<material name="right_forearm_inside_v1_material">
<color rgba="1 1 1 1.0"/>
</material>
</visual>
<collision>
<origin xyz="-1.0408340855860842566e-17 -6.9388939039072283776e-18 -0.0030000000000000026645" rpy="1.570796326794896558 -2.0583704886760704179e-31 4.7717822569229957945e-17" />
<geometry>
<mesh filename="package:///right_forearm_inside_v1.stl"/>
</geometry>
</collision>
<inertial>
<origin xyz="-0.010376272044624906821 -0.00083660515753897993912 -0.0010641276308054037868" rpy="0 0 0"/>
<mass value="0.005060248979884990686" />
<inertia ixx="1.353988633449055292e-07" ixy="-6.0704074326210628227e-08"  ixz="-8.934072800664987872e-09" iyy="2.1021900877996542692e-06" iyz="6.4614286557740921553e-09" izz="2.1294078722671817905e-06" />
</inertial>
</link>

<joint name="foot_frontright" type="revolute">
<origin xyz="0.034999999999991301958 -3.2959746043559334794e-15 -0.0069999999999990278332" rpy="-3.141592653589793116 5.6029632860372716604e-16 1.7734346143245007799" />
<parent link="rightthigh" />
<child link="rightfoot" />
<axis xyz="0 0 1"/>
<limit effort="1" velocity="20" lower="-1.0472" upper="0"/>
<joint_properties friction="0.0"/>
</joint>

<joint name="thigh_frontright" type="revolute">
<origin xyz="-0.017642932224073031022 -0.0074388637145610652518 -0.025649999999990871075" rpy="1.5707963267948956698 -0.63152345479825011676 1.570796326794891673" />
<parent link="righthip" />
<child link="rightthigh" />
<axis xyz="0 0 1"/>
<limit effort="1" velocity="20" lower="-1.0472" upper="0"/>
<joint_properties friction="0.0"/>
</joint>

<joint name="frontrighthip" type="revolute">
<origin xyz="-0.036800000000001581446 0.056500000000000778766 -7.0476127562992511725e-05" rpy="-1.570796326794896558 -1.7106901340672024212e-16 9.1593124686582624559e-15" />
<parent link="chassis" />
<child link="righthip" />
<axis xyz="0 0 1"/>
<limit effort="1" velocity="20" lower="-0.261799" upper="0.261799"/>
<joint_properties friction="0.0"/>
</joint>

<link name="righthip_2">
<visual>
<origin xyz="0.015657067775926583608 0.0049611362854387972693 -0.030749999999990923483" rpy="1.570796326794896558 -1.570796326794896558 0" />
<geometry>
<mesh filename="package:///microservosg90.stl"/>
</geometry>
<material name="microservosg90_material">
<color rgba="0.35294117647058825815 0.35294117647058825815 0.35294117647058825815 1.0"/>
</material>
</visual>
<collision>
<origin xyz="0.015657067775926583608 0.0049611362854387972693 -0.030749999999990923483" rpy="1.570796326794896558 -1.570796326794896558 0" />
<geometry>
<mesh filename="package:///microservosg90.stl"/>
</geometry>
</collision>
<visual>
<origin xyz="0.0044749999999997638889 0.012124999999999946584 -0.029999999999991672217" rpy="-1.57079632679489678 1.3356066461656234727e-15 3.141592653589793116" />
<geometry>
<mesh filename="package:///hip_v2.stl"/>
</geometry>
<material name="hip_v2_material">
<color rgba="1 1 1 1.0"/>
</material>
</visual>
<collision>
<origin xyz="0.0044749999999997638889 0.012124999999999946584 -0.029999999999991672217" rpy="-1.57079632679489678 1.3356066461656234727e-15 3.141592653589793116" />
<geometry>
<mesh filename="package:///hip_v2.stl"/>
</geometry>
</collision>
<visual>
<origin xyz="0.0044750000000061199157 -0.012124999999999956993 -0.029999999999996140865" rpy="1.570796326794896336 3.3566038837307755185e-13 3.141592653589793116" />
<geometry>
<mesh filename="package:///hip_v2.stl"/>
</geometry>
<material name="hip_v2_material">
<color rgba="1 1 1 1.0"/>
</material>
</visual>
<collision>
<origin xyz="0.0044750000000061199157 -0.012124999999999956993 -0.029999999999996140865" rpy="1.570796326794896336 3.3566038837307755185e-13 3.141592653589793116" />
<geometry>
<mesh filename="package:///hip_v2.stl"/>
</geometry>
</collision>
<visual>
<origin xyz="0 0 -0.0014999999999999735767" rpy="-3.141592653589793116 -2.127942819740166194e-30 3.802887658476176292e-32" />
<geometry>
<mesh filename="package:///18g_thigh_servo_attachment_v3.stl"/>
</geometry>
<material name="18g_thigh_servo_attachment_v3_material">
<color rgba="1 1 1 1.0"/>
</material>
</visual>
<collision>
<origin xyz="0 0 -0.0014999999999999735767" rpy="-3.141592653589793116 -2.127942819740166194e-30 3.802887658476176292e-32" />
<geometry>
<mesh filename="package:///18g_thigh_servo_attachment_v3.stl"/>
</geometry>
</collision>
<visual>
<origin xyz="0.0038875000000004392153 3.6591823321385774648e-18 -0.050899999999989176125" rpy="3.141592653589793116 3.3699599501924295366e-13 3.141592653589793116" />
<geometry>
<mesh filename="package:///hip_joint_to_bearing_v3.stl"/>
</geometry>
<material name="hip_joint_to_bearing_v3_material">
<color rgba="1 1 1 1.0"/>
</material>
</visual>
<collision>
<origin xyz="0.0038875000000004392153 3.6591823321385774648e-18 -0.050899999999989176125" rpy="3.141592653589793116 3.3699599501924295366e-13 3.141592653589793116" />
<geometry>
<mesh filename="package:///hip_joint_to_bearing_v3.stl"/>
</geometry>
</collision>
<visual>
<origin xyz="0 0 -0.0014999999999999735767" rpy="1.570796326794896558 -5.5022100929803731063e-31 1.0510216525242782661e-33" />
<geometry>
<mesh filename="package:///9g_servo_arm_v1.stl"/>
</geometry>
<material name="9g_servo_arm_v1_material">
<color rgba="0.62745098039215685404 0.62745098039215685404 0.62745098039215685404 1.0"/>
</material>
</visual>
<collision>
<origin xyz="0 0 -0.0014999999999999735767" rpy="1.570796326794896558 -5.5022100929803731063e-31 1.0510216525242782661e-33" />
<geometry>
<mesh filename="package:///9g_servo_arm_v1.stl"/>
</geometry>
</collision>
<visual>
<origin xyz="0.015657067775926594017 -0.0074388637145611684678 -0.030749999999990909605" rpy="-1.57079632679489678 1.570796326794896336 0" />
<geometry>
<mesh filename="package:///microservosg90.stl"/>
</geometry>
<material name="microservosg90_material">
<color rgba="0.35294117647058825815 0.35294117647058825815 0.35294117647058825815 1.0"/>
</material>
</visual>
<collision>
<origin xyz="0.015657067775926594017 -0.0074388637145611684678 -0.030749999999990909605" rpy="-1.57079632679489678 1.570796326794896336 0" />
<geometry>
<mesh filename="package:///microservosg90.stl"/>
</geometry>
</collision>
<visual>
<origin xyz="0.0038874999999999743094 -3.8218126580114031299e-18 -0.009099999999999941469" rpy="-1.9988767292402708881e-16 2.127942819740166194e-30 3.141592653589793116" />
<geometry>
<mesh filename="package:///hip_joint_to_servo_v2.stl"/>
</geometry>
<material name="hip_joint_to_servo_v2_material">
<color rgba="1 1 1 1.0"/>
</material>
</visual>
<collision>
<origin xyz="0.0038874999999999743094 -3.8218126580114031299e-18 -0.009099999999999941469" rpy="-1.9988767292402708881e-16 2.127942819740166194e-30 3.141592653589793116" />
<geometry>
<mesh filename="package:///hip_joint_to_servo_v2.stl"/>
</geometry>
</collision>
<visual>
<origin xyz="-0.021642932224073367642 -0.0074388637145611719373 -0.025649999999990957811" rpy="-3.141592653589793116 -1.5707963267948956698 0" />
<geometry>
<mesh filename="package:///bearing_10x15x4_v1.stl"/>
</geometry>
<material name="bearing_10x15x4_v1_material">
<color rgba="0.62745098039215685404 0.62745098039215685404 0.62745098039215685404 1.0"/>
</material>
</visual>
<collision>
<origin xyz="-0.021642932224073367642 -0.0074388637145611719373 -0.025649999999990957811" rpy="-3.141592653589793116 -1.5707963267948956698 0" />
<geometry>
<mesh filename="package:///bearing_10x15x4_v1.stl"/>
</geometry>
</collision>
<visual>
<origin xyz="-0.021642932224073367642 -0.0074388637145611719373 -0.025649999999990957811" rpy="-3.141592653589793116 -1.5707963267948956698 0" />
<geometry>
<mesh filename="package:///right_forearm_pivot_v1.stl"/>
</geometry>
<material name="right_forearm_pivot_v1_material">
<color rgba="1 1 1 1.0"/>
</material>
</visual>
<collision>
<origin xyz="-0.021642932224073367642 -0.0074388637145611719373 -0.025649999999990957811" rpy="-3.141592653589793116 -1.5707963267948956698 0" />
<geometry>
<mesh filename="package:///right_forearm_pivot_v1.stl"/>
</geometry>
</collision>
<visual>
<origin xyz="-0.015642932224073369252 -0.0074388637145611702026 -0.025649999999990957811" rpy="-1.570796326794896558 -1.5707963267948956698 0" />
<geometry>
<mesh filename="package:///9g_servo_arm_v1.stl"/>
</geometry>
<material name="9g_servo_arm_v1_material">
<color rgba="0.62745098039215685404 0.62745098039215685404 0.62745098039215685404 1.0"/>
</material>
</visual>
<collision>
<origin xyz="-0.015642932224073369252 -0.0074388637145611702026 -0.025649999999990957811" rpy="-1.570796326794896558 -1.5707963267948956698 0" />
<geometry>
<mesh filename="package:///9g_servo_arm_v1.stl"/>
</geometry>
</collision>
<visual>
<origin xyz="-0.015642932224073369252 -0.0074388637145611702026 -0.025649999999990957811" rpy="1.2943564998328542606e-16 -1.5707963267948956698 0" />
<geometry>
<mesh filename="package:///9g_thigh_servo_attachment_v1.stl"/>
</geometry>
<material name="9g_thigh_servo_attachment_v1_material">
<color rgba="1 1 1 1.0"/>
</material>
</visual>
<collision>
<origin xyz="-0.015642932224073369252 -0.0074388637145611702026 -0.025649999999990957811" rpy="1.2943564998328542606e-16 -1.5707963267948956698 0" />
<geometry>
<mesh filename="package:///9g_thigh_servo_attachment_v1.stl"/>
</geometry>
</collision>
<visual>
<origin xyz="-0.02464293222407328704 -0.018555812535806862074 -0.039164960532358475409" rpy="1.5707963267948987784 0.68837531027923459792 1.5707963267949005548" />
<geometry>
<mesh filename="package:///right_forearm_linkage_v1.stl"/>
</geometry>
<material name="right_forearm_linkage_v1_material">
<color rgba="1 1 1 1.0"/>
</material>
</visual>
<collision>
<origin xyz="-0.02464293222407328704 -0.018555812535806862074 -0.039164960532358475409" rpy="1.5707963267948987784 0.68837531027923459792 1.5707963267949005548" />
<geometry>
<mesh filename="package:///right_forearm_linkage_v1.stl"/>
</geometry>
</collision>
<visual>
<origin xyz="-0.028642932224073235081 -0.0078107477265611418085 -0.025352155522328417847" rpy="-1.57079632679495651 -1.5435606468479745601 -1.5707963267947400166" />
<geometry>
<mesh filename="package:///right_cover_v2.stl"/>
</geometry>
<material name="right_cover_v2_material">
<color rgba="1 1 1 1.0"/>
</material>
</visual>
<collision>
<origin xyz="-0.028642932224073235081 -0.0078107477265611418085 -0.025352155522328417847" rpy="-1.57079632679495651 -1.5435606468479745601 -1.5707963267947400166" />
<geometry>
<mesh filename="package:///right_cover_v2.stl"/>
</geometry>
</collision>
<visual>
<origin xyz="-0.024642932224073280101 -0.018555812535806862074 -0.039164960532358475409" rpy="1.5707963267948987784 0.68837531027923459792 1.5707963267949005548" />
<geometry>
<mesh filename="package:///bearing_5x8x2.5_v1.stl"/>
</geometry>
<material name="bearing_5x8x2.5_v1_material">
<color rgba="0.62745098039215685404 0.62745098039215685404 0.62745098039215685404 1.0"/>
</material>
</visual>
<collision>
<origin xyz="-0.024642932224073280101 -0.018555812535806862074 -0.039164960532358475409" rpy="1.5707963267948987784 0.68837531027923459792 1.5707963267949005548" />
<geometry>
<mesh filename="package:///bearing_5x8x2.5_v1.stl"/>
</geometry>
</collision>
<visual>
<origin xyz="-0.019142932224073351544 -0.0061560981491748777844 -0.04936506931265861875" rpy="3.1415926535897926719 1.570796326794747344 0" />
<geometry>
<mesh filename="package:///bearing_5x8x2.5_v1.stl"/>
</geometry>
<material name="bearing_5x8x2.5_v1_material">
<color rgba="0.62745098039215685404 0.62745098039215685404 0.62745098039215685404 1.0"/>
</material>
</visual>
<collision>
<origin xyz="-0.019142932224073351544 -0.0061560981491748777844 -0.04936506931265861875" rpy="3.1415926535897926719 1.570796326794747344 0" />
<geometry>
<mesh filename="package:///bearing_5x8x2.5_v1.stl"/>
</geometry>
</collision>
<visual>
<origin xyz="-0.021642932224073402336 0.0049611362854387981366 -0.035849999999991152833" rpy="1.5707963267948998887 -1.5707963267948898967 0" />
<geometry>
<mesh filename="package:///right_forearm_servo_attachment_v1.stl"/>
</geometry>
<material name="right_forearm_servo_attachment_v1_material">
<color rgba="1 1 1 1.0"/>
</material>
</visual>
<collision>
<origin xyz="-0.021642932224073402336 0.0049611362854387981366 -0.035849999999991152833" rpy="1.5707963267948998887 -1.5707963267948898967 0" />
<geometry>
<mesh filename="package:///right_forearm_servo_attachment_v1.stl"/>
</geometry>
</collision>
<visual>
<origin xyz="-0.015642932224073355374 0.0049611362854387981366 -0.035849999999990958544" rpy="1.570796326794896558 1.5707963267948954478 0" />
<geometry>
<mesh filename="package:///9g_servo_arm_v1.stl"/>
</geometry>
<material name="9g_servo_arm_v1_material">
<color rgba="0.62745098039215685404 0.62745098039215685404 0.62745098039215685404 1.0"/>
</material>
</visual>
<collision>
<origin xyz="-0.015642932224073355374 0.0049611362854387981366 -0.035849999999990958544" rpy="1.570796326794896558 1.5707963267948954478 0" />
<geometry>
<mesh filename="package:///9g_servo_arm_v1.stl"/>
</geometry>
</collision>
<inertial>
<origin xyz="-0.0011710670974884804241 -0.0027751546053958056973 -0.028924859847319225881" rpy="0 0 0"/>
<mass value="0.035352377824358502401" />
<inertia ixx="8.7221517697940916523e-06" ixy="-1.5327589570214117722e-06"  ixz="-6.3234324719324679081e-07" iyy="1.1158273187212561011e-05" iyz="1.7742325608328413287e-07" izz="8.318129636653771755e-06" />
</inertial>
</link>

<link name="rightthigh_2">
<visual>
<origin xyz="0.034999999999997297162 5.2458037913538646535e-15 -0.0069999999999999923395" rpy="-1.6653345369377251964e-16 1.1102230246251490462e-15 3.5149683797554561726e-15" />
<geometry>
<mesh filename="package:///bearing_5x8x2.5_v1.stl"/>
</geometry>
<material name="bearing_5x8x2.5_v1_material">
<color rgba="0.62745098039215685404 0.62745098039215685404 0.62745098039215685404 1.0"/>
</material>
</visual>
<collision>
<origin xyz="0.034999999999997297162 5.2458037913538646535e-15 -0.0069999999999999923395" rpy="-1.6653345369377251964e-16 1.1102230246251490462e-15 3.5149683797554561726e-15" />
<geometry>
<mesh filename="package:///bearing_5x8x2.5_v1.stl"/>
</geometry>
</collision>
<visual>
<origin xyz="-1.3877787807814456755e-17 0 -0.0044999999999999970579" rpy="3.141592653589793116 -3.0067787733014283374e-31 5.1787811654151683233e-18" />
<geometry>
<mesh filename="package:///left_thigh_v1.stl"/>
</geometry>
<material name="left_thigh_v1_material">
<color rgba="1 1 1 1.0"/>
</material>
</visual>
<collision>
<origin xyz="-1.3877787807814456755e-17 0 -0.0044999999999999970579" rpy="3.141592653589793116 -3.0067787733014283374e-31 5.1787811654151683233e-18" />
<geometry>
<mesh filename="package:///left_thigh_v1.stl"/>
</geometry>
</collision>
<inertial>
<origin xyz="0.013280795316697640088 0.00036090885672670775918 -0.0044952881914008353467" rpy="0 0 0"/>
<mass value="0.0018464874791640287222" />
<inertia ixx="2.9147245096330123794e-08" ixy="-3.1720402746123391413e-09"  ixz="1.4292640858371216526e-08" iyy="3.5092222213976820047e-07" iyz="8.5226615733145894131e-10" izz="3.67120350006656852e-07" />
</inertial>
</link>

<link name="rightfoot_2">
<visual>
<origin xyz="1.1102230246251565404e-16 4.1633363423443370266e-17 0.00050000000000002126077" rpy="1.570796326794896558 -3.9586185168284505047e-31 -5.8107756656542900288e-18" />
<geometry>
<mesh filename="package:///right_forearm_outside_v1.stl"/>
</geometry>
<material name="right_forearm_outside_v1_material">
<color rgba="1 1 1 1.0"/>
</material>
</visual>
<collision>
<origin xyz="1.1102230246251565404e-16 4.1633363423443370266e-17 0.00050000000000002126077" rpy="1.570796326794896558 -3.9586185168284505047e-31 -5.8107756656542900288e-18" />
<geometry>
<mesh filename="package:///right_forearm_outside_v1.stl"/>
</geometry>
</collision>
<visual>
<origin xyz="2.7755575615628913511e-17 -2.7755575615628913511e-17 -0.0030000000000000096034" rpy="1.570796326794896558 -3.9586185168284505047e-31 -5.8107756656542900288e-18" />
<geometry>
<mesh filename="package:///right_forearm_inside_v1.stl"/>
</geometry>
<material name="right_forearm_inside_v1_material">
<color rgba="1 1 1 1.0"/>
</material>
</visual>
<collision>
<origin xyz="2.7755575615628913511e-17 -2.7755575615628913511e-17 -0.0030000000000000096034" rpy="1.570796326794896558 -3.9586185168284505047e-31 -5.8107756656542900288e-18" />
<geometry>
<mesh filename="package:///right_forearm_inside_v1.stl"/>
</geometry>
</collision>
<inertial>
<origin xyz="-0.010376272044624750696 -0.00083660515753905409855 -0.0010641276308053435051" rpy="0 0 0"/>
<mass value="0.005060248979884990686" />
<inertia ixx="1.3539886334490796442e-07" ixy="-6.0704074326209926778e-08"  ixz="-8.9340728006674230917e-09" iyy="2.1021900877996576573e-06" iyz="6.4614286557751062788e-09" izz="2.129407872267183908e-06" />
</inertial>
</link>

<joint name="foot_backright" type="revolute">
<origin xyz="0.034999999999997297162 5.2458037913538646535e-15 -0.0069999999999999923395" rpy="-3.141592653589793116 2.2441480830048960661e-16 1.4414733445528478128" />
<parent link="rightthigh_2" />
<child link="rightfoot_2" />
<axis xyz="0 0 1"/>
<limit effort="1" velocity="20" lower="-1.0472" upper="0"/>
<joint_properties friction="0.0"/>
</joint>

<joint name="thigh_backright" type="revolute">
<origin xyz="-0.017642932224073377967 -0.0074388637145611710699 -0.025649999999990985566" rpy="1.5707963267948950037 -0.76963751995166607145 1.5707963267948952257" />
<parent link="righthip_2" />
<child link="rightthigh_2" />
<axis xyz="0 0 1"/>
<limit effort="1" velocity="20" lower="-1.0472" upper="0"/>
<joint_properties friction="0.0"/>
</joint>

<joint name="backrighthip" type="revolute">
<origin xyz="-0.036800000000002490441 0.15150000000000204969 -7.0476127562969092958e-05" rpy="-1.570796326794896558 1.0648674274956146044e-16 7.5640658693905968835e-15" />
<parent link="chassis" />
<child link="righthip_2" />
<axis xyz="0 0 1"/>
<limit effort="1" velocity="20" lower="-0.261799" upper="0.261799"/>
<joint_properties friction="0.0"/>
</joint>

</robot>
